Workbook

Sheet Task_Tracking
A1: FSCM – Task tracking (Epic → Module → Chức năng → Backend / Portal / Mobile)
A2: Mỗi dòng là một task trên một nền tảng. Cột trắng: chọn PIC, Status, ngày, ghi chú. Cột xám tự tính. Lọc theo Epic / Module / Nền tảng / Sprint / PIC bằng nút lọc ở dòng tiêu đề.
A4: Task ID | B4: Epic | C4: Tên epic | D4: Module | E4: Chức năng | F4: Nền tảng | G4: Công việc | H4: Priority | I4: Sprint | J4: Thời gian sprint | K4: PIC | L4: Status | M4: Trễ hạn | N4: Bắt đầu | O4: Hoàn thành | P4: Ghi chú
A5: F08-BE | B5: E1 | C5: Nền tảng & xác thực | D5: Xác thực & phân quyền | E5: Đăng nhập Portal | F5: Backend | G5: Entra ID JWT, /me trả vai trò + kho / khu vực | H5: High | I5: S1 | J5: =IFERROR(TEXT(INDEX(Sprints!$B$5:$B$8,MATCH(I5,Sprints!$A$5:$A$8,0)),"dd/mm")&" – "&TEXT(INDEX(Sprints!$C$5:$C$8,MATCH(I5,Sprints!$A$5:$A$8,0)),"dd/mm"),"") -> 18/10 – 31/10 | K5: Khiết | L5: To Do | M5: =IFERROR(IF(AND(L5<>"Done",TODAY()>INDEX(Sprints!$C$5:$C$8,MATCH(I5,Sprints!$A$5:$A$8,0))),"Trễ",""),"")
A6: F08-FE | B6: E1 | C6: Nền tảng & xác thực | D6: Xác thực & phân quyền | E6: Đăng nhập Portal | F6: Portal | G6: MSAL đăng nhập, lưu token, xử lý 401 | H6: High | I6: S1 | J6: =IFERROR(TEXT(INDEX(Sprints!$B$5:$B$8,MATCH(I6,Sprints!$A$5:$A$8,0)),"dd/mm")&" – "&TEXT(INDEX(Sprints!$C$5:$C$8,MATCH(I6,Sprints!$A$5:$A$8,0)),"dd/mm"),"") -> 18/10 – 31/10 | K6: Hoàng | L6: To Do | M6: =IFERROR(IF(AND(L6<>"Done",TODAY()>INDEX(Sprints!$C$5:$C$8,MATCH(I6,Sprints!$A$5:$A$8,0))),"Trễ",""),"")
A7: F09-BE | B7: E1 | C7: Nền tảng & xác thực | D7: Xác thực & phân quyền | E7: Đăng nhập app mobile | F7: Backend | G7: Chốt cách đăng nhập app (Entra hoặc endpoint riêng) và làm phần server | H7: High | I7: S1 | J7: =IFERROR(TEXT(INDEX(Sprints!$B$5:$B$8,MATCH(I7,Sprints!$A$5:$A$8,0)),"dd/mm")&" – "&TEXT(INDEX(Sprints!$C$5:$C$8,MATCH(I7,Sprints!$A$5:$A$8,0)),"dd/mm"),"") -> 18/10 – 31/10 | K7: Hải | L7: To Do | M7: =IFERROR(IF(AND(L7<>"Done",TODAY()>INDEX(Sprints!$C$5:$C$8,MATCH(I7,Sprints!$A$5:$A$8,0))),"Trễ",""),"") | P7: Mock đang dùng SĐT + mật khẩu
A8: F09-MB | B8: E1 | C8: Nền tảng & xác thực | D8: Xác thực & phân quyền | E8: Đăng nhập app mobile | F8: Mobile | G8: Màn đăng nhập, lưu token bảo mật, tự đăng nhập lại | H8: High | I8: S1 | J8: =IFERROR(TEXT(INDEX(Sprints!$B$5:$B$8,MATCH(I8,Sprints!$A$5:$A$8,0)),"dd/mm")&" – "&TEXT(INDEX(Sprints!$C$5:$C$8,MATCH(I8,Sprints!$A$5:$A$8,0)),"dd/mm"),"") -> 18/10 – 31/10 | K8: Sơn | L8: To Do | M8: =IFERROR(IF(AND(L8<>"Done",TODAY()>INDEX(Sprints!$C$5:$C$8,MATCH(I8,Sprints!$A$5:$A$8,0))),"Trễ",""),"") | P8: Mock đang dùng SĐT + mật khẩu
A9: F10-BE | B9: E1 | C9: Nền tảng & xác thực | D9: Xác thực & phân quyền | E9: Phân quyền theo vai trò | F9: Backend | G9: [Authorize(Roles)] cho mọi API, kiểm tra phạm vi kho / vùng / retailer | H9: High | I9: S1 | J9: =IFERROR(TEXT(INDEX(Sprints!$B$5:$B$8,MATCH(I9,Sprints!$A$5:$A$8,0)),"dd/mm")&" – "&TEXT(INDEX(Sprints!$C$5:$C$8,MATCH(I9,Sprints!$A$5:$A$8,0)),"dd/mm"),"") -> 18/10 – 31/10 | K9: Khiết | L9: To Do | M9: =IFERROR(IF(AND(L9<>"Done",TODAY()>INDEX(Sprints!$C$5:$C$8,MATCH(I9,Sprints!$A$5:$A$8,0))),"Trễ",""),"")
A10: F10-FE | B10: E1 | C10: Nền tảng & xác thực | D10: Xác thực & phân quyền | E10: Phân quyền theo vai trò | F10: Portal | G10: Ẩn menu + chặn route theo vai trò | H10: High | I10: S1 | J10: =IFERROR(TEXT(INDEX(Sprints!$B$5:$B$8,MATCH(I10,Sprints!$A$5:$A$8,0)),"dd/mm")&" – "&TEXT(INDEX(Sprints!$C$5:$C$8,MATCH(I10,Sprints!$A$5:$A$8,0)),"dd/mm"),"") -> 18/10 – 31/10 | K10: Sơn | L10: To Do | M10: =IFERROR(IF(AND(L10<>"Done",TODAY()>INDEX(Sprints!$C$5:$C$8,MATCH(I10,Sprints!$A$5:$A$8,0))),"Trễ",""),"")
A11: F10-MB | B11: E1 | C11: Nền tảng & xác thực | D11: Xác thực & phân quyền | E11: Phân quyền theo vai trò | F11: Mobile | G11: Điều hướng theo vai trò sau đăng nhập | H11: High | I11: S1 | J11: =IFERROR(TEXT(INDEX(Sprints!$B$5:$B$8,MATCH(I11,Sprints!$A$5:$A$8,0)),"dd/mm")&" – "&TEXT(INDEX(Sprints!$C$5:$C$8,MATCH(I11,Sprints!$A$5:$A$8,0)),"dd/mm"),"") -> 18/10 – 31/10 | K11: Hoàng | L11: To Do | M11: =IFERROR(IF(AND(L11<>"Done",TODAY()>INDEX(Sprints!$C$5:$C$8,MATCH(I11,Sprints!$A$5:$A$8,0))),"Trễ",""),"")
A12: F11-BE | B12: E2 | C12: Dữ liệu gốc | D12: Người dùng | E12: Seed Admin, không tạo Admin trên UI | F12: Backend | G12: Seed Admin khi deploy, chặn tạo vai trò Admin | H12: High | I12: S1 | J12: =IFERROR(TEXT(INDEX(Sprints!$B$5:$B$8,MATCH(I12,Sprints!$A$5:$A$8,0)),"dd/mm")&" – "&TEXT(INDEX(Sprints!$C$5:$C$8,MATCH(I12,Sprints!$A$5:$A$8,0)),"dd/mm"),"") -> 18/10 – 31/10 | K12: Khiết | L12: To Do | M12: =IFERROR(IF(AND(L12<>"Done",TODAY()>INDEX(Sprints!$C$5:$C$8,MATCH(I12,Sprints!$A$5:$A$8,0))),"Trễ",""),"") | P12: Chốt 02/10
A13: F11-FE | B13: E2 | C13: Dữ liệu gốc | D13: Người dùng | E13: Seed Admin, không tạo Admin trên UI | F13: Portal | G13: Form người dùng không có lựa chọn Admin | H13: High | I13: S1 | J13: =IFERROR(TEXT(INDEX(Sprints!$B$5:$B$8,MATCH(I13,Sprints!$A$5:$A$8,0)),"dd/mm")&" – "&TEXT(INDEX(Sprints!$C$5:$C$8,MATCH(I13,Sprints!$A$5:$A$8,0)),"dd/mm"),"") -> 18/10 – 31/10 | K13: Hoàng | L13: To Do | M13: =IFERROR(IF(AND(L13<>"Done",TODAY()>INDEX(Sprints!$C$5:$C$8,MATCH(I13,Sprints!$A$5:$A$8,0))),"Trễ",""),"") | P13: Chốt 02/10
A14: F12-BE | B14: E2 | C14: Dữ liệu gốc | D14: Người dùng | E14: Quản lý người dùng | F14: Backend | G14: API tạo / sửa / khóa, gán kho, khu vực, nhóm Sales, retailer | H14: High | I14: S1 | J14: =IFERROR(TEXT(INDEX(Sprints!$B$5:$B$8,MATCH(I14,Sprints!$A$5:$A$8,0)),"dd/mm")&" – "&TEXT(INDEX(Sprints!$C$5:$C$8,MATCH(I14,Sprints!$A$5:$A$8,0)),"dd/mm"),"") -> 18/10 – 31/10 | K14: Khiết | L14: To Do | M14: =IFERROR(IF(AND(L14<>"Done",TODAY()>INDEX(Sprints!$C$5:$C$8,MATCH(I14,Sprints!$A$5:$A$8,0))),"Trễ",""),"")
A15: F12-FE | B15: E2 | C15: Dữ liệu gốc | D15: Người dùng | E15: Quản lý người dùng | F15: Portal | G15: Danh sách, form tạo / sửa, khóa tài khoản | H15: High | I15: S1 | J15: =IFERROR(TEXT(INDEX(Sprints!$B$5:$B$8,MATCH(I15,Sprints!$A$5:$A$8,0)),"dd/mm")&" – "&TEXT(INDEX(Sprints!$C$5:$C$8,MATCH(I15,Sprints!$A$5:$A$8,0)),"dd/mm"),"") -> 18/10 – 31/10 | K15: Hoàng | L15: To Do | M15: =IFERROR(IF(AND(L15<>"Done",TODAY()>INDEX(Sprints!$C$5:$C$8,MATCH(I15,Sprints!$A$5:$A$8,0))),"Trễ",""),"")
A16: F13-MB | B16: E2 | C16: Dữ liệu gốc | D16: Người dùng | E16: Hồ sơ cá nhân trên app | F16: Mobile | G16: Thông tin tài khoản, đăng xuất | H16: High | I16: S1 | J16: =IFERROR(TEXT(INDEX(Sprints!$B$5:$B$8,MATCH(I16,Sprints!$A$5:$A$8,0)),"dd/mm")&" – "&TEXT(INDEX(Sprints!$C$5:$C$8,MATCH(I16,Sprints!$A$5:$A$8,0)),"dd/mm"),"") -> 18/10 – 31/10 | K16: Hoàng | L16: To Do | M16: =IFERROR(IF(AND(L16<>"Done",TODAY()>INDEX(Sprints!$C$5:$C$8,MATCH(I16,Sprints!$A$5:$A$8,0))),"Trễ",""),"")
A17: F14-BE | B17: E2 | C17: Dữ liệu gốc | D17: Danh mục & sản phẩm | E17: Danh mục sản phẩm | F17: Backend | G17: API CRUD danh mục CAT-00 | H17: High | I17: S1 | J17: =IFERROR(TEXT(INDEX(Sprints!$B$5:$B$8,MATCH(I17,Sprints!$A$5:$A$8,0)),"dd/mm")&" – "&TEXT(INDEX(Sprints!$C$5:$C$8,MATCH(I17,Sprints!$A$5:$A$8,0)),"dd/mm"),"") -> 18/10 – 31/10 | K17: Khiết | L17: To Do | M17: =IFERROR(IF(AND(L17<>"Done",TODAY()>INDEX(Sprints!$C$5:$C$8,MATCH(I17,Sprints!$A$5:$A$8,0))),"Trễ",""),"")
A18: F14-FE | B18: E2 | C18: Dữ liệu gốc | D18: Danh mục & sản phẩm | E18: Danh mục sản phẩm | F18: Portal | G18: Màn danh mục: danh sách, tạo, sửa | H18: High | I18: S1 | J18: =IFERROR(TEXT(INDEX(Sprints!$B$5:$B$8,MATCH(I18,Sprints!$A$5:$A$8,0)),"dd/mm")&" – "&TEXT(INDEX(Sprints!$C$5:$C$8,MATCH(I18,Sprints!$A$5:$A$8,0)),"dd/mm"),"") -> 18/10 – 31/10 | K18: Sơn | L18: To Do | M18: =IFERROR(IF(AND(L18<>"Done",TODAY()>INDEX(Sprints!$C$5:$C$8,MATCH(I18,Sprints!$A$5:$A$8,0))),"Trễ",""),"")
A19: F15-BE | B19: E2 | C19: Dữ liệu gốc | D19: Danh mục & sản phẩm | E19: Sản phẩm Nháp → Publish → Inactive | F19: Backend | G19: Vòng đời sản phẩm, chặn sửa khi đã publish | H19: High | I19: S1 | J19: =IFERROR(TEXT(INDEX(Sprints!$B$5:$B$8,MATCH(I19,Sprints!$A$5:$A$8,0)),"dd/mm")&" – "&TEXT(INDEX(Sprints!$C$5:$C$8,MATCH(I19,Sprints!$A$5:$A$8,0)),"dd/mm"),"") -> 18/10 – 31/10 | K19: Khiết | L19: To Do | M19: =IFERROR(IF(AND(L19<>"Done",TODAY()>INDEX(Sprints!$C$5:$C$8,MATCH(I19,Sprints!$A$5:$A$8,0))),"Trễ",""),"") | P19: Chốt 02/10
A20: F15-FE | B20: E2 | C20: Dữ liệu gốc | D20: Danh mục & sản phẩm | E20: Sản phẩm Nháp → Publish → Inactive | F20: Portal | G20: Danh sách + form sản phẩm, nút Publish / Inactive | H20: High | I20: S1 | J20: =IFERROR(TEXT(INDEX(Sprints!$B$5:$B$8,MATCH(I20,Sprints!$A$5:$A$8,0)),"dd/mm")&" – "&TEXT(INDEX(Sprints!$C$5:$C$8,MATCH(I20,Sprints!$A$5:$A$8,0)),"dd/mm"),"") -> 18/10 – 31/10 | K20: Hoàng | L20: To Do | M20: =IFERROR(IF(AND(L20<>"Done",TODAY()>INDEX(Sprints!$C$5:$C$8,MATCH(I20,Sprints!$A$5:$A$8,0))),"Trễ",""),"") | P20: Chốt 02/10
A21: F16-BE | B21: E2 | C21: Dữ liệu gốc | D21: Danh mục & sản phẩm | E21: Clone sản phẩm để sửa | F21: Backend | G21: API clone sang SKU mới | H21: High | I21: S1 | J21: =IFERROR(TEXT(INDEX(Sprints!$B$5:$B$8,MATCH(I21,Sprints!$A$5:$A$8,0)),"dd/mm")&" – "&TEXT(INDEX(Sprints!$C$5:$C$8,MATCH(I21,Sprints!$A$5:$A$8,0)),"dd/mm"),"") -> 18/10 – 31/10 | K21: Hải | L21: To Do | M21: =IFERROR(IF(AND(L21<>"Done",TODAY()>INDEX(Sprints!$C$5:$C$8,MATCH(I21,Sprints!$A$5:$A$8,0))),"Trễ",""),"")
A22: F16-FE | B22: E2 | C22: Dữ liệu gốc | D22: Danh mục & sản phẩm | E22: Clone sản phẩm để sửa | F22: Portal | G22: Nút "Tạo bản mới từ sản phẩm này" | H22: High | I22: S1 | J22: =IFERROR(TEXT(INDEX(Sprints!$B$5:$B$8,MATCH(I22,Sprints!$A$5:$A$8,0)),"dd/mm")&" – "&TEXT(INDEX(Sprints!$C$5:$C$8,MATCH(I22,Sprints!$A$5:$A$8,0)),"dd/mm"),"") -> 18/10 – 31/10 | K22: Sơn | L22: To Do | M22: =IFERROR(IF(AND(L22<>"Done",TODAY()>INDEX(Sprints!$C$5:$C$8,MATCH(I22,Sprints!$A$5:$A$8,0))),"Trễ",""),"")
A23: F17-BE | B23: E2 | C23: Dữ liệu gốc | D23: Kho | E23: Quản lý kho | F23: Backend | G23: API kho tổng / kho vùng WH-XX, tọa độ, thủ kho, tồn tối thiểu | H23: High | I23: S1 | J23: =IFERROR(TEXT(INDEX(Sprints!$B$5:$B$8,MATCH(I23,Sprints!$A$5:$A$8,0)),"dd/mm")&" – "&TEXT(INDEX(Sprints!$C$5:$C$8,MATCH(I23,Sprints!$A$5:$A$8,0)),"dd/mm"),"") -> 18/10 – 31/10 | K23: Hải | L23: To Do | M23: =IFERROR(IF(AND(L23<>"Done",TODAY()>INDEX(Sprints!$C$5:$C$8,MATCH(I23,Sprints!$A$5:$A$8,0))),"Trễ",""),"")
A24: F17-FE | B24: E2 | C24: Dữ liệu gốc | D24: Kho | E24: Quản lý kho | F24: Portal | G24: Màn danh sách + form kho | H24: High | I24: S1 | J24: =IFERROR(TEXT(INDEX(Sprints!$B$5:$B$8,MATCH(I24,Sprints!$A$5:$A$8,0)),"dd/mm")&" – "&TEXT(INDEX(Sprints!$C$5:$C$8,MATCH(I24,Sprints!$A$5:$A$8,0)),"dd/mm"),"") -> 18/10 – 31/10 | K24: Sơn | L24: To Do | M24: =IFERROR(IF(AND(L24<>"Done",TODAY()>INDEX(Sprints!$C$5:$C$8,MATCH(I24,Sprints!$A$5:$A$8,0))),"Trễ",""),"")
A25: F18-BE | B25: E2 | C25: Dữ liệu gốc | D25: Khu vực & retailer | E25: Khu vực & nhóm Sales | F25: Backend | G25: API khu vực, nhóm Q12-A, gán Sales | H25: High | I25: S1 | J25: =IFERROR(TEXT(INDEX(Sprints!$B$5:$B$8,MATCH(I25,Sprints!$A$5:$A$8,0)),"dd/mm")&" – "&TEXT(INDEX(Sprints!$C$5:$C$8,MATCH(I25,Sprints!$A$5:$A$8,0)),"dd/mm"),"") -> 18/10 – 31/10 | K25: Hải | L25: To Do | M25: =IFERROR(IF(AND(L25<>"Done",TODAY()>INDEX(Sprints!$C$5:$C$8,MATCH(I25,Sprints!$A$5:$A$8,0))),"Trễ",""),"")
A26: F18-FE | B26: E2 | C26: Dữ liệu gốc | D26: Khu vực & retailer | E26: Khu vực & nhóm Sales | F26: Portal | G26: Màn Khu vực & nhóm Sales | H26: High | I26: S1 | J26: =IFERROR(TEXT(INDEX(Sprints!$B$5:$B$8,MATCH(I26,Sprints!$A$5:$A$8,0)),"dd/mm")&" – "&TEXT(INDEX(Sprints!$C$5:$C$8,MATCH(I26,Sprints!$A$5:$A$8,0)),"dd/mm"),"") -> 18/10 – 31/10 | K26: Sơn | L26: To Do | M26: =IFERROR(IF(AND(L26<>"Done",TODAY()>INDEX(Sprints!$C$5:$C$8,MATCH(I26,Sprints!$A$5:$A$8,0))),"Trễ",""),"")
A27: F19-BE | B27: E2 | C27: Dữ liệu gốc | D27: Khu vực & retailer | E27: Retailer + thông tin tiềm năng | F27: Backend | G27: API retailer mã 8 số, GPS, tiềm năng (doanh thu dự báo, độ lớn, khả năng nhập) | H27: High | I27: S1 | J27: =IFERROR(TEXT(INDEX(Sprints!$B$5:$B$8,MATCH(I27,Sprints!$A$5:$A$8,0)),"dd/mm")&" – "&TEXT(INDEX(Sprints!$C$5:$C$8,MATCH(I27,Sprints!$A$5:$A$8,0)),"dd/mm"),"") -> 18/10 – 31/10 | K27: Hải | L27: To Do | M27: =IFERROR(IF(AND(L27<>"Done",TODAY()>INDEX(Sprints!$C$5:$C$8,MATCH(I27,Sprints!$A$5:$A$8,0))),"Trễ",""),"")
A28: F19-FE | B28: E2 | C28: Dữ liệu gốc | D28: Khu vực & retailer | E28: Retailer + thông tin tiềm năng | F28: Portal | G28: Danh sách + chi tiết + form retailer | H28: High | I28: S1 | J28: =IFERROR(TEXT(INDEX(Sprints!$B$5:$B$8,MATCH(I28,Sprints!$A$5:$A$8,0)),"dd/mm")&" – "&TEXT(INDEX(Sprints!$C$5:$C$8,MATCH(I28,Sprints!$A$5:$A$8,0)),"dd/mm"),"") -> 18/10 – 31/10 | K28: Sơn | L28: To Do | M28: =IFERROR(IF(AND(L28<>"Done",TODAY()>INDEX(Sprints!$C$5:$C$8,MATCH(I28,Sprints!$A$5:$A$8,0))),"Trễ",""),"")
A29: F20-BE | B29: E2 | C29: Dữ liệu gốc | D29: Khu vực & retailer | E29: Retailer trong vùng trên app Sales | F29: Backend | G29: API retailer theo vùng của Sales đăng nhập | H29: High | I29: S2 | J29: =IFERROR(TEXT(INDEX(Sprints!$B$5:$B$8,MATCH(I29,Sprints!$A$5:$A$8,0)),"dd/mm")&" – "&TEXT(INDEX(Sprints!$C$5:$C$8,MATCH(I29,Sprints!$A$5:$A$8,0)),"dd/mm"),"") -> 01/11 – 14/11 | K29: Hải | L29: To Do | M29: =IFERROR(IF(AND(L29<>"Done",TODAY()>INDEX(Sprints!$C$5:$C$8,MATCH(I29,Sprints!$A$5:$A$8,0))),"Trễ",""),"")
A30: F20-MB | B30: E2 | C30: Dữ liệu gốc | D30: Khu vực & retailer | E30: Retailer trong vùng trên app Sales | F30: Mobile | G30: Danh sách + chi tiết retailer, tìm kiếm | H30: High | I30: S2 | J30: =IFERROR(TEXT(INDEX(Sprints!$B$5:$B$8,MATCH(I30,Sprints!$A$5:$A$8,0)),"dd/mm")&" – "&TEXT(INDEX(Sprints!$C$5:$C$8,MATCH(I30,Sprints!$A$5:$A$8,0)),"dd/mm"),"") -> 01/11 – 14/11 | K30: Hoàng | L30: To Do | M30: =IFERROR(IF(AND(L30<>"Done",TODAY()>INDEX(Sprints!$C$5:$C$8,MATCH(I30,Sprints!$A$5:$A$8,0))),"Trễ",""),"")
A31: F21-BE | B31: E2 | C31: Dữ liệu gốc | D31: Khu vực & retailer | E31: Khai báo retailer mới (KB) | F31: Backend | G31: API tạo yêu cầu KB-0000, duyệt / từ chối, sinh mã retailer | H31: Medium | I31: S2 | J31: =IFERROR(TEXT(INDEX(Sprints!$B$5:$B$8,MATCH(I31,Sprints!$A$5:$A$8,0)),"dd/mm")&" – "&TEXT(INDEX(Sprints!$C$5:$C$8,MATCH(I31,Sprints!$A$5:$A$8,0)),"dd/mm"),"") -> 01/11 – 14/11 | K31: Hải | L31: To Do | M31: =IFERROR(IF(AND(L31<>"Done",TODAY()>INDEX(Sprints!$C$5:$C$8,MATCH(I31,Sprints!$A$5:$A$8,0))),"Trễ",""),"")
A32: F21-FE | B32: E2 | C32: Dữ liệu gốc | D32: Khu vực & retailer | E32: Khai báo retailer mới (KB) | F32: Portal | G32: Màn duyệt yêu cầu KB | H32: Medium | I32: S2 | J32: =IFERROR(TEXT(INDEX(Sprints!$B$5:$B$8,MATCH(I32,Sprints!$A$5:$A$8,0)),"dd/mm")&" – "&TEXT(INDEX(Sprints!$C$5:$C$8,MATCH(I32,Sprints!$A$5:$A$8,0)),"dd/mm"),"") -> 01/11 – 14/11 | K32: Hoàng | L32: To Do | M32: =IFERROR(IF(AND(L32<>"Done",TODAY()>INDEX(Sprints!$C$5:$C$8,MATCH(I32,Sprints!$A$5:$A$8,0))),"Trễ",""),"")
... A39: F24-FE | B39: E3 | C39: Bán hàng & đơn hàng | D39: Khuyến mãi & báo giá | E39: Khuyến mãi theo SKU / nhóm (KM) | F39: Portal | G39: Màn khuyến mãi: danh sách, tạo, tạm dừng | H39: High | I39: S2 | J39: =IFERROR(TEXT(INDEX(Sprints!$B$5:$B$8,MATCH(I39,Sprints!$A$5:$A$8,0)),"dd/mm")&" – "&TEXT(INDEX(Sprints!$C$5:$C$8,MATCH(I39,Sprints!$A$5:$A$8,0)),"dd/mm"),"") -> 01/11 – 14/11 | K39: Nhân | L39: To Do | M39: =IFERROR(IF(AND(L39<>"Done",TODAY()>INDEX(Sprints!$C$5:$C$8,MATCH(I39,Sprints!$A$5:$A$8,0))),"Trễ",""),"")
A40: F25-BE | B40: E3 | C40: Bán hàng & đơn hàng | D40: Khuyến mãi & báo giá | E40: Báo giá khi đặt đơn | F40: Backend | G40: POST /pricing/quote tính giá + khuyến mãi | H40: High | I40: S2 | J40: =IFERROR(TEXT(INDEX(Sprints!$B$5:$B$8,MATCH(I40,Sprints!$A$5:$A$8,0)),"dd/mm")&" – "&TEXT(INDEX(Sprints!$C$5:$C$8,MATCH(I40,Sprints!$A$5:$A$8,0)),"dd/mm"),"") -> 01/11 – 14/11 | K40: Hải | L40: To Do | M40: =IFERROR(IF(AND(L40<>"Done",TODAY()>INDEX(Sprints!$C$5:$C$8,MATCH(I40,Sprints!$A$5:$A$8,0))),"Trễ",""),"") | P40: Server tính lại khi sync
A41: F25-MB | B41: E3 | C41: Bán hàng & đơn hàng | D41: Khuyến mãi & báo giá | E41: Báo giá khi đặt đơn | F41: Mobile | G41: Tính khuyến mãi tạm trên máy khi offline | H41: High | I41: S2 | J41: =IFERROR(TEXT(INDEX(Sprints!$B$5:$B$8,MATCH(I41,Sprints!$A$5:$A$8,0)),"dd/mm")&" – "&TEXT(INDEX(Sprints!$C$5:$C$8,MATCH(I41,Sprints!$A$5:$A$8,0)),"dd/mm"),"") -> 01/11 – 14/11 | K41: Hoàng | L41: To Do | M41: =IFERROR(IF(AND(L41<>"Done",TODAY()>INDEX(Sprints!$C$5:$C$8,MATCH(I41,Sprints!$A$5:$A$8,0))),"Trễ",""),"") | P41: Server tính lại khi sync
A42: F26-MB | B42: E3 | C42: Bán hàng & đơn hàng | D42: Khuyến mãi & báo giá | E42: Sản phẩm & khuyến mãi trên app Sales | F42: Mobile | G42: Danh sách sản phẩm, giá, khuyến mãi đang chạy | H42: High | I42: S2 | J42: =IFERROR(TEXT(INDEX(Sprints!$B$5:$B$8,MATCH(I42,Sprints!$A$5:$A$8,0)),"dd/mm")&" – "&TEXT(INDEX(Sprints!$C$5:$C$8,MATCH(I42,Sprints!$A$5:$A$8,0)),"dd/mm"),"") -> 01/11 – 14/11 | K42: Hoàng | L42: To Do | M42: =IFERROR(IF(AND(L42<>"Done",TODAY()>INDEX(Sprints!$C$5:$C$8,MATCH(I42,Sprints!$A$5:$A$8,0))),"Trễ",""),"")
A43: F27-BE | B43: E3 | C43: Bán hàng & đơn hàng | D43: Đặt đơn & đồng bộ | E43: Tạo đơn online | F43: Backend | G43: API tạo đơn DH-000000, kiểm tra retailer, thanh toán | H43: High | I43: S2 | J43: =IFERROR(TEXT(INDEX(Sprints!$B$5:$B$8,MATCH(I43,Sprints!$A$5:$A$8,0)),"dd/mm")&" – "&TEXT(INDEX(Sprints!$C$5:$C$8,MATCH(I43,Sprints!$A$5:$A$8,0)),"dd/mm"),"") -> 01/11 – 14/11 | K43: Hải | L43: To Do | M43: =IFERROR(IF(AND(L43<>"Done",TODAY()>INDEX(Sprints!$C$5:$C$8,MATCH(I43,Sprints!$A$5:$A$8,0))),"Trễ",""),"")
A44: F27-MB | B44: E3 | C44: Bán hàng & đơn hàng | D44: Đặt đơn & đồng bộ | E44: Tạo đơn online | F44: Mobile | G44: Màn tạo đơn + xác nhận (COD / trả trước / công nợ nếu được phép) | H44: High | I44: S2 | J44: =IFERROR(TEXT(INDEX(Sprints!$B$5:$B$8,MATCH(I44,Sprints!$A$5:$A$8,0)),"dd/mm")&" – "&TEXT(INDEX(Sprints!$C$5:$C$8,MATCH(I44,Sprints!$A$5:$A$8,0)),"dd/mm"),"") -> 01/11 – 14/11 | K44: Sơn | L44: To Do | M44: =IFERROR(IF(AND(L44<>"Done",TODAY()>INDEX(Sprints!$C$5:$C$8,MATCH(I44,Sprints!$A$5:$A$8,0))),"Trễ",""),"")
A45: F28-BE | B45: E3 | C45: Bán hàng & đơn hàng | D45: Đặt đơn & đồng bộ | E45: Chặn đặt trái vùng | F45: Backend | G45: Từ chối đơn của retailer ngoài vùng Sales | H45: High | I45: S2 | J45: =IFERROR(TEXT(INDEX(Sprints!$B$5:$B$8,MATCH(I45,Sprints!$A$5:$A$8,0)),"dd/mm")&" – "&TEXT(INDEX(Sprints!$C$5:$C$8,MATCH(I45,Sprints!$A$5:$A$8,0)),"dd/mm"),"") -> 01/11 – 14/11 | K45: Hải | L45: To Do | M45: =IFERROR(IF(AND(L45<>"Done",TODAY()>INDEX(Sprints!$C$5:$C$8,MATCH(I45,Sprints!$A$5:$A$8,0))),"Trễ",""),"") | P45: Chốt 02/10
A46: F28-MB | B46: E3 | C46: Bán hàng & đơn hàng | D46: Đặt đơn & đồng bộ | E46: Chặn đặt trái vùng | F46: Mobile | G46: Khóa nút đặt hàng với retailer ngoài vùng | H46: High | I46: S2 | J46: =IFERROR(TEXT(INDEX(Sprints!$B$5:$B$8,MATCH(I46,Sprints!$A$5:$A$8,0)),"dd/mm")&" – "&TEXT(INDEX(Sprints!$C$5:$C$8,MATCH(I46,Sprints!$A$5:$A$8,0)),"dd/mm"),"") -> 01/11 – 14/11 | K46: Sơn | L46: To Do | M46: =IFERROR(IF(AND(L46<>"Done",TODAY()>INDEX(Sprints!$C$5:$C$8,MATCH(I46,Sprints!$A$5:$A$8,0))),"Trễ",""),"") | P46: Chốt 02/10
A47: F29-BE | B47: E3 | C47: Bán hàng & đơn hàng | D47: Đặt đơn & đồng bộ | E47: Snapshot dữ liệu cho app | F47: Backend | G47: GET /sync/snapshot: retailer, sản phẩm, giá, KM, tồn khả dụng | H47: High | I47: S3 | J47: =IFERROR(TEXT(INDEX(Sprints!$B$5:$B$8,MATCH(I47,Sprints!$A$5:$A$8,0)),"dd/mm")&" – "&TEXT(INDEX(Sprints!$C$5:$C$8,MATCH(I47,Sprints!$A$5:$A$8,0)),"dd/mm"),"") -> 15/11 – 28/11 | L47: To Do | M47: =IFERROR(IF(AND(L47<>"Done",TODAY()>INDEX(Sprints!$C$5:$C$8,MATCH(I47,Sprints!$A$5:$A$8,0))),"Trễ",""),"")
...

Sheet Team
A1: Thành viên
A2: Danh sách này là nguồn cho dropdown PIC trên Task_Tracking. Sửa tên / thêm người ở cột A.
A4: PIC (tên ngắn) | B4: Họ tên | C4: Vai trò | D4: Số task | E4: Done | F4: % Done
A5: Nhân | B5: Nguyen Thien Nhan | C5: Leader | D5: =COUNTIF(Task_Tracking!$K$5:$K$400,A5) -> 14 | E5: =COUNTIFS(Task_Tracking!$K$5:$K$400,A5,Task_Tracking!$L$5:$L$400,"Done") -> 0 | F5: =IFERROR(E5/D5,0) -> 0
A6: Khiết | B6: Tran Ngoc Khiet | D6: =COUNTIF(Task_Tracking!$K$5:$K$400,A6) -> 11 | E6: =COUNTIFS(Task_Tracking!$K$5:$K$400,A6,Task_Tracking!$L$5:$L$400,"Done") -> 0 | F6: =IFERROR(E6/D6,0) -> 0
A7: Hải | B7: Doan Duc Hai | D7: =COUNTIF(Task_Tracking!$K$5:$K$400,A7) -> 18 | E7: =COUNTIFS(Task_Tracking!$K$5:$K$400,A7,Task_Tracking!$L$5:$L$400,"Done") -> 0 | F7: =IFERROR(E7/D7,0) -> 0
A8: Sơn | B8: Vo Minh Son | D8: =COUNTIF(Task_Tracking!$K$5:$K$400,A8) -> 16 | E8: =COUNTIFS(Task_Tracking!$K$5:$K$400,A8,Task_Tracking!$L$5:$L$400,"Done") -> 0 | F8: =IFERROR(E8/D8,0) -> 0
A9: Hoàng | B9: Truong Le Huy Hoang | D9: =COUNTIF(Task_Tracking!$K$5:$K$400,A9) -> 16 | E9: =COUNTIFS(Task_Tracking!$K$5:$K$400,A9,Task_Tracking!$L$5:$L$400,"Done") -> 0 | F9: =IFERROR(E9/D9,0) -> 0

Sheet Dashboard
A1: FSCM – Dashboard tiến độ 8 tuần
A2: Tự tính từ Task_Tracking và Sprints. Ô vàng ở cột PIC trên Task_Tracking = task chưa có người nhận.
A4: Tổng quan
A5: Tổng task | B5: Done | C5: % Done | D5: Chưa có PIC | E5: Trễ hạn | F5: Blocked | G5: Sprint hiện tại
A6: =COUNTA(Task_Tracking!$G$5:$G$400) -> 149 | B6: =COUNTIF(Task_Tracking!$L$5:$L$400,"Done") -> 0 | C6: =IFERROR(B6/A6,0) -> 0 | D6: =COUNTIFS(Task_Tracking!$G$5:$G$400,"<>",Task_Tracking!$K$5:$K$400,"") -> 74 | E6: =COUNTIF(Task_Tracking!$M$5:$M$400,"Trễ") -> 0 | F6: =COUNTIF(Task_Tracking!$L$5:$L$400,"Blocked") -> 0 | G6: =IFERROR(INDEX(Sprints!$A$5:$A$8,MATCH("Đang chạy",Sprints!$H$5:$H$8,0)),IF(TODAY()<Sprints!$B$5,"Chưa bắt đầu","Đã hết 8 tuần")) -> Chưa bắt đầu
A8: Theo sprint
A9: Sprint | B9: Thời gian | C9: Backend | D9: Portal | E9: Mobile | F9: Tổng task | G9: Done | H9: Còn lại | I9: Lũy kế kế hoạch | J9: Lũy kế Done | K9: % Done
A10: S1 | B10: =TEXT(Sprints!B5,"dd/mm")&" – "&TEXT(Sprints!C5,"dd/mm") -> 18/10 – 31/10 | C10: =COUNTIFS(Task_Tracking!$I$5:$I$400,$A10,Task_Tracking!$F$5:$F$400,"Backend") -> 16 | D10: =COUNTIFS(Task_Tracking!$I$5:$I$400,$A10,Task_Tracking!$F$5:$F$400,"Portal") -> 13 | E10: =COUNTIFS(Task_Tracking!$I$5:$I$400,$A10,Task_Tracking!$F$5:$F$400,"Mobile") -> 3 | F10: =SUM(C10:E10) -> 32 | G10: =COUNTIFS(Task_Tracking!$I$5:$I$400,$A10,Task_Tracking!$L$5:$L$400,"Done") -> 0 | H10: =F10-G10 -> 32 | I10: =SUM($F$10:F10) -> 32 | J10: =SUM($G$10:G10) -> 0 | K10: =IFERROR(G10/F10,0) -> 0
A11: S2 | B11: =TEXT(Sprints!B6,"dd/mm")&" – "&TEXT(Sprints!C6,"dd/mm") -> 01/11 – 14/11 | C11: =COUNTIFS(Task_Tracking!$I$5:$I$400,$A11,Task_Tracking!$F$5:$F$400,"Backend") -> 21 | D11: =COUNTIFS(Task_Tracking!$I$5:$I$400,$A11,Task_Tracking!$F$5:$F$400,"Portal") -> 11 | E11: =COUNTIFS(Task_Tracking!$I$5:$I$400,$A11,Task_Tracking!$F$5:$F$400,"Mobile") -> 11 | F11: =SUM(C11:E11) -> 43 | G11: =COUNTIFS(Task_Tracking!$I$5:$I$400,$A11,Task_Tracking!$L$5:$L$400,"Done") -> 0 | H11: =F11-G11 -> 43 | I11: =SUM($F$10:F11) -> 75 | J11: =SUM($G$10:G11) -> 0 | K11: =IFERROR(G11/F11,0) -> 0
A12: S3 | B12: =TEXT(Sprints!B7,"dd/mm")&" – "&TEXT(Sprints!C7,"dd/mm") -> 15/11 – 28/11 | C12: =COUNTIFS(Task_Tracking!$I$5:$I$400,$A12,Task_Tracking!$F$5:$F$400,"Backend") -> 33 | D12: =COUNTIFS(Task_Tracking!$I$5:$I$400,$A12,Task_Tracking!$F$5:$F$400,"Portal") -> 20 | E12: =COUNTIFS(Task_Tracking!$I$5:$I$400,$A12,Task_Tracking!$F$5:$F$400,"Mobile") -> 14 | F12: =SUM(C12:E12) -> 67 | G12: =COUNTIFS(Task_Tracking!$I$5:$I$400,$A12,Task_Tracking!$L$5:$L$400,"Done") -> 0 | H12: =F12-G12 -> 67 | I12: =SUM($F$10:F12) -> 142 | J12: =SUM($G$10:G12) -> 0 | K12: =IFERROR(G12/F12,0) -> 0
A13: S4 | B13: =TEXT(Sprints!B8,"dd/mm")&" – "&TEXT(Sprints!C8,"dd/mm") -> 29/11 – 12/12 | C13: =COUNTIFS(Task_Tracking!$I$5:$I$400,$A13,Task_Tracking!$F$5:$F$400,"Backend") -> 3 | D13: =COUNTIFS(Task_Tracking!$I$5:$I$400,$A13,Task_Tracking!$F$5:$F$400,"Portal") -> 2 | E13: =COUNTIFS(Task_Tracking!$I$5:$I$400,$A13,Task_Tracking!$F$5:$F$400,"Mobile") -> 2 | F13: =SUM(C13:E13) -> 7 | G13: =COUNTIFS(Task_Tracking!$I$5:$I$400,$A13,Task_Tracking!$L$5:$L$400,"Done") -> 0 | H13: =F13-G13 -> 7 | I13: =SUM($F$10:F13) -> 149 | J13: =SUM($G$10:G13) -> 0 | K13: =IFERROR(G13/F13,0) -> 0
A14: Tổng | C14: =SUM(C10:C13) -> 73 | D14: =SUM(D10:D13) -> 46 | E14: =SUM(E10:E13) -> 30 | F14: =SUM(F10:F13) -> 149 | G14: =SUM(G10:G13) -> 0 | H14: =SUM(H10:H13) -> 149 | K14: =IFERROR(G14/F14,0) -> 0
A16: Khối lượng theo PIC × sprint (số task) – dùng để cân việc khi chia PIC
A17: PIC | B17: S1 | C17: S2 | D17: S3 | E17: S4 | F17: Tổng | G17: Done | H17: % Done
A18: =Team!A5 -> Nhân | B18: =COUNTIFS(Task_Tracking!$I$5:$I$400,"S1",Task_Tracking!$K$5:$K$400,$A18) -> 4 | C18: =COUNTIFS(Task_Tracking!$I$5:$I$400,"S2",Task_Tracking!$K$5:$K$400,$A18) -> 10 | D18: =COUNTIFS(Task_Tracking!$I$5:$I$400,"S3",Task_Tracking!$K$5:$K$400,$A18) -> 0 | E18: =COUNTIFS(Task_Tracking!$I$5:$I$400,"S4",Task_Tracking!$K$5:$K$400,$A18) -> 0 | F18: =SUM(B18:E18) -> 14 | G18: =COUNTIFS(Task_Tracking!$K$5:$K$400,$A18,Task_Tracking!$L$5:$L$400,"Done") -> 0 | H18: =IFERROR(G18/F18,0) -> 0
A19: =Team!A6 -> Khiết | B19: =COUNTIFS(Task_Tracking!$I$5:$I$400,"S1",Task_Tracking!$K$5:$K$400,$A19) -> 6 | C19: =COUNTIFS(Task_Tracking!$I$5:$I$400,"S2",Task_Tracking!$K$5:$K$400,$A19) -> 5 | D19: =COUNTIFS(Task_Tracking!$I$5:$I$400,"S3",Task_Tracking!$K$5:$K$400,$A19) -> 0 | E19: =COUNTIFS(Task_Tracking!$I$5:$I$400,"S4",Task_Tracking!$K$5:$K$400,$A19) -> 0 | F19: =SUM(B19:E19) -> 11 | G19: =COUNTIFS(Task_Tracking!$K$5:$K$400,$A19,Task_Tracking!$L$5:$L$400,"Done") -> 0 | H19: =IFERROR(G19/F19,0) -> 0
A20: =Team!A7 -> Hải | B20: =COUNTIFS(Task_Tracking!$I$5:$I$400,"S1",Task_Tracking!$K$5:$K$400,$A20) -> 7 | C20: =COUNTIFS(Task_Tracking!$I$5:$I$400,"S2",Task_Tracking!$K$5:$K$400,$A20) -> 11 | D20: =COUNTIFS(Task_Tracking!$I$5:$I$400,"S3",Task_Tracking!$K$5:$K$400,$A20) -> 0 | E20: =COUNTIFS(Task_Tracking!$I$5:$I$400,"S4",Task_Tracking!$K$5:$K$400,$A20) -> 0 | F20: =SUM(B20:E20) -> 18 | G20: =COUNTIFS(Task_Tracking!$K$5:$K$400,$A20,Task_Tracking!$L$5:$L$400,"Done") -> 0 | H20: =IFERROR(G20/F20,0) -> 0
A21: =Team!A8 -> Sơn | B21: =COUNTIFS(Task_Tracking!$I$5:$I$400,"S1",Task_Tracking!$K$5:$K$400,$A21) -> 9 | C21: =COUNTIFS(Task_Tracking!$I$5:$I$400,"S2",Task_Tracking!$K$5:$K$400,$A21) -> 7 | D21: =COUNTIFS(Task_Tracking!$I$5:$I$400,"S3",Task_Tracking!$K$5:$K$400,$A21) -> 0 | E21: =COUNTIFS(Task_Tracking!$I$5:$I$400,"S4",Task_Tracking!$K$5:$K$400,$A21) -> 0 | F21: =SUM(B21:E21) -> 16 | G21: =COUNTIFS(Task_Tracking!$K$5:$K$400,$A21,Task_Tracking!$L$5:$L$400,"Done") -> 0 | H21: =IFERROR(G21/F21,0) -> 0
A22: =Team!A9 -> Hoàng | B22: =COUNTIFS(Task_Tracking!$I$5:$I$400,"S1",Task_Tracking!$K$5:$K$400,$A22) -> 6 | C22: =COUNTIFS(Task_Tracking!$I$5:$I$400,"S2",Task_Tracking!$K$5:$K$400,$A22) -> 10 | D22: =COUNTIFS(Task_Tracking!$I$5:$I$400,"S3",Task_Tracking!$K$5:$K$400,$A22) -> 0 | E22: =COUNTIFS(Task_Tracking!$I$5:$I$400,"S4",Task_Tracking!$K$5:$K$400,$A22) -> 0 | F22: =SUM(B22:E22) -> 16 | G22: =COUNTIFS(Task_Tracking!$K$5:$K$400,$A22,Task_Tracking!$L$5:$L$400,"Done") -> 0 | H22: =IFERROR(G22/F22,0) -> 0
A23: (Chưa gán) | B23: =COUNTIFS(Task_Tracking!$I$5:$I$400,"S1",Task_Tracking!$G$5:$G$400,"<>",Task_Tracking!$K$5:$K$400,"") -> 0 | C23: =COUNTIFS(Task_Tracking!$I$5:$I$400,"S2",Task_Tracking!$G$5:$G$400,"<>",Task_Tracking!$K$5:$K$400,"") -> 0 | D23: =COUNTIFS(Task_Tracking!$I$5:$I$400,"S3",Task_Tracking!$G$5:$G$400,"<>",Task_Tracking!$K$5:$K$400,"") -> 67 | E23: =COUNTIFS(Task_Tracking!$I$5:$I$400,"S4",Task_Tracking!$G$5:$G$400,"<>",Task_Tracking!$K$5:$K$400,"") -> 7 | F23: =SUM(B23:E23) -> 74 | G23: =COUNTIFS(Task_Tracking!$G$5:$G$400,"<>",Task_Tracking!$K$5:$K$400,"",Task_Tracking!$L$5:$L$400,"Done") -> 0 | H23: =IFERROR(G23/F23,0) -> 0
A25: Theo epic
A26: Epic | B26: Tên epic | C26: Backend | D26: Portal | E26: Mobile | F26: Tổng task | G26: Done | H26: Còn lại | I26: Blocked | J26: Trễ | K26: % Done
A27: E1 | B27: Nền tảng & xác thực | C27: =COUNTIFS(Task_Tracking!$B$5:$B$400,$A27,Task_Tracking!$F$5:$F$400,"Backend") -> 3 | D27: =COUNTIFS(Task_Tracking!$B$5:$B$400,$A27,Task_Tracking!$F$5:$F$400,"Portal") -> 2 | E27: =COUNTIFS(Task_Tracking!$B$5:$B$400,$A27,Task_Tracking!$F$5:$F$400,"Mobile") -> 2 | F27: =SUM(C27:E27) -> 7 | G27: =COUNTIFS(Task_Tracking!$B$5:$B$400,$A27,Task_Tracking!$L$5:$L$400,"Done") -> 0 | H27: =F27-G27 -> 7 | I27: =COUNTIFS(Task_Tracking!$B$5:$B$400,$A27,Task_Tracking!$L$5:$L$400,"Blocked") -> 0 | J27: =COUNTIFS(Task_Tracking!$B$5:$B$400,$A27,Task_Tracking!$M$5:$M$400,"Trễ") -> 0 | K27: =IFERROR(G27/F27,0) -> 0
A28: E2 | B28: Dữ liệu gốc | C28: =COUNTIFS(Task_Tracking!$B$5:$B$400,$A28,Task_Tracking!$F$5:$F$400,"Backend") -> 12 | D28: =COUNTIFS(Task_Tracking!$B$5:$B$400,$A28,Task_Tracking!$F$5:$F$400,"Portal") -> 11 | E28: =COUNTIFS(Task_Tracking!$B$5:$B$400,$A28,Task_Tracking!$F$5:$F$400,"Mobile") -> 3 | F28: =SUM(C28:E28) -> 26 | G28: =COUNTIFS(Task_Tracking!$B$5:$B$400,$A28,Task_Tracking!$L$5:$L$400,"Done") -> 0 | H28: =F28-G28 -> 26 | I28: =COUNTIFS(Task_Tracking!$B$5:$B$400,$A28,Task_Tracking!$L$5:$L$400,"Blocked") -> 0 | J28: =COUNTIFS(Task_Tracking!$B$5:$B$400,$A28,Task_Tracking!$M$5:$M$400,"Trễ") -> 0 | K28: =IFERROR(G28/F28,0) -> 0
A29: E3 | B29: Bán hàng & đơn hàng | C29: =COUNTIFS(Task_Tracking!$B$5:$B$400,$A29,Task_Tracking!$F$5:$F$400,"Backend") -> 13 | D29: =COUNTIFS(Task_Tracking!$B$5:$B$400,$A29,Task_Tracking!$F$5:$F$400,"Portal") -> 5 | E29: =COUNTIFS(Task_Tracking!$B$5:$B$400,$A29,Task_Tracking!$F$5:$F$400,"Mobile") -> 8 | F29: =SUM(C29:E29) -> 26 | G29: =COUNTIFS(Task_Tracking!$B$5:$B$400,$A29,Task_Tracking!$L$5:$L$400,"Done") -> 0 | H29: =F29-G29 -> 26 | I29: =COUNTIFS(Task_Tracking!$B$5:$B$400,$A29,Task_Tracking!$L$5:$L$400,"Blocked") -> 0 | J29: =COUNTIFS(Task_Tracking!$B$5:$B$400,$A29,Task_Tracking!$M$5:$M$400,"Trễ") -> 0 | K29: =IFERROR(G29/F29,0) -> 0
A30: E4 | B30: Kho & tồn kho | C30: =COUNTIFS(Task_Tracking!$B$5:$B$400,$A30,Task_Tracking!$F$5:$F$400,"Backend") -> 15 | D30: =COUNTIFS(Task_Tracking!$B$5:$B$400,$A30,Task_Tracking!$F$5:$F$400,"Portal") -> 9 | E30: =COUNTIFS(Task_Tracking!$B$5:$B$400,$A30,Task_Tracking!$F$5:$F$400,"Mobile") -> 4 | F30: =SUM(C30:E30) -> 28 | G30: =COUNTIFS(Task_Tracking!$B$5:$B$400,$A30,Task_Tracking!$L$5:$L$400,"Done") -> 0 | H30: =F30-G30 -> 28 | I30: =COUNTIFS(Task_Tracking!$B$5:$B$400,$A30,Task_Tracking!$L$5:$L$400,"Blocked") -> 0 | J30: =COUNTIFS(Task_Tracking!$B$5:$B$400,$A30,Task_Tracking!$M$5:$M$400,"Trễ") -> 0 | K30: =IFERROR(G30/F30,0) -> 0
A31: E5 | B31: Vận chuyển & giao nhận | C31: =COUNTIFS(Task_Tracking!$B$5:$B$400,$A31,Task_Tracking!$F$5:$F$400,"Backend") -> 9 | D31: =COUNTIFS(Task_Tracking!$B$5:$B$400,$A31,Task_Tracking!$F$5:$F$400,"Portal") -> 5 | E31: =COUNTIFS(Task_Tracking!$B$5:$B$400,$A31,Task_Tracking!$F$5:$F$400,"Mobile") -> 3 | F31: =SUM(C31:E31) -> 17 | G31: =COUNTIFS(Task_Tracking!$B$5:$B$400,$A31,Task_Tracking!$L$5:$L$400,"Done") -> 0 | H31: =F31-G31 -> 17 | I31: =COUNTIFS(Task_Tracking!$B$5:$B$400,$A31,Task_Tracking!$L$5:$L$400,"Blocked") -> 0 | J31: =COUNTIFS(Task_Tracking!$B$5:$B$400,$A31,Task_Tracking!$M$5:$M$400,"Trễ") -> 0 | K31: =IFERROR(G31/F31,0) -> 0
A32: E6 | B32: Thanh toán & công nợ | C32: =COUNTIFS(Task_Tracking!$B$5:$B$400,$A32,Task_Tracking!$F$5:$F$400,"Backend") -> 6 | D32: =COUNTIFS(Task_Tracking!$B$5:$B$400,$A32,Task_Tracking!$F$5:$F$400,"Portal") -> 3 | E32: =COUNTIFS(Task_Tracking!$B$5:$B$400,$A32,Task_Tracking!$F$5:$F$400,"Mobile") -> 3 | F32: =SUM(C32:E32) -> 12 | G32: =COUNTIFS(Task_Tracking!$B$5:$B$400,$A32,Task_Tracking!$L$5:$L$400,"Done") -> 0 | H32: =F32-G32 -> 12 | I32: =COUNTIFS(Task_Tracking!$B$5:$B$400,$A32,Task_Tracking!$L$5:$L$400,"Blocked") -> 0 | J32: =COUNTIFS(Task_Tracking!$B$5:$B$400,$A32,Task_Tracking!$M$5:$M$400,"Trễ") -> 0 | K32: =IFERROR(G32/F32,0) -> 0
A33: E7 | B33: Loyalty | C33: =COUNTIFS(Task_Tracking!$B$5:$B$400,$A33,Task_Tracking!$F$5:$F$400,"Backend") -> 6 | D33: =COUNTIFS(Task_Tracking!$B$5:$B$400,$A33,Task_Tracking!$F$5:$F$400,"Portal") -> 4 | E33: =COUNTIFS(Task_Tracking!$B$5:$B$400,$A33,Task_Tracking!$F$5:$F$400,"Mobile") -> 2 | F33: =SUM(C33:E33) -> 12 | G33: =COUNTIFS(Task_Tracking!$B$5:$B$400,$A33,Task_Tracking!$L$5:$L$400,"Done") -> 0 | H33: =F33-G33 -> 12 | I33: =COUNTIFS(Task_Tracking!$B$5:$B$400,$A33,Task_Tracking!$L$5:$L$400,"Blocked") -> 0 | J33: =COUNTIFS(Task_Tracking!$B$5:$B$400,$A33,Task_Tracking!$M$5:$M$400,"Trễ") -> 0 | K33: =IFERROR(G33/F33,0) -> 0
A34: E8 | B34: Báo cáo & thông báo | C34: =COUNTIFS(Task_Tracking!$B$5:$B$400,$A34,Task_Tracking!$F$5:$F$400,"Backend") -> 6 | D34: =COUNTIFS(Task_Tracking!$B$5:$B$400,$A34,Task_Tracking!$F$5:$F$400,"Portal") -> 5 | E34: =COUNTIFS(Task_Tracking!$B$5:$B$400,$A34,Task_Tracking!$F$5:$F$400,"Mobile") -> 3 | F34: =SUM(C34:E34) -> 14 | G34: =COUNTIFS(Task_Tracking!$B$5:$B$400,$A34,Task_Tracking!$L$5:$L$400,"Done") -> 0 | H34: =F34-G34 -> 14 | I34: =COUNTIFS(Task_Tracking!$B$5:$B$400,$A34,Task_Tracking!$L$5:$L$400,"Blocked") -> 0 | J34: =COUNTIFS(Task_Tracking!$B$5:$B$400,$A34,Task_Tracking!$M$5:$M$400,"Trễ") -> 0 | K34: =IFERROR(G34/F34,0) -> 0
A35: E9 | B35: Kiểm thử & bàn giao | C35: =COUNTIFS(Task_Tracking!$B$5:$B$400,$A35,Task_Tracking!$F$5:$F$400,"Backend") -> 3 | D35: =COUNTIFS(Task_Tracking!$B$5:$B$400,$A35,Task_Tracking!$F$5:$F$400,"Portal") -> 2 | E35: =COUNTIFS(Task_Tracking!$B$5:$B$400,$A35,Task_Tracking!$F$5:$F$400,"Mobile") -> 2 | F35: =SUM(C35:E35) -> 7 | G35: =COUNTIFS(Task_Tracking!$B$5:$B$400,$A35,Task_Tracking!$L$5:$L$400,"Done") -> 0 | H35: =F35-G35 -> 7 | I35: =COUNTIFS(Task_Tracking!$B$5:$B$400,$A35,Task_Tracking!$L$5:$L$400,"Blocked") -> 0 | J35: =COUNTIFS(Task_Tracking!$B$5:$B$400,$A35,Task_Tracking!$M$5:$M$400,"Trễ") -> 0 | K35: =IFERROR(G35/F35,0) -> 0
A37: Theo nền tảng × status
A38: Nền tảng | B38: To Do | C38: In Progress | D38: In Review | E38: Done | F38: Blocked | G38: Tổng | H38: % Done
A39: Backend | B39: =COUNTIFS(Task_Tracking!$F$5:$F$400,$A39,Task_Tracking!$L$5:$L$400,"To Do") -> 73 | C39: =COUNTIFS(Task_Tracking!$F$5:$F$400,$A39,Task_Tracking!$L$5:$L$400,"In Progress") -> 0 | D39: =COUNTIFS(Task_Tracking!$F$5:$F$400,$A39,Task_Tracking!$L$5:$L$400,"In Review") -> 0 | E39: =COUNTIFS(Task_Tracking!$F$5:$F$400,$A39,Task_Tracking!$L$5:$L$400,"Done") -> 0 | F39: =COUNTIFS(Task_Tracking!$F$5:$F$400,$A39,Task_Tracking!$L$5:$L$400,"Blocked") -> 0 | G39: =SUM(B39:F39) -> 73 | H39: =IFERROR(E39/G39,0) -> 0
A40: Portal | B40: =COUNTIFS(Task_Tracking!$F$5:$F$400,$A40,Task_Tracking!$L$5:$L$400,"To Do") -> 46 | C40: =COUNTIFS(Task_Tracking!$F$5:$F$400,$A40,Task_Tracking!$L$5:$L$400,"In Progress") -> 0 | D40: =COUNTIFS(Task_Tracking!$F$5:$F$400,$A40,Task_Tracking!$L$5:$L$400,"In Review") -> 0 | E40: =COUNTIFS(Task_Tracking!$F$5:$F$400,$A40,Task_Tracking!$L$5:$L$400,"Done") -> 0 | F40: =COUNTIFS(Task_Tracking!$F$5:$F$400,$A40,Task_Tracking!$L$5:$L$400,"Blocked") -> 0 | G40: =SUM(B40:F40) -> 46 | H40: =IFERROR(E40/G40,0) -> 0
A41: Mobile | B41: =COUNTIFS(Task_Tracking!$F$5:$F$400,$A41,Task_Tracking!$L$5:$L$400,"To Do") -> 30 | C41: =COUNTIFS(Task_Tracking!$F$5:$F$400,$A41,Task_Tracking!$L$5:$L$400,"In Progress") -> 0 | D41: =COUNTIFS(Task_Tracking!$F$5:$F$400,$A41,Task_Tracking!$L$5:$L$400,"In Review") -> 0 | E41: =COUNTIFS(Task_Tracking!$F$5:$F$400,$A41,Task_Tracking!$L$5:$L$400,"Done") -> 0 | F41: =COUNTIFS(Task_Tracking!$F$5:$F$400,$A41,Task_Tracking!$L$5:$L$400,"Blocked") -> 0 | G41: =SUM(B41:F41) -> 30 | H41: =IFERROR(E41/G41,0) -> 0

Sheet Sprints
A1: Kế hoạch 4 sprint (2 tuần / sprint, 8 tuần)
A2: Chỉ sửa ngày bắt đầu Sprint 1 (ô B5, chữ xanh); các sprint sau tự lùi theo. Hôm nay: | F2: =TODAY() -> 46309
A4: Sprint | B4: Bắt đầu | C4: Kết thúc | D4: Mục tiêu sprint | E4: Số task | F4: Done | G4: % Done | H4: Trạng thái
A5: S1 | B5: 46313 | C5: =B5+13 -> 46326 | D5: Nền tảng & dữ liệu gốc: đăng nhập, phân quyền, hồ sơ, người dùng, danh mục, sản phẩm, kho, khu vực, retailer, MLOR, kỳ hạn công nợ, bảng vận chuyển + khoảng cách + ETA | E5: =COUNTIF(Task_Tracking!$I$5:$I$400,A5) -> 32 | F5: =COUNTIFS(Task_Tracking!$I$5:$I$400,A5,Task_Tracking!$L$5:$L$400,"Done") -> 0 | G5: =IFERROR(F5/E5,0) -> 0 | H5: =IF(TODAY()>C5,"Đã qua",IF(TODAY()>=B5,"Đang chạy","Sắp tới")) -> Sắp tới
A6: S2 | B6: =B5+14 -> 46327 | C6: =B6+13 -> 46340 | D6: Luồng đặt đơn → phân bổ → kho: khuyến mãi, báo giá, tạo đơn online, phân bổ có trọng số + giải thích, duyệt đơn, nhập kho + tem, picking + quét xuất, thanh toán, khai báo retailer | E6: =COUNTIF(Task_Tracking!$I$5:$I$400,A6) -> 43 | F6: =COUNTIFS(Task_Tracking!$I$5:$I$400,A6,Task_Tracking!$L$5:$L$400,"Done") -> 0 | G6: =IFERROR(F6/E6,0) -> 0 | H6: =IF(TODAY()>C6,"Đã qua",IF(TODAY()>=B6,"Đang chạy","Sắp tới")) -> Sắp tới
A7: S3 | B7: =B6+14 -> 46341 | C7: =B7+13 -> 46354 | D7: Offline + đồng bộ, giao nhận (xe, điều phối, nhận hàng QR), công nợ một phần, giảm giá HSD, hủy, điều chuyển, luân chuyển cận hạn, thông báo in-app | E7: =COUNTIF(Task_Tracking!$I$5:$I$400,A7) -> 67 | F7: =COUNTIFS(Task_Tracking!$I$5:$I$400,A7,Task_Tracking!$L$5:$L$400,"Done") -> 0 | G7: =IFERROR(F7/E7,0) -> 0 | H7: =IF(TODAY()>C7,"Đã qua",IF(TODAY()>=B7,"Đang chạy","Sắp tới")) -> Sắp tới
A8: S4 | B8: =B7+14 -> 46355 | C8: =B8+13 -> 46368 | D8: Loyalty (điểm, quà, đổi quà), KPI + xếp hạng + sản phẩm bán chạy, dashboard, khiếu nại, push, backtest; tuần cuối: test tích hợp, sửa lỗi, demo | E8: =COUNTIF(Task_Tracking!$I$5:$I$400,A8) -> 7 | F8: =COUNTIFS(Task_Tracking!$I$5:$I$400,A8,Task_Tracking!$L$5:$L$400,"Done") -> 0 | G8: =IFERROR(F8/E8,0) -> 0 | H8: =IF(TODAY()>C8,"Đã qua",IF(TODAY()>=B8,"Đang chạy","Sắp tới")) -> Sắp tới
A9: S5 | B9: =B8+14 -> 46369 | C9: =B9+5 -> 46374 | D9: Backup Week
A10: 8 tuần tính cả tuần này: 12/10 → 06/12/2026. Tuần cuối của S4 (30/11 – 06/12) dành cho test tích hợp, sửa lỗi và chuẩn bị demo – không nhận chức năng mới.

Sheet Lists
A1: Status | B1: Priority | C1: Nền tảng | D1: Sprint
A2: To Do | B2: High | C2: Backend | D2: S1
A3: In Progress | B3: Medium | C3: Portal | D3: S2
A4: In Review | B4: Low | C4: Mobile | D4: S3
A5: Done | D5: S4
A6: Blocked

Sheet Huong_dan
A1: Hướng dẫn
A2: Cấu trúc: Epic → Module → Chức năng → mỗi nền tảng (Backend / Portal / Mobile) là một dòng task riêng trên Task_Tracking. Task ID = mã chức năng + nền tảng (F27-BE, F27-MB…); các dòng cùng mã F27 là cùng một chức năng.
A3: Cột PIC để trống: chọn người từ dropdown (danh sách ở sheet Team). Ô PIC tô vàng = task chưa có người nhận. Dashboard có bảng PIC × sprint để cân khối lượng khi chia.
A4: Sprint: 4 sprint × 2 tuần, từ 12/10 đến 06/12/2026 (8 tuần, tính cả tuần này – sheet Sprints). Tuần cuối S4 chỉ test, sửa lỗi, demo. Task chưa Done mà đã qua ngày kết thúc sprint sẽ hiện "Trễ".
A5: Ô được sửa: PIC, Status, Priority, Sprint (có thể dời task sang sprint khác), Bắt đầu, Hoàn thành, Ghi chú. Không sửa cột xám (Thời gian sprint, Trễ hạn).
A6: Thêm task: điền tiếp dòng trống dưới bảng (Task ID mới, Epic, Module, Chức năng, Nền tảng, Công việc, Sprint); công thức có sẵn tới dòng 400.
A8: Status | B8: Ý nghĩa
A9: To Do | B9: Chưa bắt đầu
A10: In Progress | B10: Đang code
A11: In Review | B11: Xong code, chờ review / test
A12: Done | B12: Đã merge, test pass trên môi trường chung
A13: Blocked | B13: Bị chặn – ghi lý do ở Ghi chú
A15: Priority | B15: Ý nghĩa
A16: High | B16: Luồng chính để demo / bảo vệ, hoặc mục GVHD / hội đồng đã chốt sau Review 1 (loyalty, KPI sau KM, sản phẩm bán chạy, giảm giá HSD, luân chuyển…)
A17: Medium | B17: Chức năng hỗ trợ trong scope; nếu trễ thì làm bản gọn, không bỏ
A18: Low | B18: Ngoài scope đã chốt, chỉ làm khi dư thời gian (hiện không có task nào)
A20: Nguyên tắc xếp sprint | B20: Làm theo phụ thuộc: dữ liệu gốc + bảng vận chuyển (S1) → đặt đơn, phân bổ, kho (S2) → offline, giao nhận, công nợ, luân chuyển (S3) → loyalty, KPI, báo cáo + test (S4). Backend và Portal / Mobile của cùng chức năng nằm cùng sprint.
A21: Ví dụ cập nhật | B21: F33-BE "Thuật toán phân bổ B1–B4": chọn PIC, Status = In Progress. Khi xong: Status = Done, điền ngày Hoàn thành; Dashboard tự cộng vào S2, E3, Backend và PIC đó.
