Workbook

Sheet Task_Tracking
A1: FSCM – Task tracking (Epic → Module → Chức năng → Backend / Portal / Mobile)
A2: Mỗi dòng là một task trên một nền tảng. Cột trắng: chọn PIC, Status, ngày, ghi chú. Cột xám tự tính. Lọc theo Epic / Module / Nền tảng / Sprint / PIC bằng nút lọc ở dòng tiêu đề.
A4: Task ID | B4: Epic | C4: Tên epic | D4: Module | E4: Chức năng | F4: Nền tảng | G4: Công việc | H4: Priority | I4: Sprint | J4: Thời gian sprint | K4: PIC | L4: Status | M4: Trễ hạn | N4: Bắt đầu | O4: Hoàn thành | P4: Ghi chú
A5: F08-BE | B5: E1 | C5: Nền tảng & xác thực | D5: Xác thực & phân quyền | E5: Đăng nhập Portal | F5: Backend | G5: Kiểm tra token đăng nhập Microsoft Entra ID cho Portal. Cung cấp API thông tin người đang đăng nhập gồm vai trò, kho, khu vực và phạm vi dữ liệu được xem. Trả lỗi rõ khi token hết hạn hoặc tài khoản bị khóa. | H5: High | I5: S1 | J5: {=IFERROR(TEXT(INDEX(Sprints!$B$5:$B$7,MATCH(I5,Sprints!$A$5:$A$7,0)),"dd/mm")&" – "&TEXT(INDEX(Sprints!$C$5:$C$7,MATCH(I5,Sprints!$A$5:$A$7,0)),"dd/mm"),"")} -> 19/10 – 01/11 | K5: Khiết | L5: To Do | M5: {=IFERROR(IF(AND(L5<>"Done",TODAY()>INDEX(Sprints!$C$5:$C$7,MATCH(I5,Sprints!$A$5:$A$7,0))),"Trễ",""),"")}
A6: F08-FE | B6: E1 | C6: Nền tảng & xác thực | D6: Xác thực & phân quyền | E6: Đăng nhập Portal | F6: Portal | G6: Làm đăng nhập Portal bằng tài khoản Microsoft qua MSAL. Sau đăng nhập lấy thông tin và quyền từ server để mở đúng trang. Khi phiên hết hạn thì yêu cầu đăng nhập lại, hiển thị lỗi thay vì để màn hình trống. | H6: High | I6: S1 | J6: {=IFERROR(TEXT(INDEX(Sprints!$B$5:$B$7,MATCH(I6,Sprints!$A$5:$A$7,0)),"dd/mm")&" – "&TEXT(INDEX(Sprints!$C$5:$C$7,MATCH(I6,Sprints!$A$5:$A$7,0)),"dd/mm"),"")} -> 19/10 – 01/11 | K6: Hoàng | L6: To Do | M6: {=IFERROR(IF(AND(L6<>"Done",TODAY()>INDEX(Sprints!$C$5:$C$7,MATCH(I6,Sprints!$A$5:$A$7,0))),"Trễ",""),"")}
A7: F09-BE | B7: E1 | C7: Nền tảng & xác thực | D7: Xác thực & phân quyền | E7: Đăng nhập app mobile | F7: Backend | G7: Thống nhất cơ chế xác thực mobile với người làm app và triển khai phần server tương ứng. Trả thông tin tài khoản, vai trò và phạm vi dữ liệu sau đăng nhập. App và Portal phải dùng cùng danh tính và quyền của người dùng. | H7: High | I7: S1 | J7: {=IFERROR(TEXT(INDEX(Sprints!$B$5:$B$7,MATCH(I7,Sprints!$A$5:$A$7,0)),"dd/mm")&" – "&TEXT(INDEX(Sprints!$C$5:$C$7,MATCH(I7,Sprints!$A$5:$A$7,0)),"dd/mm"),"")} -> 19/10 – 01/11 | K7: Hải | L7: To Do | M7: {=IFERROR(IF(AND(L7<>"Done",TODAY()>INDEX(Sprints!$C$5:$C$7,MATCH(I7,Sprints!$A$5:$A$7,0))),"Trễ",""),"")} | P7: Mock đang dùng SĐT + mật khẩu
A8: F09-MB | B8: E1 | C8: Nền tảng & xác thực | D8: Xác thực & phân quyền | E8: Đăng nhập app mobile | F8: Mobile | G8: Làm màn đăng nhập app theo cơ chế đã thống nhất với F09-BE. Lưu thông tin phiên bằng bộ lưu trữ bảo mật, khôi phục phiên còn hiệu lực khi mở app và xóa phiên khi đăng xuất. Báo rõ sai thông tin hoặc tài khoản bị khóa. | H8: High | I8: S1 | J8: {=IFERROR(TEXT(INDEX(Sprints!$B$5:$B$7,MATCH(I8,Sprints!$A$5:$A$7,0)),"dd/mm")&" – "&TEXT(INDEX(Sprints!$C$5:$C$7,MATCH(I8,Sprints!$A$5:$A$7,0)),"dd/mm"),"")} -> 19/10 – 01/11 | K8: Sơn | L8: To Do | M8: {=IFERROR(IF(AND(L8<>"Done",TODAY()>INDEX(Sprints!$C$5:$C$7,MATCH(I8,Sprints!$A$5:$A$7,0))),"Trễ",""),"")} | P8: Mock đang dùng SĐT + mật khẩu
A9: F10-BE | B9: E1 | C9: Nền tảng & xác thực | D9: Xác thực & phân quyền | E9: Phân quyền theo vai trò | F9: Backend | G9: Áp dụng phân quyền cho toàn bộ API theo sáu vai trò: Admin, Operator, Sales Manager, Warehouse Keeper, Sales, Retailer. Ngoài vai trò còn kiểm tra đúng kho, khu vực, nhóm Sales hoặc retailer. Chặn cả trường hợp sửa mã trên URL để xem dữ liệu ngoài quyền. | H9: High | I9: S1 | J9: {=IFERROR(TEXT(INDEX(Sprints!$B$5:$B$7,MATCH(I9,Sprints!$A$5:$A$7,0)),"dd/mm")&" – "&TEXT(INDEX(Sprints!$C$5:$C$7,MATCH(I9,Sprints!$A$5:$A$7,0)),"dd/mm"),"")} -> 19/10 – 01/11 | K9: Khiết | L9: To Do | M9: {=IFERROR(IF(AND(L9<>"Done",TODAY()>INDEX(Sprints!$C$5:$C$7,MATCH(I9,Sprints!$A$5:$A$7,0))),"Trễ",""),"")}
A10: F10-FE | B10: E1 | C10: Nền tảng & xác thực | D10: Xác thực & phân quyền | E10: Phân quyền theo vai trò | F10: Portal | G10: Chỉ hiện menu và nút thao tác phù hợp với vai trò đăng nhập trên Portal. Chặn truy cập trực tiếp đường dẫn ngoài quyền và hiện thông báo không đủ quyền. Quyền trên màn hình phải khớp với API, không chỉ ẩn menu. | H10: High | I10: S1 | J10: {=IFERROR(TEXT(INDEX(Sprints!$B$5:$B$7,MATCH(I10,Sprints!$A$5:$A$7,0)),"dd/mm")&" – "&TEXT(INDEX(Sprints!$C$5:$C$7,MATCH(I10,Sprints!$A$5:$A$7,0)),"dd/mm"),"")} -> 19/10 – 01/11 | K10: Sơn | L10: To Do | M10: {=IFERROR(IF(AND(L10<>"Done",TODAY()>INDEX(Sprints!$C$5:$C$7,MATCH(I10,Sprints!$A$5:$A$7,0))),"Trễ",""),"")}
A11: F10-MB | B11: E1 | C11: Nền tảng & xác thực | D11: Xác thực & phân quyền | E11: Phân quyền theo vai trò | F11: Mobile | G11: Mở đúng màn và nhóm chức năng cho Sales, Thủ kho hoặc Retailer sau đăng nhập. Ẩn thao tác ngoài vai trò và xử lý lỗi không đủ quyền từ server. Retailer chỉ theo dõi, nhận hàng và dùng chức năng được cấp, không tự đặt đơn. | H11: High | I11: S1 | J11: {=IFERROR(TEXT(INDEX(Sprints!$B$5:$B$7,MATCH(I11,Sprints!$A$5:$A$7,0)),"dd/mm")&" – "&TEXT(INDEX(Sprints!$C$5:$C$7,MATCH(I11,Sprints!$A$5:$A$7,0)),"dd/mm"),"")} -> 19/10 – 01/11 | K11: Hoàng | L11: To Do | M11: {=IFERROR(IF(AND(L11<>"Done",TODAY()>INDEX(Sprints!$C$5:$C$7,MATCH(I11,Sprints!$A$5:$A$7,0))),"Trễ",""),"")}
A12: F11-BE | B12: E2 | C12: Dữ liệu gốc | D12: Người dùng | E12: Seed Admin, không tạo Admin trên UI | F12: Backend | G12: Tạo sẵn tài khoản Admin ban đầu khi triển khai hệ thống. Chặn API tạo hoặc đổi tài khoản thông thường thành Admin. Chạy bước khởi tạo nhiều lần không tạo trùng Admin. | H12: High | I12: S1 | J12: {=IFERROR(TEXT(INDEX(Sprints!$B$5:$B$7,MATCH(I12,Sprints!$A$5:$A$7,0)),"dd/mm")&" – "&TEXT(INDEX(Sprints!$C$5:$C$7,MATCH(I12,Sprints!$A$5:$A$7,0)),"dd/mm"),"")} -> 19/10 – 01/11 | K12: Khiết | L12: To Do | M12: {=IFERROR(IF(AND(L12<>"Done",TODAY()>INDEX(Sprints!$C$5:$C$7,MATCH(I12,Sprints!$A$5:$A$7,0))),"Trễ",""),"")} | P12: Chốt 02/10
A13: F11-FE | B13: E2 | C13: Dữ liệu gốc | D13: Người dùng | E13: Seed Admin, không tạo Admin trên UI | F13: Portal | G13: Trong form quản lý người dùng, chỉ cho chọn các vai trò được phép tạo. Không có lựa chọn tạo Admin hoặc nâng tài khoản thành Admin. Hiển thị lỗi từ server nếu thao tác không hợp lệ. | H13: High | I13: S1 | J13: {=IFERROR(TEXT(INDEX(Sprints!$B$5:$B$7,MATCH(I13,Sprints!$A$5:$A$7,0)),"dd/mm")&" – "&TEXT(INDEX(Sprints!$C$5:$C$7,MATCH(I13,Sprints!$A$5:$A$7,0)),"dd/mm"),"")} -> 19/10 – 01/11 | K13: Hoàng | L13: To Do | M13: {=IFERROR(IF(AND(L13<>"Done",TODAY()>INDEX(Sprints!$C$5:$C$7,MATCH(I13,Sprints!$A$5:$A$7,0))),"Trễ",""),"")} | P13: Chốt 02/10
A14: F12-BE | B14: E2 | C14: Dữ liệu gốc | D14: Người dùng | E14: Quản lý người dùng | F14: Backend | G14: Cung cấp API danh sách, tạo, sửa và khóa tài khoản. Lưu vai trò và liên kết cần thiết như kho của Thủ kho, khu vực/nhóm của Sales hoặc retailer của tài khoản khách. Kiểm tra dữ liệu trùng và quyền của người thao tác. | H14: High | I14: S1 | J14: {=IFERROR(TEXT(INDEX(Sprints!$B$5:$B$7,MATCH(I14,Sprints!$A$5:$A$7,0)),"dd/mm")&" – "&TEXT(INDEX(Sprints!$C$5:$C$7,MATCH(I14,Sprints!$A$5:$A$7,0)),"dd/mm"),"")} -> 19/10 – 01/11 | K14: Khiết | L14: To Do | M14: {=IFERROR(IF(AND(L14<>"Done",TODAY()>INDEX(Sprints!$C$5:$C$7,MATCH(I14,Sprints!$A$5:$A$7,0))),"Trễ",""),"")}
A15: F12-FE | B15: E2 | C15: Dữ liệu gốc | D15: Người dùng | E15: Quản lý người dùng | F15: Portal | G15: Làm màn quản lý người dùng trên Portal gồm tìm kiếm, lọc, tạo, sửa và khóa tài khoản. Form thay đổi trường gán kho, khu vực, nhóm hoặc retailer theo vai trò đã chọn. Hiển thị rõ trạng thái tài khoản và lỗi nhập liệu. | H15: High | I15: S1 | J15: {=IFERROR(TEXT(INDEX(Sprints!$B$5:$B$7,MATCH(I15,Sprints!$A$5:$A$7,0)),"dd/mm")&" – "&TEXT(INDEX(Sprints!$C$5:$C$7,MATCH(I15,Sprints!$A$5:$A$7,0)),"dd/mm"),"")} -> 19/10 – 01/11 | K15: Hoàng | L15: To Do | M15: {=IFERROR(IF(AND(L15<>"Done",TODAY()>INDEX(Sprints!$C$5:$C$7,MATCH(I15,Sprints!$A$5:$A$7,0))),"Trễ",""),"")}
A16: F13-MB | B16: E2 | C16: Dữ liệu gốc | D16: Người dùng | E16: Hồ sơ cá nhân trên app | F16: Mobile | G16: Làm màn hồ sơ trên app để người dùng xem tên, tài khoản, vai trò và thông tin được gán. Có nút đăng xuất và xóa phiên đăng nhập trên thiết bị. Không cho tự sửa vai trò hoặc phạm vi quản lý. | H16: High | I16: S1 | J16: {=IFERROR(TEXT(INDEX(Sprints!$B$5:$B$7,MATCH(I16,Sprints!$A$5:$A$7,0)),"dd/mm")&" – "&TEXT(INDEX(Sprints!$C$5:$C$7,MATCH(I16,Sprints!$A$5:$A$7,0)),"dd/mm"),"")} -> 19/10 – 01/11 | K16: Hoàng | L16: To Do | M16: {=IFERROR(IF(AND(L16<>"Done",TODAY()>INDEX(Sprints!$C$5:$C$7,MATCH(I16,Sprints!$A$5:$A$7,0))),"Trễ",""),"")}
A17: F14-BE | B17: E2 | C17: Dữ liệu gốc | D17: Danh mục & sản phẩm | E17: Danh mục sản phẩm | F17: Backend | G17: Cung cấp API quản lý danh mục sản phẩm: danh sách, tạo, sửa và trạng thái sử dụng. Sinh mã danh mục theo quy ước, kiểm tra tên/mã trùng. Danh mục đã được sản phẩm sử dụng phải được kiểm tra trước khi xóa. | H17: High | I17: S1 | J17: {=IFERROR(TEXT(INDEX(Sprints!$B$5:$B$7,MATCH(I17,Sprints!$A$5:$A$7,0)),"dd/mm")&" – "&TEXT(INDEX(Sprints!$C$5:$C$7,MATCH(I17,Sprints!$A$5:$A$7,0)),"dd/mm"),"")} -> 19/10 – 01/11 | K17: Khiết | L17: To Do | M17: {=IFERROR(IF(AND(L17<>"Done",TODAY()>INDEX(Sprints!$C$5:$C$7,MATCH(I17,Sprints!$A$5:$A$7,0))),"Trễ",""),"")}
A18: F14-FE | B18: E2 | C18: Dữ liệu gốc | D18: Danh mục & sản phẩm | E18: Danh mục sản phẩm | F18: Portal | G18: Làm màn danh mục sản phẩm với danh sách, tìm kiếm và form tạo/sửa. Cho chọn trạng thái sử dụng và hiển thị lỗi trùng hoặc không thể xóa. Danh sách danh mục này được dùng trong form sản phẩm. | H18: High | I18: S1 | J18: {=IFERROR(TEXT(INDEX(Sprints!$B$5:$B$7,MATCH(I18,Sprints!$A$5:$A$7,0)),"dd/mm")&" – "&TEXT(INDEX(Sprints!$C$5:$C$7,MATCH(I18,Sprints!$A$5:$A$7,0)),"dd/mm"),"")} -> 19/10 – 01/11 | K18: Sơn | L18: To Do | M18: {=IFERROR(IF(AND(L18<>"Done",TODAY()>INDEX(Sprints!$C$5:$C$7,MATCH(I18,Sprints!$A$5:$A$7,0))),"Trễ",""),"")}
A19: F15-BE | B19: E2 | C19: Dữ liệu gốc | D19: Danh mục & sản phẩm | E19: Sản phẩm Nháp → Publish → Inactive | F19: Backend | G19: Xử lý vòng đời sản phẩm: Nháp, Đã công bố và Ngừng kinh doanh. Cho sửa sản phẩm khi còn Nháp, kiểm tra đủ dữ liệu SKU và hạn sử dụng trước khi công bố. Chặn sửa thông tin đã khóa sau công bố và chặn đặt mới sản phẩm ngừng kinh doanh. | H19: High | I19: S1 | J19: {=IFERROR(TEXT(INDEX(Sprints!$B$5:$B$7,MATCH(I19,Sprints!$A$5:$A$7,0)),"dd/mm")&" – "&TEXT(INDEX(Sprints!$C$5:$C$7,MATCH(I19,Sprints!$A$5:$A$7,0)),"dd/mm"),"")} -> 19/10 – 01/11 | K19: Khiết | L19: To Do | M19: {=IFERROR(IF(AND(L19<>"Done",TODAY()>INDEX(Sprints!$C$5:$C$7,MATCH(I19,Sprints!$A$5:$A$7,0))),"Trễ",""),"")} | P19: Chốt 02/10
A20: F15-FE | B20: E2 | C20: Dữ liệu gốc | D20: Danh mục & sản phẩm | E20: Sản phẩm Nháp → Publish → Inactive | F20: Portal | G20: Làm danh sách và form sản phẩm gồm SKU, danh mục, quy cách, giá và hạn sử dụng. Có nút công bố hoặc ngừng kinh doanh theo trạng thái. Sau công bố khóa các trường không được sửa, hướng người dùng sang tạo bản mới khi cần thay đổi. | H20: High | I20: S1 | J20: {=IFERROR(TEXT(INDEX(Sprints!$B$5:$B$7,MATCH(I20,Sprints!$A$5:$A$7,0)),"dd/mm")&" – "&TEXT(INDEX(Sprints!$C$5:$C$7,MATCH(I20,Sprints!$A$5:$A$7,0)),"dd/mm"),"")} -> 19/10 – 01/11 | K20: Hoàng | L20: To Do | M20: {=IFERROR(IF(AND(L20<>"Done",TODAY()>INDEX(Sprints!$C$5:$C$7,MATCH(I20,Sprints!$A$5:$A$7,0))),"Trễ",""),"")} | P20: Chốt 02/10
A21: F16-BE | B21: E2 | C21: Dữ liệu gốc | D21: Danh mục & sản phẩm | E21: Clone sản phẩm để sửa | F21: Backend | G21: Cung cấp API sao chép thông tin sản phẩm đã có thành một sản phẩm Nháp với SKU mới. Không sao chép tồn kho, batch hoặc giao dịch của SKU cũ. Kiểm tra SKU mới không trùng trước khi lưu. | H21: High | I21: S1 | J21: {=IFERROR(TEXT(INDEX(Sprints!$B$5:$B$7,MATCH(I21,Sprints!$A$5:$A$7,0)),"dd/mm")&" – "&TEXT(INDEX(Sprints!$C$5:$C$7,MATCH(I21,Sprints!$A$5:$A$7,0)),"dd/mm"),"")} -> 19/10 – 01/11 | K21: Hải | L21: To Do | M21: {=IFERROR(IF(AND(L21<>"Done",TODAY()>INDEX(Sprints!$C$5:$C$7,MATCH(I21,Sprints!$A$5:$A$7,0))),"Trễ",""),"")}
A22: F16-FE | B22: E2 | C22: Dữ liệu gốc | D22: Danh mục & sản phẩm | E22: Clone sản phẩm để sửa | F22: Portal | G22: Thêm nút Tạo bản mới từ sản phẩm này trên chi tiết sản phẩm. Mở form điền sẵn thông tin có thể sao chép, yêu cầu SKU mới và cho chỉnh trước khi lưu Nháp. Hiển thị rõ bản mới là một sản phẩm riêng. | H22: High | I22: S1 | J22: {=IFERROR(TEXT(INDEX(Sprints!$B$5:$B$7,MATCH(I22,Sprints!$A$5:$A$7,0)),"dd/mm")&" – "&TEXT(INDEX(Sprints!$C$5:$C$7,MATCH(I22,Sprints!$A$5:$A$7,0)),"dd/mm"),"")} -> 19/10 – 01/11 | K22: Sơn | L22: To Do | M22: {=IFERROR(IF(AND(L22<>"Done",TODAY()>INDEX(Sprints!$C$5:$C$7,MATCH(I22,Sprints!$A$5:$A$7,0))),"Trễ",""),"")}
A23: F17-BE | B23: E2 | C23: Dữ liệu gốc | D23: Kho | E23: Quản lý kho | F23: Backend | G23: Cung cấp API quản lý kho: mã, tên, loại kho, địa chỉ, tọa độ, Thủ kho và ngưỡng tồn tối thiểu. Kiểm tra mã trùng và tọa độ hợp lệ. Dữ liệu kho được dùng để nhập hàng và phân bổ xuất trực tiếp tới retailer. | H23: High | I23: S1 | J23: {=IFERROR(TEXT(INDEX(Sprints!$B$5:$B$7,MATCH(I23,Sprints!$A$5:$A$7,0)),"dd/mm")&" – "&TEXT(INDEX(Sprints!$C$5:$C$7,MATCH(I23,Sprints!$A$5:$A$7,0)),"dd/mm"),"")} -> 19/10 – 01/11 | K23: Hải | L23: To Do | M23: {=IFERROR(IF(AND(L23<>"Done",TODAY()>INDEX(Sprints!$C$5:$C$7,MATCH(I23,Sprints!$A$5:$A$7,0))),"Trễ",""),"")}
A24: F17-FE | B24: E2 | C24: Dữ liệu gốc | D24: Kho | E24: Quản lý kho | F24: Portal | G24: Làm danh sách, chi tiết và form tạo/sửa kho trên Portal. Cho nhập địa chỉ, tọa độ, loại kho, Thủ kho và tồn tối thiểu. Hiển thị lỗi dữ liệu và trạng thái hoạt động của kho. | H24: High | I24: S1 | J24: {=IFERROR(TEXT(INDEX(Sprints!$B$5:$B$7,MATCH(I24,Sprints!$A$5:$A$7,0)),"dd/mm")&" – "&TEXT(INDEX(Sprints!$C$5:$C$7,MATCH(I24,Sprints!$A$5:$A$7,0)),"dd/mm"),"")} -> 19/10 – 01/11 | K24: Sơn | L24: To Do | M24: {=IFERROR(IF(AND(L24<>"Done",TODAY()>INDEX(Sprints!$C$5:$C$7,MATCH(I24,Sprints!$A$5:$A$7,0))),"Trễ",""),"")}
A25: F18-BE | B25: E2 | C25: Dữ liệu gốc | D25: Khu vực & retailer | E25: Khu vực & nhóm Sales | F25: Backend | G25: Cung cấp API quản lý khu vực bán hàng và nhóm Sales. Cho gán Sales vào nhóm/khu vực, lưu quan hệ quản lý của Sales Manager và kiểm tra dữ liệu trùng. Các quan hệ này được dùng để giới hạn danh sách retailer và đơn hàng. | H25: High | I25: S1 | J25: {=IFERROR(TEXT(INDEX(Sprints!$B$5:$B$7,MATCH(I25,Sprints!$A$5:$A$7,0)),"dd/mm")&" – "&TEXT(INDEX(Sprints!$C$5:$C$7,MATCH(I25,Sprints!$A$5:$A$7,0)),"dd/mm"),"")} -> 19/10 – 01/11 | K25: Hải | L25: To Do | M25: {=IFERROR(IF(AND(L25<>"Done",TODAY()>INDEX(Sprints!$C$5:$C$7,MATCH(I25,Sprints!$A$5:$A$7,0))),"Trễ",""),"")}
A26: F18-FE | B26: E2 | C26: Dữ liệu gốc | D26: Khu vực & retailer | E26: Khu vực & nhóm Sales | F26: Portal | G26: Làm màn Khu vực và nhóm Sales: danh sách, tạo/sửa và gán thành viên. Hiển thị Sales Manager, khu vực và Sales trong từng nhóm để người quản lý kiểm tra phân công. Lưu thay đổi qua API và báo lỗi cụ thể. | H26: High | I26: S1 | J26: {=IFERROR(TEXT(INDEX(Sprints!$B$5:$B$7,MATCH(I26,Sprints!$A$5:$A$7,0)),"dd/mm")&" – "&TEXT(INDEX(Sprints!$C$5:$C$7,MATCH(I26,Sprints!$A$5:$A$7,0)),"dd/mm"),"")} -> 19/10 – 01/11 | K26: Sơn | L26: To Do | M26: {=IFERROR(IF(AND(L26<>"Done",TODAY()>INDEX(Sprints!$C$5:$C$7,MATCH(I26,Sprints!$A$5:$A$7,0))),"Trễ",""),"")}
A27: F19-BE | B27: E2 | C27: Dữ liệu gốc | D27: Khu vực & retailer | E27: Hồ sơ retailer và thông tin tiềm năng | F27: Backend | G27: Quản lý hồ sơ retailer: tên, liên hệ, địa chỉ/GPS, khu vực, Sales phụ trách và thông tin tiềm năng như quy mô, doanh thu dự kiến, khả năng nhập. Liên kết hồ sơ với bộ MLOR theo Category/SKU của F22. Trả dữ liệu cho màn hai tab, kiểm tra trùng và phạm vi truy cập. | H27: High | I27: S1 | J27: {=IFERROR(TEXT(INDEX(Sprints!$B$5:$B$7,MATCH(I27,Sprints!$A$5:$A$7,0)),"dd/mm")&" – "&TEXT(INDEX(Sprints!$C$5:$C$7,MATCH(I27,Sprints!$A$5:$A$7,0)),"dd/mm"),"")} -> 19/10 – 01/11 | K27: Hải | L27: To Do | M27: {=IFERROR(IF(AND(L27<>"Done",TODAY()>INDEX(Sprints!$C$5:$C$7,MATCH(I27,Sprints!$A$5:$A$7,0))),"Trễ",""),"")} | P27: Hồ sơ retailer hai tab và MLOR Category/SKU: Backend Hải; Portal/Mobile Hoàng. F21-MB gồm phần nhập MLOR trên app, dùng API F22-BE.
A28: F19-FE | B28: E2 | C28: Dữ liệu gốc | D28: Khu vực & retailer | E28: Hồ sơ retailer và thông tin tiềm năng | F28: Portal | G28: Làm màn danh sách và chi tiết retailer trên Portal. Tab Thông tin chung gồm liên hệ, vị trí, quy mô và tiềm năng. Tab Yêu cầu hạn sử dụng tích hợp F22-FE để quản lý MLOR theo Category và SKU đặc thù. Có tìm kiếm/lọc và thao tác theo quyền. | H28: High | I28: S1 | J28: {=IFERROR(TEXT(INDEX(Sprints!$B$5:$B$7,MATCH(I28,Sprints!$A$5:$A$7,0)),"dd/mm")&" – "&TEXT(INDEX(Sprints!$C$5:$C$7,MATCH(I28,Sprints!$A$5:$A$7,0)),"dd/mm"),"")} -> 19/10 – 01/11 | K28: Hoàng | L28: To Do | M28: {=IFERROR(IF(AND(L28<>"Done",TODAY()>INDEX(Sprints!$C$5:$C$7,MATCH(I28,Sprints!$A$5:$A$7,0))),"Trễ",""),"")} | P28: Hồ sơ retailer hai tab và MLOR Category/SKU: Backend Hải; Portal/Mobile Hoàng. F21-MB gồm phần nhập MLOR trên app, dùng API F22-BE.
A29: F20-BE | B29: E2 | C29: Dữ liệu gốc | D29: Khu vực & retailer | E29: Hồ sơ retailer trong vùng trên app Sales | F29: Backend | G29: Trả danh sách và chi tiết retailer thuộc Sales đăng nhập, hỗ trợ tìm kiếm/lọc hoạt động. Dữ liệu gồm thông tin chung và MLOR theo Category/SKU từ F22 để tư vấn. Xác định phạm vi từ tài khoản, không tin mã Sales app truyền lên. | H29: High | I29: S1 | J29: {=IFERROR(TEXT(INDEX(Sprints!$B$5:$B$7,MATCH(I29,Sprints!$A$5:$A$7,0)),"dd/mm")&" – "&TEXT(INDEX(Sprints!$C$5:$C$7,MATCH(I29,Sprints!$A$5:$A$7,0)),"dd/mm"),"")} -> 19/10 – 01/11 | K29: Hải | L29: To Do | M29: {=IFERROR(IF(AND(L29<>"Done",TODAY()>INDEX(Sprints!$C$5:$C$7,MATCH(I29,Sprints!$A$5:$A$7,0))),"Trễ",""),"")} | P29: Hồ sơ retailer hai tab và MLOR Category/SKU: Backend Hải; Portal/Mobile Hoàng. F21-MB gồm phần nhập MLOR trên app, dùng API F22-BE.
A30: F20-MB | B30: E2 | C30: Dữ liệu gốc | D30: Khu vực & retailer | E30: Hồ sơ retailer trong vùng trên app Sales | F30: Mobile | G30: Làm danh sách retailer trong phạm vi Sales. Chi tiết có tab Thông tin chung và tab Yêu cầu hạn sử dụng, hiển thị MLOR theo Category cùng SKU ghi đè. Mở phần khai báo của F21-MB khi có quyền, mở tạo đơn khi retailer đã hoạt động. | H30: High | I30: S1 | J30: {=IFERROR(TEXT(INDEX(Sprints!$B$5:$B$7,MATCH(I30,Sprints!$A$5:$A$7,0)),"dd/mm")&" – "&TEXT(INDEX(Sprints!$C$5:$C$7,MATCH(I30,Sprints!$A$5:$A$7,0)),"dd/mm"),"")} -> 19/10 – 01/11 | K30: Hoàng | L30: To Do | M30: {=IFERROR(IF(AND(L30<>"Done",TODAY()>INDEX(Sprints!$C$5:$C$7,MATCH(I30,Sprints!$A$5:$A$7,0))),"Trễ",""),"")} | P30: Hồ sơ retailer hai tab và MLOR Category/SKU: Backend Hải; Portal/Mobile Hoàng. F21-MB gồm phần nhập MLOR trên app, dùng API F22-BE.
A31: F21-BE | B31: E2 | C31: Dữ liệu gốc | D31: Khu vực & retailer | E31: Sales khai báo retailer hai tab | F31: Backend | G31: Nhận yêu cầu khai báo retailer mới từ Sales gồm hai nhóm: hồ sơ chung và MLOR theo Category/SKU. Dùng bộ kiểm tra F22 để xác định dữ liệu hợp lệ. Lưu Chờ duyệt, cho duyệt/từ chối có lý do. Khi duyệt mới tạo retailer và cấu hình MLOR chính thức, chống tạo trùng. | H31: Medium | I31: S1 | J31: {=IFERROR(TEXT(INDEX(Sprints!$B$5:$B$7,MATCH(I31,Sprints!$A$5:$A$7,0)),"dd/mm")&" – "&TEXT(INDEX(Sprints!$C$5:$C$7,MATCH(I31,Sprints!$A$5:$A$7,0)),"dd/mm"),"")} -> 19/10 – 01/11 | K31: Hải | L31: To Do | M31: {=IFERROR(IF(AND(L31<>"Done",TODAY()>INDEX(Sprints!$C$5:$C$7,MATCH(I31,Sprints!$A$5:$A$7,0))),"Trễ",""),"")} | P31: Hồ sơ retailer hai tab và MLOR Category/SKU: Backend Hải; Portal/Mobile Hoàng. F21-MB gồm phần nhập MLOR trên app, dùng API F22-BE.
A32: F21-FE | B32: E2 | C32: Dữ liệu gốc | D32: Khu vực & retailer | E32: Sales khai báo retailer hai tab | F32: Portal | G32: Làm màn duyệt yêu cầu retailer trên Portal với hai tab: Thông tin chung và Yêu cầu hạn sử dụng. Hiển thị quy mô/tiềm năng, MLOR Category và SKU đặc thù, nguồn mức đang áp dụng. Cho duyệt/từ chối có lý do và hiện mã retailer sau duyệt. | H32: Medium | I32: S1 | J32: {=IFERROR(TEXT(INDEX(Sprints!$B$5:$B$7,MATCH(I32,Sprints!$A$5:$A$7,0)),"dd/mm")&" – "&TEXT(INDEX(Sprints!$C$5:$C$7,MATCH(I32,Sprints!$A$5:$A$7,0)),"dd/mm"),"")} -> 19/10 – 01/11 | K32: Hoàng | L32: To Do | M32: {=IFERROR(IF(AND(L32<>"Done",TODAY()>INDEX(Sprints!$C$5:$C$7,MATCH(I32,Sprints!$A$5:$A$7,0))),"Trễ",""),"")} | P32: Hồ sơ retailer hai tab và MLOR Category/SKU: Backend Hải; Portal/Mobile Hoàng. F21-MB gồm phần nhập MLOR trên app, dùng API F22-BE.
A33: F21-MB | B33: E2 | C33: Dữ liệu gốc | D33: Khu vực & retailer | E33: Sales khai báo retailer hai tab | F33: Mobile | G33: Làm phần Sales khai báo retailer qua hai tab. Thông tin chung nhập liên hệ, địa chỉ/GPS, quy mô và tiềm năng. Yêu cầu hạn sử dụng nhập MLOR theo Category hoặc SKU đặc thù. Hồ sơ mới gửi qua F21-BE để duyệt; retailer đã có dùng API F19/F22 theo quyền. Hiển thị mức SKU ghi đè Category và kết quả xử lý. | H33: Medium | I33: S1 | J33: {=IFERROR(TEXT(INDEX(Sprints!$B$5:$B$7,MATCH(I33,Sprints!$A$5:$A$7,0)),"dd/mm")&" – "&TEXT(INDEX(Sprints!$C$5:$C$7,MATCH(I33,Sprints!$A$5:$A$7,0)),"dd/mm"),"")} -> 19/10 – 01/11 | K33: Hoàng | L33: To Do | M33: {=IFERROR(IF(AND(L33<>"Done",TODAY()>INDEX(Sprints!$C$5:$C$7,MATCH(I33,Sprints!$A$5:$A$7,0))),"Trễ",""),"")} | P33: Hồ sơ retailer hai tab và MLOR Category/SKU: Backend Hải; Portal/Mobile Hoàng. F21-MB gồm phần nhập MLOR trên app, dùng API F22-BE.
A34: F22-BE | B34: E2 | C34: Dữ liệu gốc | D34: Khu vực & retailer | E34: MLOR retailer theo Category và SKU | F34: Backend | G34: Quản lý MLOR của retailer theo Category và SKU, dùng chung cho khai báo và hồ sơ đã duyệt. MLOR là % hạn sử dụng tối thiểu còn khi nhận hàng. Ưu tiên mức SKU riêng, rồi Category, rồi mặc định sản phẩm. Kiểm tỷ lệ hợp lệ, quyền cập nhật và trả cả mức lẫn nguồn áp dụng. Đơn được server nhận lưu bản MLOR đã áp dụng, cấu hình mới không âm thầm sửa đơn cũ. | H34: High | I34: S1 | J34: {=IFERROR(TEXT(INDEX(Sprints!$B$5:$B$7,MATCH(I34,Sprints!$A$5:$A$7,0)),"dd/mm")&" – "&TEXT(INDEX(Sprints!$C$5:$C$7,MATCH(I34,Sprints!$A$5:$A$7,0)),"dd/mm"),"")} -> 19/10 – 01/11 | K34: Hải | L34: To Do | M34: {=IFERROR(IF(AND(L34<>"Done",TODAY()>INDEX(Sprints!$C$5:$C$7,MATCH(I34,Sprints!$A$5:$A$7,0))),"Trễ",""),"")} | P34: Hồ sơ retailer hai tab và MLOR Category/SKU: Backend Hải; Portal/Mobile Hoàng. F21-MB gồm phần nhập MLOR trên app, dùng API F22-BE.
A35: F22-FE | B35: E2 | C35: Dữ liệu gốc | D35: Khu vực & retailer | E35: MLOR retailer theo Category và SKU | F35: Portal | G35: Làm tab Yêu cầu hạn sử dụng trong hồ sơ retailer. Cho cấu hình MLOR theo Category và bổ sung SKU đặc thù ghi đè. Hiển thị % áp dụng thực tế cùng nguồn SKU/Category/mặc định, cho xóa mức riêng để kế thừa. Giải thích % này kiểm lúc khách nhận, không phải % giảm giá. | H35: High | I35: S1 | J35: {=IFERROR(TEXT(INDEX(Sprints!$B$5:$B$7,MATCH(I35,Sprints!$A$5:$A$7,0)),"dd/mm")&" – "&TEXT(INDEX(Sprints!$C$5:$C$7,MATCH(I35,Sprints!$A$5:$A$7,0)),"dd/mm"),"")} -> 19/10 – 01/11 | K35: Hoàng | L35: To Do | M35: {=IFERROR(IF(AND(L35<>"Done",TODAY()>INDEX(Sprints!$C$5:$C$7,MATCH(I35,Sprints!$A$5:$A$7,0))),"Trễ",""),"")} | P35: Hồ sơ retailer hai tab và MLOR Category/SKU: Backend Hải; Portal/Mobile Hoàng. F21-MB gồm phần nhập MLOR trên app, dùng API F22-BE.
A36: F23-BE | B36: E2 | C36: Dữ liệu gốc | D36: Khu vực & retailer | E36: Kỳ hạn công nợ cho phép | F36: Backend | G36: Lưu kỳ hạn công nợ được phép cho từng retailer: không được mua công nợ hoặc 7, 14, 30 ngày. Khi tạo đơn công nợ phải kiểm tra retailer có được phép và lưu kỳ hạn áp dụng cho đơn. Thay đổi sau này không tự sửa kỳ hạn đơn cũ. | H36: High | I36: S1 | J36: {=IFERROR(TEXT(INDEX(Sprints!$B$5:$B$7,MATCH(I36,Sprints!$A$5:$A$7,0)),"dd/mm")&" – "&TEXT(INDEX(Sprints!$C$5:$C$7,MATCH(I36,Sprints!$A$5:$A$7,0)),"dd/mm"),"")} -> 19/10 – 01/11 | K36: Hải | L36: To Do | M36: {=IFERROR(IF(AND(L36<>"Done",TODAY()>INDEX(Sprints!$C$5:$C$7,MATCH(I36,Sprints!$A$5:$A$7,0))),"Trễ",""),"")}
A37: F23-FE | B37: E2 | C37: Dữ liệu gốc | D37: Khu vực & retailer | E37: Kỳ hạn công nợ cho phép | F37: Portal | G37: Thêm lựa chọn kỳ hạn công nợ trong form retailer trên Portal. Hiển thị Không cho phép hoặc số ngày được duyệt. Giải thích đây là số ngày tính từ khi đơn được nhận đủ, không phải số ngày kể từ lúc đặt. | H37: High | I37: S1 | J37: {=IFERROR(TEXT(INDEX(Sprints!$B$5:$B$7,MATCH(I37,Sprints!$A$5:$A$7,0)),"dd/mm")&" – "&TEXT(INDEX(Sprints!$C$5:$C$7,MATCH(I37,Sprints!$A$5:$A$7,0)),"dd/mm"),"")} -> 19/10 – 01/11 | K37: Sơn | L37: To Do | M37: {=IFERROR(IF(AND(L37<>"Done",TODAY()>INDEX(Sprints!$C$5:$C$7,MATCH(I37,Sprints!$A$5:$A$7,0))),"Trễ",""),"")}
A38: F24-BE | B38: E3 | C38: Bán hàng & đơn hàng | D38: Khuyến mãi & báo giá | E38: Khuyến mãi theo SKU / nhóm (KM) | F38: Backend | G38: Quản lý khuyến mãi thông thường theo SKU/nhóm: mức giảm, đối tượng, hiệu lực và tạm dừng. Tính giá cơ sở sau khuyến mãi hợp lệ khi lập/nhận đơn và lưu quy tắc áp dụng. Giá cơ sở này là đầu vào tính giảm HSD sau phân bổ ở F89, khuyến mãi không thay đổi MLOR. | H38: High | I38: S1 | J38: {=IFERROR(TEXT(INDEX(Sprints!$B$5:$B$7,MATCH(I38,Sprints!$A$5:$A$7,0)),"dd/mm")&" – "&TEXT(INDEX(Sprints!$C$5:$C$7,MATCH(I38,Sprints!$A$5:$A$7,0)),"dd/mm"),"")} -> 19/10 – 01/11 | K38: Nhân | L38: To Do | M38: {=IFERROR(IF(AND(L38<>"Done",TODAY()>INDEX(Sprints!$C$5:$C$7,MATCH(I38,Sprints!$A$5:$A$7,0))),"Trễ",""),"")}
A39: F24-FE | B39: E3 | C39: Bán hàng & đơn hàng | D39: Khuyến mãi & báo giá | E39: Khuyến mãi theo SKU / nhóm (KM) | F39: Portal | G39: Làm màn khuyến mãi thông thường theo SKU/nhóm, gồm danh sách, mức giảm, đối tượng, hiệu lực và tạm dừng. Ghi rõ đây là phần tính giá cơ sở khi đặt hàng. Bảng giảm thêm theo % HSD được quản lý riêng ở F46, không cấu hình MLOR trong khuyến mãi. | H39: High | I39: S1 | J39: {=IFERROR(TEXT(INDEX(Sprints!$B$5:$B$7,MATCH(I39,Sprints!$A$5:$A$7,0)),"dd/mm")&" – "&TEXT(INDEX(Sprints!$C$5:$C$7,MATCH(I39,Sprints!$A$5:$A$7,0)),"dd/mm"),"")} -> 19/10 – 01/11 | K39: Nhân | L39: To Do | M39: {=IFERROR(IF(AND(L39<>"Done",TODAY()>INDEX(Sprints!$C$5:$C$7,MATCH(I39,Sprints!$A$5:$A$7,0))),"Trễ",""),"")}
A40: F25-BE | B40: E3 | C40: Bán hàng & đơn hàng | D40: Khuyến mãi & báo giá | E40: Giá dự kiến trước phân bổ | F40: Backend | G40: Báo giá khi Sales tạo hoặc đồng bộ đơn: trả giá niêm yết, khuyến mãi thông thường hợp lệ, giá cơ sở sau khuyến mãi và tổng dự kiến. Chưa chọn batch nên chưa tính giảm HSD. Lưu phiên bản/điều kiện giá cơ sở khi server nhận đơn. Không giữ tồn hoặc cam kết mức giảm HSD trước đợt. | H40: High | I40: S1 | J40: {=IFERROR(TEXT(INDEX(Sprints!$B$5:$B$7,MATCH(I40,Sprints!$A$5:$A$7,0)),"dd/mm")&" – "&TEXT(INDEX(Sprints!$C$5:$C$7,MATCH(I40,Sprints!$A$5:$A$7,0)),"dd/mm"),"")} -> 19/10 – 01/11 | K40: Hải | L40: To Do | M40: {=IFERROR(IF(AND(L40<>"Done",TODAY()>INDEX(Sprints!$C$5:$C$7,MATCH(I40,Sprints!$A$5:$A$7,0))),"Trễ",""),"")} | P40: Chưa có batch: chưa tính giảm HSD. Giá cơ sở sau KM thường được server kiểm tra/lưu khi nhận đơn.
A41: F25-MB | B41: E3 | C41: Bán hàng & đơn hàng | D41: Khuyến mãi & báo giá | E41: Giá dự kiến trước phân bổ | F41: Mobile | G41: Hiện giá niêm yết, khuyến mãi thông thường, giá cơ sở và tổng dự kiến khi Sales soạn đơn. Ghi rõ giảm theo HSD chỉ biết sau phân bổ batch, chưa giữ hàng và chưa thu tiền trả trước. Offline hiển thị thời điểm dữ liệu giá, chờ server kiểm tra khi đồng bộ. | H41: High | I41: S1 | J41: {=IFERROR(TEXT(INDEX(Sprints!$B$5:$B$7,MATCH(I41,Sprints!$A$5:$A$7,0)),"dd/mm")&" – "&TEXT(INDEX(Sprints!$C$5:$C$7,MATCH(I41,Sprints!$A$5:$A$7,0)),"dd/mm"),"")} -> 19/10 – 01/11 | K41: Hoàng | L41: To Do | M41: {=IFERROR(IF(AND(L41<>"Done",TODAY()>INDEX(Sprints!$C$5:$C$7,MATCH(I41,Sprints!$A$5:$A$7,0))),"Trễ",""),"")} | P41: Chưa có batch: chưa tính giảm HSD. Giá cơ sở sau KM thường được server kiểm tra/lưu khi nhận đơn.
...

Sheet Team
A1: Thành viên
A2: Danh sách này là nguồn cho dropdown PIC trên Task_Tracking. Sửa tên / thêm người ở cột A.
A4: PIC (tên ngắn) | B4: Họ tên | C4: Vai trò | D4: Số task | E4: Done | F4: % Done
A5: Nhân | B5: Nguyen Thien Nhan | C5: Leader; full stack thuật toán, loyalty và khiếu nại | D5: =COUNTIF(Task_Tracking!$K$5:$K$400,A5) -> 55 | E5: =COUNTIFS(Task_Tracking!$K$5:$K$400,A5,Task_Tracking!$L$5:$L$400,"Done") -> 0 | F5: =IFERROR(E5/D5,0) -> 0
A6: Khiết | B6: Tran Ngoc Khiet | C6: Backend | D6: =COUNTIF(Task_Tracking!$K$5:$K$400,A6) -> 24 | E6: =COUNTIFS(Task_Tracking!$K$5:$K$400,A6,Task_Tracking!$L$5:$L$400,"Done") -> 0 | F6: =IFERROR(E6/D6,0) -> 0
A7: Hải | B7: Doan Duc Hai | C7: Backend; giữ phân công Portal đã có | D7: =COUNTIF(Task_Tracking!$K$5:$K$400,A7) -> 27 | E7: =COUNTIFS(Task_Tracking!$K$5:$K$400,A7,Task_Tracking!$L$5:$L$400,"Done") -> 0 | F7: =IFERROR(E7/D7,0) -> 0
A8: Sơn | B8: Vo Minh Son | C8: Portal / Mobile | D8: =COUNTIF(Task_Tracking!$K$5:$K$400,A8) -> 28 | E8: =COUNTIFS(Task_Tracking!$K$5:$K$400,A8,Task_Tracking!$L$5:$L$400,"Done") -> 0 | F8: =IFERROR(E8/D8,0) -> 0
A9: Hoàng | B9: Truong Le Huy Hoang | C9: Portal / Mobile | D9: =COUNTIF(Task_Tracking!$K$5:$K$400,A9) -> 29 | E9: =COUNTIFS(Task_Tracking!$K$5:$K$400,A9,Task_Tracking!$L$5:$L$400,"Done") -> 0 | F9: =IFERROR(E9/D9,0) -> 0

Sheet Dashboard
A1: FSCM – Dashboard tiến độ
A2: Tự tính từ Task_Tracking và Sprints. Ô vàng ở cột PIC trên Task_Tracking = task chưa có người nhận.
A4: Tổng quan
A5: Tổng task | B5: Done | C5: % Done | D5: Chưa có PIC | E5: Trễ hạn | F5: Blocked | G5: Sprint hiện tại
A6: =COUNTA(Task_Tracking!$G$5:$G$400) -> 163 | B6: =COUNTIF(Task_Tracking!$L$5:$L$400,"Done") -> 0 | C6: =IFERROR(B6/A6,0) -> 0 | D6: =COUNTIFS(Task_Tracking!$G$5:$G$400,"<>",Task_Tracking!$K$5:$K$400,"") -> 0 | E6: =COUNTIF(Task_Tracking!$M$5:$M$400,"Trễ") -> 0 | F6: =COUNTIF(Task_Tracking!$L$5:$L$400,"Blocked") -> 0 | G6: {=IFERROR(INDEX(Sprints!$A$5:$A$7,MATCH("Đang chạy",Sprints!$H$5:$H$7,0)),IF(TODAY()<Sprints!$B$5,"Chưa bắt đầu","Đã hết kế hoạch"))} -> S1
A8: Theo sprint
A9: Sprint | B9: Thời gian | C9: Backend | D9: Portal | E9: Mobile | F9: Tổng task | G9: Done | H9: Còn lại | I9: Lũy kế kế hoạch | J9: Lũy kế Done | K9: % Done
A10: S1 | B10: =TEXT(Sprints!B5,"dd/mm")&" – "&TEXT(Sprints!C5,"dd/mm") -> 19/10 – 01/11 | C10: =COUNTIFS(Task_Tracking!$I$5:$I$400,$A10,Task_Tracking!$F$5:$F$400,"Backend") -> 31 | D10: =COUNTIFS(Task_Tracking!$I$5:$I$400,$A10,Task_Tracking!$F$5:$F$400,"Portal") -> 21 | E10: =COUNTIFS(Task_Tracking!$I$5:$I$400,$A10,Task_Tracking!$F$5:$F$400,"Mobile") -> 12 | F10: =SUM(C10:E10) -> 64 | G10: =COUNTIFS(Task_Tracking!$I$5:$I$400,$A10,Task_Tracking!$L$5:$L$400,"Done") -> 0 | H10: =F10-G10 -> 64 | I10: =SUM($F$10:F10) -> 64 | J10: =SUM($G$10:G10) -> 0 | K10: =IFERROR(G10/F10,0) -> 0
A11: S2 | B11: =TEXT(Sprints!B6,"dd/mm")&" – "&TEXT(Sprints!C6,"dd/mm") -> 02/11 – 15/11 | C11: =COUNTIFS(Task_Tracking!$I$5:$I$400,$A11,Task_Tracking!$F$5:$F$400,"Backend") -> 33 | D11: =COUNTIFS(Task_Tracking!$I$5:$I$400,$A11,Task_Tracking!$F$5:$F$400,"Portal") -> 18 | E11: =COUNTIFS(Task_Tracking!$I$5:$I$400,$A11,Task_Tracking!$F$5:$F$400,"Mobile") -> 14 | F11: =SUM(C11:E11) -> 65 | G11: =COUNTIFS(Task_Tracking!$I$5:$I$400,$A11,Task_Tracking!$L$5:$L$400,"Done") -> 0 | H11: =F11-G11 -> 65 | I11: =SUM($F$10:F11) -> 129 | J11: =SUM($G$10:G11) -> 0 | K11: =IFERROR(G11/F11,0) -> 0
A12: S3 | B12: =TEXT(Sprints!B7,"dd/mm")&" – "&TEXT(Sprints!C7,"dd/mm") -> 16/11 – 22/11 | C12: =COUNTIFS(Task_Tracking!$I$5:$I$400,$A12,Task_Tracking!$F$5:$F$400,"Backend") -> 16 | D12: =COUNTIFS(Task_Tracking!$I$5:$I$400,$A12,Task_Tracking!$F$5:$F$400,"Portal") -> 10 | E12: =COUNTIFS(Task_Tracking!$I$5:$I$400,$A12,Task_Tracking!$F$5:$F$400,"Mobile") -> 8 | F12: =SUM(C12:E12) -> 34 | G12: =COUNTIFS(Task_Tracking!$I$5:$I$400,$A12,Task_Tracking!$L$5:$L$400,"Done") -> 0 | H12: =F12-G12 -> 34 | I12: =SUM($F$10:F12) -> 163 | J12: =SUM($G$10:G12) -> 0 | K12: =IFERROR(G12/F12,0) -> 0
A13: Tổng | C13: =SUM(C10:C12) -> 80 | D13: =SUM(D10:D12) -> 49 | E13: =SUM(E10:E12) -> 34 | F13: =SUM(F10:F12) -> 163 | G13: =SUM(G10:G12) -> 0 | H13: =SUM(H10:H12) -> 163 | K13: =IFERROR(G13/F13,0) -> 0
A15: Khối lượng theo PIC × sprint (số task) – dùng để cân việc khi chia PIC
A16: PIC | B16: S1 | C16: S2 | D16: S3 | E16: Tổng | F16: Done | G16: % Done
A17: =Team!A5 -> Nhân | B17: =COUNTIFS(Task_Tracking!$I$5:$I$400,"S1",Task_Tracking!$K$5:$K$400,$A17) -> 8 | C17: =COUNTIFS(Task_Tracking!$I$5:$I$400,"S2",Task_Tracking!$K$5:$K$400,$A17) -> 37 | D17: =COUNTIFS(Task_Tracking!$I$5:$I$400,"S3",Task_Tracking!$K$5:$K$400,$A17) -> 10 | E17: =SUM(B17:D17) -> 55 | F17: =COUNTIFS(Task_Tracking!$K$5:$K$400,$A17,Task_Tracking!$L$5:$L$400,"Done") -> 0 | G17: =IFERROR(F17/E17,0) -> 0
A18: =Team!A6 -> Khiết | B18: =COUNTIFS(Task_Tracking!$I$5:$I$400,"S1",Task_Tracking!$K$5:$K$400,$A18) -> 10 | C18: =COUNTIFS(Task_Tracking!$I$5:$I$400,"S2",Task_Tracking!$K$5:$K$400,$A18) -> 7 | D18: =COUNTIFS(Task_Tracking!$I$5:$I$400,"S3",Task_Tracking!$K$5:$K$400,$A18) -> 7 | E18: =SUM(B18:D18) -> 24 | F18: =COUNTIFS(Task_Tracking!$K$5:$K$400,$A18,Task_Tracking!$L$5:$L$400,"Done") -> 0 | G18: =IFERROR(F18/E18,0) -> 0
A19: =Team!A7 -> Hải | B19: =COUNTIFS(Task_Tracking!$I$5:$I$400,"S1",Task_Tracking!$K$5:$K$400,$A19) -> 17 | C19: =COUNTIFS(Task_Tracking!$I$5:$I$400,"S2",Task_Tracking!$K$5:$K$400,$A19) -> 6 | D19: =COUNTIFS(Task_Tracking!$I$5:$I$400,"S3",Task_Tracking!$K$5:$K$400,$A19) -> 4 | E19: =SUM(B19:D19) -> 27 | F19: =COUNTIFS(Task_Tracking!$K$5:$K$400,$A19,Task_Tracking!$L$5:$L$400,"Done") -> 0 | G19: =IFERROR(F19/E19,0) -> 0
A20: =Team!A8 -> Sơn | B20: =COUNTIFS(Task_Tracking!$I$5:$I$400,"S1",Task_Tracking!$K$5:$K$400,$A20) -> 13 | C20: =COUNTIFS(Task_Tracking!$I$5:$I$400,"S2",Task_Tracking!$K$5:$K$400,$A20) -> 7 | D20: =COUNTIFS(Task_Tracking!$I$5:$I$400,"S3",Task_Tracking!$K$5:$K$400,$A20) -> 8 | E20: =SUM(B20:D20) -> 28 | F20: =COUNTIFS(Task_Tracking!$K$5:$K$400,$A20,Task_Tracking!$L$5:$L$400,"Done") -> 0 | G20: =IFERROR(F20/E20,0) -> 0
A21: =Team!A9 -> Hoàng | B21: =COUNTIFS(Task_Tracking!$I$5:$I$400,"S1",Task_Tracking!$K$5:$K$400,$A21) -> 16 | C21: =COUNTIFS(Task_Tracking!$I$5:$I$400,"S2",Task_Tracking!$K$5:$K$400,$A21) -> 8 | D21: =COUNTIFS(Task_Tracking!$I$5:$I$400,"S3",Task_Tracking!$K$5:$K$400,$A21) -> 5 | E21: =SUM(B21:D21) -> 29 | F21: =COUNTIFS(Task_Tracking!$K$5:$K$400,$A21,Task_Tracking!$L$5:$L$400,"Done") -> 0 | G21: =IFERROR(F21/E21,0) -> 0
A22: (Chưa gán) | B22: =COUNTIFS(Task_Tracking!$I$5:$I$400,"S1",Task_Tracking!$G$5:$G$400,"<>",Task_Tracking!$K$5:$K$400,"") -> 0 | C22: =COUNTIFS(Task_Tracking!$I$5:$I$400,"S2",Task_Tracking!$G$5:$G$400,"<>",Task_Tracking!$K$5:$K$400,"") -> 0 | D22: =COUNTIFS(Task_Tracking!$I$5:$I$400,"S3",Task_Tracking!$G$5:$G$400,"<>",Task_Tracking!$K$5:$K$400,"") -> 0 | E22: =SUM(B22:D22) -> 0 | F22: =COUNTIFS(Task_Tracking!$G$5:$G$400,"<>",Task_Tracking!$K$5:$K$400,"",Task_Tracking!$L$5:$L$400,"Done") -> 0 | G22: =IFERROR(F22/E22,0) -> 0
A24: Theo epic
A25: Epic | B25: Tên epic | C25: Backend | D25: Portal | E25: Mobile | F25: Tổng task | G25: Done | H25: Còn lại | I25: Blocked | J25: Trễ | K25: % Done
A26: E1 | B26: Nền tảng & xác thực | C26: =COUNTIFS(Task_Tracking!$B$5:$B$400,$A26,Task_Tracking!$F$5:$F$400,"Backend") -> 3 | D26: =COUNTIFS(Task_Tracking!$B$5:$B$400,$A26,Task_Tracking!$F$5:$F$400,"Portal") -> 2 | E26: =COUNTIFS(Task_Tracking!$B$5:$B$400,$A26,Task_Tracking!$F$5:$F$400,"Mobile") -> 2 | F26: =SUM(C26:E26) -> 7 | G26: =COUNTIFS(Task_Tracking!$B$5:$B$400,$A26,Task_Tracking!$L$5:$L$400,"Done") -> 0 | H26: =F26-G26 -> 7 | I26: =COUNTIFS(Task_Tracking!$B$5:$B$400,$A26,Task_Tracking!$L$5:$L$400,"Blocked") -> 0 | J26: =COUNTIFS(Task_Tracking!$B$5:$B$400,$A26,Task_Tracking!$M$5:$M$400,"Trễ") -> 0 | K26: =IFERROR(G26/F26,0) -> 0
A27: E2 | B27: Dữ liệu gốc | C27: =COUNTIFS(Task_Tracking!$B$5:$B$400,$A27,Task_Tracking!$F$5:$F$400,"Backend") -> 12 | D27: =COUNTIFS(Task_Tracking!$B$5:$B$400,$A27,Task_Tracking!$F$5:$F$400,"Portal") -> 11 | E27: =COUNTIFS(Task_Tracking!$B$5:$B$400,$A27,Task_Tracking!$F$5:$F$400,"Mobile") -> 3 | F27: =SUM(C27:E27) -> 26 | G27: =COUNTIFS(Task_Tracking!$B$5:$B$400,$A27,Task_Tracking!$L$5:$L$400,"Done") -> 0 | H27: =F27-G27 -> 26 | I27: =COUNTIFS(Task_Tracking!$B$5:$B$400,$A27,Task_Tracking!$L$5:$L$400,"Blocked") -> 0 | J27: =COUNTIFS(Task_Tracking!$B$5:$B$400,$A27,Task_Tracking!$M$5:$M$400,"Trễ") -> 0 | K27: =IFERROR(G27/F27,0) -> 0
A28: E3 | B28: Bán hàng & đơn hàng | C28: =COUNTIFS(Task_Tracking!$B$5:$B$400,$A28,Task_Tracking!$F$5:$F$400,"Backend") -> 22 | D28: =COUNTIFS(Task_Tracking!$B$5:$B$400,$A28,Task_Tracking!$F$5:$F$400,"Portal") -> 10 | E28: =COUNTIFS(Task_Tracking!$B$5:$B$400,$A28,Task_Tracking!$F$5:$F$400,"Mobile") -> 11 | F28: =SUM(C28:E28) -> 43 | G28: =COUNTIFS(Task_Tracking!$B$5:$B$400,$A28,Task_Tracking!$L$5:$L$400,"Done") -> 0 | H28: =F28-G28 -> 43 | I28: =COUNTIFS(Task_Tracking!$B$5:$B$400,$A28,Task_Tracking!$L$5:$L$400,"Blocked") -> 0 | J28: =COUNTIFS(Task_Tracking!$B$5:$B$400,$A28,Task_Tracking!$M$5:$M$400,"Trễ") -> 0 | K28: =IFERROR(G28/F28,0) -> 0
A29: E4 | B29: Kho & tồn kho | C29: =COUNTIFS(Task_Tracking!$B$5:$B$400,$A29,Task_Tracking!$F$5:$F$400,"Backend") -> 11 | D29: =COUNTIFS(Task_Tracking!$B$5:$B$400,$A29,Task_Tracking!$F$5:$F$400,"Portal") -> 7 | E29: =COUNTIFS(Task_Tracking!$B$5:$B$400,$A29,Task_Tracking!$F$5:$F$400,"Mobile") -> 5 | F29: =SUM(C29:E29) -> 23 | G29: =COUNTIFS(Task_Tracking!$B$5:$B$400,$A29,Task_Tracking!$L$5:$L$400,"Done") -> 0 | H29: =F29-G29 -> 23 | I29: =COUNTIFS(Task_Tracking!$B$5:$B$400,$A29,Task_Tracking!$L$5:$L$400,"Blocked") -> 0 | J29: =COUNTIFS(Task_Tracking!$B$5:$B$400,$A29,Task_Tracking!$M$5:$M$400,"Trễ") -> 0 | K29: =IFERROR(G29/F29,0) -> 0
A30: E5 | B30: Vận chuyển & giao nhận | C30: =COUNTIFS(Task_Tracking!$B$5:$B$400,$A30,Task_Tracking!$F$5:$F$400,"Backend") -> 10 | D30: =COUNTIFS(Task_Tracking!$B$5:$B$400,$A30,Task_Tracking!$F$5:$F$400,"Portal") -> 5 | E30: =COUNTIFS(Task_Tracking!$B$5:$B$400,$A30,Task_Tracking!$F$5:$F$400,"Mobile") -> 3 | F30: =SUM(C30:E30) -> 18 | G30: =COUNTIFS(Task_Tracking!$B$5:$B$400,$A30,Task_Tracking!$L$5:$L$400,"Done") -> 0 | H30: =F30-G30 -> 18 | I30: =COUNTIFS(Task_Tracking!$B$5:$B$400,$A30,Task_Tracking!$L$5:$L$400,"Blocked") -> 0 | J30: =COUNTIFS(Task_Tracking!$B$5:$B$400,$A30,Task_Tracking!$M$5:$M$400,"Trễ") -> 0 | K30: =IFERROR(G30/F30,0) -> 0
A31: E6 | B31: Thanh toán & công nợ | C31: =COUNTIFS(Task_Tracking!$B$5:$B$400,$A31,Task_Tracking!$F$5:$F$400,"Backend") -> 6 | D31: =COUNTIFS(Task_Tracking!$B$5:$B$400,$A31,Task_Tracking!$F$5:$F$400,"Portal") -> 3 | E31: =COUNTIFS(Task_Tracking!$B$5:$B$400,$A31,Task_Tracking!$F$5:$F$400,"Mobile") -> 3 | F31: =SUM(C31:E31) -> 12 | G31: =COUNTIFS(Task_Tracking!$B$5:$B$400,$A31,Task_Tracking!$L$5:$L$400,"Done") -> 0 | H31: =F31-G31 -> 12 | I31: =COUNTIFS(Task_Tracking!$B$5:$B$400,$A31,Task_Tracking!$L$5:$L$400,"Blocked") -> 0 | J31: =COUNTIFS(Task_Tracking!$B$5:$B$400,$A31,Task_Tracking!$M$5:$M$400,"Trễ") -> 0 | K31: =IFERROR(G31/F31,0) -> 0
A32: E7 | B32: Loyalty | C32: =COUNTIFS(Task_Tracking!$B$5:$B$400,$A32,Task_Tracking!$F$5:$F$400,"Backend") -> 6 | D32: =COUNTIFS(Task_Tracking!$B$5:$B$400,$A32,Task_Tracking!$F$5:$F$400,"Portal") -> 4 | E32: =COUNTIFS(Task_Tracking!$B$5:$B$400,$A32,Task_Tracking!$F$5:$F$400,"Mobile") -> 2 | F32: =SUM(C32:E32) -> 12 | G32: =COUNTIFS(Task_Tracking!$B$5:$B$400,$A32,Task_Tracking!$L$5:$L$400,"Done") -> 0 | H32: =F32-G32 -> 12 | I32: =COUNTIFS(Task_Tracking!$B$5:$B$400,$A32,Task_Tracking!$L$5:$L$400,"Blocked") -> 0 | J32: =COUNTIFS(Task_Tracking!$B$5:$B$400,$A32,Task_Tracking!$M$5:$M$400,"Trễ") -> 0 | K32: =IFERROR(G32/F32,0) -> 0
A33: E8 | B33: Báo cáo & thông báo | C33: =COUNTIFS(Task_Tracking!$B$5:$B$400,$A33,Task_Tracking!$F$5:$F$400,"Backend") -> 6 | D33: =COUNTIFS(Task_Tracking!$B$5:$B$400,$A33,Task_Tracking!$F$5:$F$400,"Portal") -> 5 | E33: =COUNTIFS(Task_Tracking!$B$5:$B$400,$A33,Task_Tracking!$F$5:$F$400,"Mobile") -> 3 | F33: =SUM(C33:E33) -> 14 | G33: =COUNTIFS(Task_Tracking!$B$5:$B$400,$A33,Task_Tracking!$L$5:$L$400,"Done") -> 0 | H33: =F33-G33 -> 14 | I33: =COUNTIFS(Task_Tracking!$B$5:$B$400,$A33,Task_Tracking!$L$5:$L$400,"Blocked") -> 0 | J33: =COUNTIFS(Task_Tracking!$B$5:$B$400,$A33,Task_Tracking!$M$5:$M$400,"Trễ") -> 0 | K33: =IFERROR(G33/F33,0) -> 0
A34: E9 | B34: Kiểm thử & bàn giao | C34: =COUNTIFS(Task_Tracking!$B$5:$B$400,$A34,Task_Tracking!$F$5:$F$400,"Backend") -> 4 | D34: =COUNTIFS(Task_Tracking!$B$5:$B$400,$A34,Task_Tracking!$F$5:$F$400,"Portal") -> 2 | E34: =COUNTIFS(Task_Tracking!$B$5:$B$400,$A34,Task_Tracking!$F$5:$F$400,"Mobile") -> 2 | F34: =SUM(C34:E34) -> 8 | G34: =COUNTIFS(Task_Tracking!$B$5:$B$400,$A34,Task_Tracking!$L$5:$L$400,"Done") -> 0 | H34: =F34-G34 -> 8 | I34: =COUNTIFS(Task_Tracking!$B$5:$B$400,$A34,Task_Tracking!$L$5:$L$400,"Blocked") -> 0 | J34: =COUNTIFS(Task_Tracking!$B$5:$B$400,$A34,Task_Tracking!$M$5:$M$400,"Trễ") -> 0 | K34: =IFERROR(G34/F34,0) -> 0
A36: Theo nền tảng × status
A37: Nền tảng | B37: To Do | C37: In Progress | D37: In Review | E37: Done | F37: Blocked | G37: Tổng | H37: % Done
A38: Backend | B38: =COUNTIFS(Task_Tracking!$F$5:$F$400,$A38,Task_Tracking!$L$5:$L$400,"To Do") -> 80 | C38: =COUNTIFS(Task_Tracking!$F$5:$F$400,$A38,Task_Tracking!$L$5:$L$400,"In Progress") -> 0 | D38: =COUNTIFS(Task_Tracking!$F$5:$F$400,$A38,Task_Tracking!$L$5:$L$400,"In Review") -> 0 | E38: =COUNTIFS(Task_Tracking!$F$5:$F$400,$A38,Task_Tracking!$L$5:$L$400,"Done") -> 0 | F38: =COUNTIFS(Task_Tracking!$F$5:$F$400,$A38,Task_Tracking!$L$5:$L$400,"Blocked") -> 0 | G38: =SUM(B38:F38) -> 80 | H38: =IFERROR(E38/G38,0) -> 0
A39: Portal | B39: =COUNTIFS(Task_Tracking!$F$5:$F$400,$A39,Task_Tracking!$L$5:$L$400,"To Do") -> 49 | C39: =COUNTIFS(Task_Tracking!$F$5:$F$400,$A39,Task_Tracking!$L$5:$L$400,"In Progress") -> 0 | D39: =COUNTIFS(Task_Tracking!$F$5:$F$400,$A39,Task_Tracking!$L$5:$L$400,"In Review") -> 0 | E39: =COUNTIFS(Task_Tracking!$F$5:$F$400,$A39,Task_Tracking!$L$5:$L$400,"Done") -> 0 | F39: =COUNTIFS(Task_Tracking!$F$5:$F$400,$A39,Task_Tracking!$L$5:$L$400,"Blocked") -> 0 | G39: =SUM(B39:F39) -> 49 | H39: =IFERROR(E39/G39,0) -> 0
A40: Mobile | B40: =COUNTIFS(Task_Tracking!$F$5:$F$400,$A40,Task_Tracking!$L$5:$L$400,"To Do") -> 34 | C40: =COUNTIFS(Task_Tracking!$F$5:$F$400,$A40,Task_Tracking!$L$5:$L$400,"In Progress") -> 0 | D40: =COUNTIFS(Task_Tracking!$F$5:$F$400,$A40,Task_Tracking!$L$5:$L$400,"In Review") -> 0 | E40: =COUNTIFS(Task_Tracking!$F$5:$F$400,$A40,Task_Tracking!$L$5:$L$400,"Done") -> 0 | F40: =COUNTIFS(Task_Tracking!$F$5:$F$400,$A40,Task_Tracking!$L$5:$L$400,"Blocked") -> 0 | G40: =SUM(B40:F40) -> 34 | H40: =IFERROR(E40/G40,0) -> 0

Sheet Sprints
A1: Kế hoạch 3 sprint trong 5 tuần (19/10 – 22/11/2026)
A2: Chỉ sửa ngày bắt đầu Sprint 1 (ô B5, chữ xanh); các sprint sau tự lùi theo. Hôm nay: | F2: =TODAY() -> 46317
A4: Sprint | B4: Bắt đầu | C4: Kết thúc | D4: Mục tiêu sprint | E4: Số task | F4: Done | G4: % Done | H4: Trạng thái
A5: S1 | B5: 46314 | C5: =B5+13 -> 46327 | D5: Nền tảng và dữ liệu gốc; hồ sơ retailer hai tab, MLOR Category/SKU; bảng vận chuyển/ETA; KM thường và giá dự kiến; đặt/duyệt đơn trước cutoff, nhập kho/tem/batch, thanh toán. | E5: =COUNTIF(Task_Tracking!$I$5:$I$400,A5) -> 64 | F5: =COUNTIFS(Task_Tracking!$I$5:$I$400,A5,Task_Tracking!$L$5:$L$400,"Done") -> 0 | G5: =IFERROR(F5/E5,0) -> 0 | H5: =IF(TODAY()>C5,"Đã qua",IF(TODAY()>=B5,"Đang chạy","Sắp tới")) -> Đang chạy
A6: S2 | B6: =B5+14 -> 46328 | C6: =B6+13 -> 46341 | D6: Gom đợt 12h, chọn/đổi batch đạt MLOR rồi tính giảm HSD; Admin duyệt hàng/giá, reserve; offline; soạn và tách đơn giữ giá theo batch; giao nhận, công nợ, loyalty, KPI. | E6: =COUNTIF(Task_Tracking!$I$5:$I$400,A6) -> 65 | F6: =COUNTIFS(Task_Tracking!$I$5:$I$400,A6,Task_Tracking!$L$5:$L$400,"Done") -> 0 | G6: =IFERROR(F6/E6,0) -> 0 | H6: =IF(TODAY()>C6,"Đã qua",IF(TODAY()>=B6,"Đang chạy","Sắp tới")) -> Sắp tới
A7: S3 | B7: =B6+14 -> 46342 | C7: =B7+6 -> 46348 | D7: Tuần cuối: chức năng Medium còn lại (thông báo, khiếu nại, công nợ trên app, dashboard, hủy hàng, báo cáo đợt) + bộ test đợt, test tích hợp, sửa lỗi, dữ liệu demo, deploy | E7: =COUNTIF(Task_Tracking!$I$5:$I$400,A7) -> 34 | F7: =COUNTIFS(Task_Tracking!$I$5:$I$400,A7,Task_Tracking!$L$5:$L$400,"Done") -> 0 | G7: =IFERROR(F7/E7,0) -> 0 | H7: =IF(TODAY()>C7,"Đã qua",IF(TODAY()>=B7,"Đang chạy","Sắp tới")) -> Sắp tới
A9: S1 và S2 mỗi sprint 2 tuần, S3 là tuần cuối (16/11 – 22/11). S3 không nhận chức năng High mới; nếu trễ thì cắt bớt nhóm Medium trước.

Sheet Lists
A1: Status | B1: Priority | C1: Nền tảng | D1: Sprint
A2: To Do | B2: High | C2: Backend | D2: S1
A3: In Progress | B3: Medium | C3: Portal | D3: S2
A4: In Review | B4: Low | C4: Mobile | D4: S3
A5: Done
A6: Blocked

Sheet Huong_dan
A1: Hướng dẫn
A2: Cấu trúc: Epic → Module → Chức năng → mỗi nền tảng (Backend / Portal / Mobile) là một dòng task riêng trên Task_Tracking. Task ID = mã chức năng + nền tảng (F27-BE, F27-MB…); các dòng cùng mã F27 là cùng một chức năng.
A3: Phân công cụ thể: giảm HSD và giá theo batch giao Nhân Backend/Portal, Sơn Mobile; hồ sơ retailer hai tab và MLOR Category/SKU giao Hải Backend, Hoàng Portal/Mobile. Các phần khác giữ phân công hiện có.
A4: Sprint: 3 sprint trong 5 tuần từ 19/10 đến 22/11/2026 – S1 19/10–01/11, S2 02/11–15/11 (2 tuần), S3 16/11–22/11 (1 tuần, test + Medium còn lại). Task chưa Done mà đã qua ngày kết thúc sprint sẽ hiện "Trễ".
A5: Luồng thống nhất 21/10/2026: MLOR theo SKU riêng, rồi Category, rồi mặc định sản phẩm; gom nhu cầu theo SKU nhưng giữ điều kiện từng dòng. Chọn batch đạt MLOR tại ETA trước, tính giảm theo % HSD sau, Admin duyệt hàng và giá rồi mới giữ tồn/thu trả trước. F98 lưu và hiển thị giá theo batch.
A6: Ô được sửa: PIC, Status, Priority, Sprint (có thể dời task sang sprint khác), Bắt đầu, Hoàn thành, Ghi chú. Không sửa cột xám (Thời gian sprint, Trễ hạn).
A7: Thêm task: điền tiếp dòng trống dưới bảng (Task ID mới, Epic, Module, Chức năng, Nền tảng, Công việc, Sprint); công thức có sẵn tới dòng 400.
A9: Status | B9: Ý nghĩa
A10: To Do | B10: Chưa bắt đầu
A11: In Progress | B11: Đang code
A12: In Review | B12: Xong code, chờ review / test
A13: Done | B13: Đã merge, test pass trên môi trường chung
A14: Blocked | B14: Bị chặn – ghi lý do ở Ghi chú
A16: Priority | B16: Ý nghĩa
A17: High | B17: Luồng chính: hồ sơ retailer hai tab, MLOR Category/SKU, gom đợt 12h, chọn batch rồi tính giảm HSD, Admin duyệt hàng/giá, xuất kho, thanh toán, loyalty và KPI.
A18: Medium | B18: Chức năng hỗ trợ trong scope; nếu trễ thì làm bản gọn, không bỏ
A19: Low | B19: Ngoài scope đã chốt, chỉ làm khi dư thời gian (hiện không có task nào)
A21: Nguyên tắc xếp sprint | B21: S1: dữ liệu gốc + phần đầu luồng đơn (tạo, duyệt) + nhập kho. S2: đợt phân bổ 12:00 đến xuất kho, giao nhận, công nợ, loyalty, KPI – toàn bộ High còn lại. S3: Medium còn lại + test, sửa lỗi, demo. Backend và Portal / Mobile của cùng chức năng nằm cùng sprint.
A22: Ví dụ cập nhật | B22: F87-BE "Đề xuất đợt & Admin duyệt đợt": chọn PIC, Status = In Progress. Khi xong: Status = Done, điền ngày Hoàn thành; Dashboard tự cộng vào S2, E3, Backend và PIC đó.
... A25: Quy tắc tính và lưu giá | B25: F25 lấy giá cơ sở sau KM thường. F89 chọn một bậc giảm HSD theo SKU (ưu tiên) hoặc Category, giảm % hay tiền cố định/đơn vị trên giá cơ sở, giá cuối không âm; không khớp thì giảm HSD = 0. F98 lưu mọi thành phần giá theo dòng phân bổ, không tính lại khi soạn, giao, thu tiền hoặc xem lịch sử.
