Workbook

Sheet Cover
B2: TEST REPORT DOCUMENT
A4: Project Name | B4: FSCM – Short Shelf-Life FMCG Supply Chain Management and Distribution Coordination | E4: Creator | F4: Tran Ngoc Khiet, Doan Duc Hai
A5: Project Code | B5: FA26SE083 | E5: Issue Date | F5: 28/10/2026
A6: Document Code | B6: FA26SE083_Test_Report_v1.3 | E6: Version | F6: 1.3
A9: Record of change
A10: Effective Date | B10: Version | C10: Change Item | D10: *A,D,M | E10: Change description | F10: Reference
A11: 27/10/2026 | B11: 1.0 | C11: Initial FSCM test design | D11: A | E11: Initial FSCM test case inventory and test execution plan. | F11: FSCM_Report5_Test_Report.xlsx
A12: 27/10/2026 | B12: 1.1 | C12: Example-format rebuild | D12: M | E12: Reformatted all 24 module sheets using example’s Round 1–3 structure. Added master list, scenario steps, preconditions, expected results and live summary formulas. No fabricated results. | F12: SRS v1.5; SDD v1.1; GitHub main
A13: 28/10/2026 | B13: 1.2 | C13: Updated FSCM v1.2 test design aligned with approved R5 requirements | D13: M | E13: Update prepaid/deferred, discount, 00:00 cutoff, manual offline Send, delivery, loyalty and NFR tests; preserve 271 cases and evidence status. | F13: Test Documentation v1.2; Unit Test v1.2; SRS v1.8; SDD v1.8
A14: 28/10/2026 | B14: 1.3 | C14: Five Main Flows F1–F5 and seven approved business decisions | D14: M | E14: Align cutoff 00:00 ICT; percentage-only shelf-life discount; 1 point per 10,000 VND; full actual receipt before Completed; positive net price; Admin/Operator product authority; staff-completed gifts. Detail group promotion, tie-break, late verification, P1/C1/P2/SHORT and F1–F5 traceability. Preserve all cases as Not Run. | F14: Five Main Flows F1–F5; SRS/SDD v1.8; Unit Test v1.3; Test Documentation v1.3

Sheet Test Statistics
B1: TEST STATISTICS
B3: Project Name | C3: FSCM – Short Shelf-Life FMCG Supply Chain Management and Distribution Coordination | E3: Creator | H3: Doan Duc Hai
B4: Project Code | C4: FA26SE083 | E4: Reviewer/Approver
B5: Document Code | C5: FA26SE083_Test_Report_v1.3 | E5: Issue Date | H5: 28/10/2026
B6: Notes | C6: 271 planned test cases; Round 1 Not Run. Main Flows F1–F5 aligned: 00:00 ICT, percentage-only discount, full receipt, 1 point/10,000 VND, Admin/Operator SKU permissions and staff gift completion. Record actual/evidence for Pass.
B10: No | C10: Module code | D10: Passed | E10: Failed | F10: Pending | G10: N/A | H10: Number of test cases
B11: 1 | C11: Authentication | D11: =Authentication!B6 -> 0 | E11: =Authentication!C6 -> 0 | F11: =Authentication!D6 -> 11 | G11: =Authentication!E6 -> 0 | H11: =Authentication!B4 -> 11
B12: 2 | C12: User Management | D12: ='User Management'!B6 -> 0 | E12: ='User Management'!C6 -> 0 | F12: ='User Management'!D6 -> 3 | G12: ='User Management'!E6 -> 0 | H12: ='User Management'!B4 -> 3
B13: 3 | C13: Retailer Registration | D13: ='Retailer Registration'!B6 -> 0 | E13: ='Retailer Registration'!C6 -> 0 | F13: ='Retailer Registration'!D6 -> 8 | G13: ='Retailer Registration'!E6 -> 0 | H13: ='Retailer Registration'!B4 -> 8
B14: 4 | C14: Retailer Profiles | D14: ='Retailer Profiles'!B6 -> 0 | E14: ='Retailer Profiles'!C6 -> 0 | F14: ='Retailer Profiles'!D6 -> 3 | G14: ='Retailer Profiles'!E6 -> 0 | H14: ='Retailer Profiles'!B4 -> 3
B15: 5 | C15: Product & Categories | D15: ='Product & Categories'!B6 -> 0 | E15: ='Product & Categories'!C6 -> 0 | F15: ='Product & Categories'!D6 -> 10 | G15: ='Product & Categories'!E6 -> 0 | H15: ='Product & Categories'!B4 -> 10
B16: 6 | C16: Promotion Management | D16: ='Promotion Management'!B6 -> 0 | E16: ='Promotion Management'!C6 -> 0 | F16: ='Promotion Management'!D6 -> 4 | G16: ='Promotion Management'!E6 -> 0 | H16: ='Promotion Management'!B4 -> 4
B17: 7 | C17: Shelf-Life Pricing | D17: ='Shelf-Life Pricing'!B6 -> 0 | E17: ='Shelf-Life Pricing'!C6 -> 0 | F17: ='Shelf-Life Pricing'!D6 -> 9 | G17: ='Shelf-Life Pricing'!E6 -> 0 | H17: ='Shelf-Life Pricing'!B4 -> 9
B18: 8 | C18: Order Management | D18: ='Order Management'!B6 -> 0 | E18: ='Order Management'!C6 -> 0 | F18: ='Order Management'!D6 -> 20 | G18: ='Order Management'!E6 -> 0 | H18: ='Order Management'!B4 -> 20
B19: 9 | C19: Offline Synchronization | D19: ='Offline Synchronization'!B6 -> 0 | E19: ='Offline Synchronization'!C6 -> 0 | F19: ='Offline Synchronization'!D6 -> 16 | G19: ='Offline Synchronization'!E6 -> 0 | H19: ='Offline Synchronization'!B4 -> 16
B20: 10 | C20: Allocation Engine | D20: ='Allocation Engine'!B6 -> 0 | E20: ='Allocation Engine'!C6 -> 0 | F20: ='Allocation Engine'!D6 -> 29 | G20: ='Allocation Engine'!E6 -> 0 | H20: ='Allocation Engine'!B4 -> 29
B21: 11 | C21: Allocation Approval | D21: ='Allocation Approval'!B6 -> 0 | E21: ='Allocation Approval'!C6 -> 0 | F21: ='Allocation Approval'!D6 -> 6 | G21: ='Allocation Approval'!E6 -> 0 | H21: ='Allocation Approval'!B4 -> 6
B22: 12 | C22: Goods Receipts | D22: ='Goods Receipts'!B6 -> 0 | E22: ='Goods Receipts'!C6 -> 0 | F22: ='Goods Receipts'!D6 -> 3 | G22: ='Goods Receipts'!E6 -> 0 | H22: ='Goods Receipts'!B4 -> 3
B23: 13 | C23: Warehouse Inventory | D23: ='Warehouse Inventory'!B6 -> 0 | E23: ='Warehouse Inventory'!C6 -> 0 | F23: ='Warehouse Inventory'!D6 -> 12 | G23: ='Warehouse Inventory'!E6 -> 0 | H23: ='Warehouse Inventory'!B4 -> 12
B24: 14 | C24: Picking & QR | D24: ='Picking & QR'!B6 -> 0 | E24: ='Picking & QR'!C6 -> 0 | F24: ='Picking & QR'!D6 -> 14 | G24: ='Picking & QR'!E6 -> 0 | H24: ='Picking & QR'!B4 -> 14
B25: 15 | C25: Delivery & Receipt | D25: ='Delivery & Receipt'!B6 -> 0 | E25: ='Delivery & Receipt'!C6 -> 0 | F25: ='Delivery & Receipt'!D6 -> 13 | G25: ='Delivery & Receipt'!E6 -> 0 | H25: ='Delivery & Receipt'!B4 -> 13
B26: 16 | C26: Complaints & Refunds | D26: ='Complaints & Refunds'!B6 -> 0 | E26: ='Complaints & Refunds'!C6 -> 0 | F26: ='Complaints & Refunds'!D6 -> 15 | G26: ='Complaints & Refunds'!E6 -> 0 | H26: ='Complaints & Refunds'!B4 -> 15
B27: 17 | C27: Payments & Receivables | D27: ='Payments & Receivables'!B6 -> 0 | E27: ='Payments & Receivables'!C6 -> 0 | F27: ='Payments & Receivables'!D6 -> 14 | G27: ='Payments & Receivables'!E6 -> 0 | H27: ='Payments & Receivables'!B4 -> 14
B28: 18 | C28: Loyalty Management | D28: ='Loyalty Management'!B6 -> 0 | E28: ='Loyalty Management'!C6 -> 0 | F28: ='Loyalty Management'!D6 -> 15 | G28: ='Loyalty Management'!E6 -> 0 | H28: ='Loyalty Management'!B4 -> 15
B29: 19 | C29: Territory & Sales Groups | D29: ='Territory & Sales Groups'!B6 -> 0 | E29: ='Territory & Sales Groups'!C6 -> 0 | F29: ='Territory & Sales Groups'!D6 -> 3 | G29: ='Territory & Sales Groups'!E6 -> 0 | H29: ='Territory & Sales Groups'!B4 -> 3
B30: 20 | C30: Sales Reporting | D30: ='Sales Reporting'!B6 -> 0 | E30: ='Sales Reporting'!C6 -> 0 | F30: ='Sales Reporting'!D6 -> 6 | G30: ='Sales Reporting'!E6 -> 0 | H30: ='Sales Reporting'!B4 -> 6
B31: 21 | C31: Configuration & Notifications | D31: ='Configuration & Notifications'!B6 -> 0 | E31: ='Configuration & Notifications'!C6 -> 0 | F31: ='Configuration & Notifications'!D6 -> 9 | G31: ='Configuration & Notifications'!E6 -> 0 | H31: ='Configuration & Notifications'!B4 -> 9
B32: 22 | C32: Main Workflows | D32: ='Main Workflows'!B6 -> 0 | E32: ='Main Workflows'!C6 -> 0 | F32: ='Main Workflows'!D6 -> 8 | G32: ='Main Workflows'!E6 -> 0 | H32: ='Main Workflows'!B4 -> 8
B33: 23 | C33: State Transitions | D33: ='State Transitions'!B6 -> 0 | E33: ='State Transitions'!C6 -> 0 | F33: ='State Transitions'!D6 -> 20 | G33: ='State Transitions'!E6 -> 0 | H33: ='State Transitions'!B4 -> 20
B34: 24 | C34: Non-Functional Tests | D34: ='Non-Functional Tests'!B6 -> 0 | E34: ='Non-Functional Tests'!C6 -> 0 | F34: ='Non-Functional Tests'!D6 -> 20 | G34: ='Non-Functional Tests'!E6 -> 0 | H34: ='Non-Functional Tests'!B4 -> 20
C35: Sub total | D35: =SUM(D11:D34) -> 0 | E35: =SUM(E11:E34) -> 0 | F35: =SUM(F11:F34) -> 271 | G35: =SUM(G11:G34) -> 0 | H35: =SUM(H11:H34) -> 271
C37: Test coverage | E37: =IFERROR((D35+E35)/(H35-G35)*100,0) -> 0 | F37: %
C38: Test successful coverage | E38: =IFERROR(D35/(H35-G35)*100,0) -> 0 | F38: %

Sheet Test Cases
D1: TEST CASE LIST — FSCM v1.3
B3: Project Name | D3: FSCM – Short Shelf-Life FMCG Supply Chain Management and Distribution Coordination
B4: Project Code | D4: FA26SE083
B5: Test Environment Setup Description | D5: ASP.NET Core .NET 10, React, Flutter, approved API contracts, PostgreSQL staging. Main Flows F1–F5 reference fixtures (P1/C1/P2/SHORT); no fake execution results. Cutoff 00:00 ICT; percentage-only tiers; 1 point per 10,000 VND.
B8: No | C8: Function Name | D8: Sheet Name | E8: Description | F8: Pre-Condition
B9: 1 | C9: Login with system account | D9: Authentication | E9: 3 test case(s): Boundary, Negative, Positive. Example expected outcome: Issue access/refresh tokens and return authorized scope | F9: Test environment seeded; authorized All roles; transaction isolated and resettable.
B10: 2 | C10: Refresh and revoke session | D10: Authentication | E10: 3 test case(s): Boundary, Negative, Positive. Example expected outcome: Rotate token and revoke predecessor | F10: Test environment seeded; authorized All roles; transaction isolated and resettable.
B11: 3 | C11: Role and data-scope authorization | D11: Authentication | E11: 3 test case(s): Boundary, Negative, Positive. Example expected outcome: Return authorized records only | F11: Test environment seeded; authorized All roles; transaction isolated and resettable.
B12: 4 | C12: Administrator user management | D12: User Management | E12: 3 test case(s): Boundary, Negative, Positive. Example expected outcome: Create a non-admin account with traceability | F12: Test environment seeded; authorized Administrator; transaction isolated and resettable.
B13: 5 | C13: Declare retailer and assessment | D13: Retailer Registration | E13: 3 test case(s): Boundary, Negative, Positive. Example expected outcome: Create pending retailer declaration | F13: Test environment seeded; authorized Sales; Operator; transaction isolated and resettable.
B14: 6 | C14: Review retailer activation | D14: Retailer Registration | E14: 3 test case(s): Boundary, Negative, Positive. Example expected outcome: Assign active status and business code | F14: Test environment seeded; authorized Administrator; transaction isolated and resettable.
B15: 7 | C15: Manage retailer profile and MLOR | D15: Retailer Profiles | E15: 3 test case(s): Boundary, Negative, Positive. Example expected outcome: Save new version and retain history | F15: Test environment seeded; authorized Administrator; transaction isolated and resettable.
B16: 8 | C16: Manage category hierarchy | D16: Product & Categories | E16: 3 test case(s): Boundary, Negative, Positive. Example expected outcome: Persist valid non-cyclic hierarchy | F16: Test environment seeded; authorized Administrator; transaction isolated and resettable.
B17: 9 | C17: Create and publish product | D17: Product & Categories | E17: Administrator AND Operator create Draft, price, publish SKU; Published data immutable; Sales cannot write. | F17: Test environment seeded; authorized Administrator; transaction isolated and resettable.
B18: 10 | C18: Product search and catalog visibility | D18: Product & Categories | E18: 3 test case(s): Boundary, Negative, Positive. Example expected outcome: Return only permitted published products | F18: Test environment seeded; authorized Sales; Retailer; Administrator; transaction isolated and resettable.
B19: 11 | C19: Manage ordinary promotion | D19: Promotion Management | E19: 3 test case(s): Boundary, Negative, Positive. Example expected outcome: Persist promotion/version with eligibility | F19: Test environment seeded; authorized Administrator; transaction isolated and resettable.
B20: 12 | C20: Calculate shelf-life discount tier | D20: Shelf-Life Pricing | E20: Percentage-only tiers (<100%); reject fixed/zero net price; MLOR before discount; preserve batch snapshot. | F20: Test environment seeded; authorized Administrator; System; transaction isolated and resettable.
... B180: 172 | C180: R5-TC-NFR-08 — Algorithm evaluation validity | D180: Non-Functional Tests | E180: Priority P1 | SRS v1.8 §4 NFR-D06; R5-11; M12/WF04/TS02 Expected: Report complete/short, near-expiry quantity, mean distance, warehouses/order, runtime; zero invalid allocations; no optimality claim. | F180: Two evaluators consume exact same eligible snapshot and priority. Data: Seeds with close-to-expiry units, different distances.

Sheet Authentication
A2: Feature | B2: Authentication | R2: Passed
A3: Test requirement | B3: Verify account login and refresh-token lifecycle for FSCM roles: valid credentials issue scoped sessions; repeated invalid attempts trigger lockout; revoked or reused tokens cannot create extra sessions; deactivated users and cross-territory requests are denied. | R3: Failed
A4: Number of TCs | B4: =COUNTA(A12:A22) -> 11 | R4: Pending
A5: Testing Round | B5: Passed | C5: Failed | D5: Pending | E5: N/A | R5: N/A
A6: Round 1 | B6: =COUNTIF(F12:F22,"Passed")+COUNTIF(F12:F22,"Pass") -> 0 | C6: =COUNTIF(F12:F22,"Failed")+COUNTIF(F12:F22,"Fail") -> 0 | D6: =COUNTIF(F12:F22,"Not Run")+COUNTIF(F12:F22,"Blocked")+COUNTIF(F12:F22,"Pending")+COUNTBLANK(F12:F22) -> 11 | E6: =COUNTIF(F12:F22,"N/A") -> 0
A7: Round 2 | B7: =COUNTIF(I12:I22,"Passed")+COUNTIF(I12:I22,"Pass") -> 0 | C7: =COUNTIF(I12:I22,"Failed")+COUNTIF(I12:I22,"Fail") -> 0 | D7: =COUNTIF(I12:I22,"Not Run")+COUNTIF(I12:I22,"Blocked")+COUNTIF(I12:I22,"Pending") -> 0 | E7: =COUNTIF(I12:I22,"N/A") -> 0
A8: Round 3 | B8: =COUNTIF(L12:L22,"Passed")+COUNTIF(L12:L22,"Pass") -> 0 | C8: =COUNTIF(L12:L22,"Failed")+COUNTIF(L12:L22,"Fail") -> 0 | D8: =COUNTIF(L12:L22,"Not Run")+COUNTIF(L12:L22,"Blocked")+COUNTIF(L12:L22,"Pending") -> 0 | E8: =COUNTIF(L12:L22,"N/A") -> 0
A10: Test Case ID | B10: Test Case Description | C10: Test Case Procedure | D10: Expected Results | E10: Pre-conditions | F10: Round 1 | G10: Test date | H10: Tester | I10: Round 2 | J10: Test date | K10: Tester | L10: Round 3 | M10: Test date | N10: Tester | O10: Note
A11: Authentication — FSCM scenarios
A12: FT-001-P | B12: Login with system account Positive — Active user and valid password | C12: 1. Seed isolated FSCM fixture with required SKU, retailer, warehouse, roles and state; record starting stock/payment/ledger snapshots. 2. Sign in as All roles; perform scenario: Active user and valid password. 3. Submit both the valid operation and the specified invalid/boundary input. 4. Compare response, persisted state, actor audit, once-only effects and unchanged records against the expected result. | D12: Issue access/refresh tokens and return authorized scope | E12: Test environment seeded; authorized All roles; transaction isolated and resettable. | F12: Not Run | O12: Type: Positive; Role: All roles; Level: System / Integration SRS v1.8 / BR: 3.2.1; BR-01–03 Test data: Active user and valid password Source: https://github.com/GFA26SE63/FSCM-Backend/blob/0f56f7099f07aa60d76673e6b6a57a2b606fb833/src/FSCM.API/Controllers/AuthController.cs Automation: Manual / candidate Version: 1.3; Actual result: —; Evidence: —
A13: FT-001-N | B13: Login with system account Negative — Incorrect password, five attempts | C13: 1. Seed isolated FSCM fixture with required SKU, retailer, warehouse, roles and state; record starting stock/payment/ledger snapshots. 2. Sign in as All roles; perform scenario: Incorrect password, five attempts. 3. Submit both the valid operation and the specified invalid/boundary input. 4. Compare response, persisted state, actor audit, once-only effects and unchanged records against the expected result. | D13: Reject credentials without session and enforce lockout | E13: Test environment seeded; authorized All roles; transaction isolated and resettable. | F13: Not Run | O13: Type: Negative; Role: All roles; Level: System / Integration SRS v1.8 / BR: 3.2.1; BR-01–03 Test data: Incorrect password, five attempts Source: https://github.com/GFA26SE63/FSCM-Backend/blob/0f56f7099f07aa60d76673e6b6a57a2b606fb833/src/FSCM.API/Controllers/AuthController.cs Automation: Manual / candidate Version: 1.3; Actual result: —; Evidence: —
A14: FT-001-B | B14: Login with system account Boundary — Account locked until expiry | C14: 1. Seed isolated FSCM fixture with required SKU, retailer, warehouse, roles and state; record starting stock/payment/ledger snapshots. 2. Sign in as All roles; perform scenario: Account locked until expiry. 3. Submit both the valid operation and the specified invalid/boundary input. 4. Compare response, persisted state, actor audit, once-only effects and unchanged records against the expected result. | D14: Do not allow login while locked; allow only after expiry | E14: Test environment seeded; authorized All roles; transaction isolated and resettable. | F14: Not Run | O14: Type: Boundary; Role: All roles; Level: System / Integration SRS v1.8 / BR: 3.2.1; BR-01–03 Test data: Account locked until expiry Source: https://github.com/GFA26SE63/FSCM-Backend/blob/0f56f7099f07aa60d76673e6b6a57a2b606fb833/src/FSCM.API/Controllers/AuthController.cs Automation: Manual / candidate Version: 1.3; Actual result: —; Evidence: —
A15: FT-002-P | B15: Refresh and revoke session Positive — Valid active refresh token | C15: 1. Seed isolated FSCM fixture with required SKU, retailer, warehouse, roles and state; record starting stock/payment/ledger snapshots. 2. Sign in as All roles; perform scenario: Valid active refresh token. 3. Submit both the valid operation and the specified invalid/boundary input. 4. Compare response, persisted state, actor audit, once-only effects and unchanged records against the expected result. | D15: Rotate token and revoke predecessor | E15: Test environment seeded; authorized All roles; transaction isolated and resettable. | F15: Not Run | O15: Type: Positive; Role: All roles; Level: System / Integration SRS v1.8 / BR: 3.2.1; NFR Security Test data: Valid active refresh token Source: https://github.com/GFA26SE63/FSCM-Backend/blob/0f56f7099f07aa60d76673e6b6a57a2b606fb833/src/FSCM.Application/Features/Identity/IdentityService.cs Automation: Manual / candidate Version: 1.3; Actual result: —; Evidence: —
A16: FT-002-N | B16: Refresh and revoke session Negative — Revoked refresh token | C16: 1. Seed isolated FSCM fixture with required SKU, retailer, warehouse, roles and state; record starting stock/payment/ledger snapshots. 2. Sign in as All roles; perform scenario: Revoked refresh token. 3. Submit both the valid operation and the specified invalid/boundary input. 4. Compare response, persisted state, actor audit, once-only effects and unchanged records against the expected result. | D16: Deny invalid/revoked token | E16: Test environment seeded; authorized All roles; transaction isolated and resettable. | F16: Not Run | O16: Type: Negative; Role: All roles; Level: System / Integration SRS v1.8 / BR: 3.2.1; NFR Security Test data: Revoked refresh token Source: https://github.com/GFA26SE63/FSCM-Backend/blob/0f56f7099f07aa60d76673e6b6a57a2b606fb833/src/FSCM.Application/Features/Identity/IdentityService.cs Automation: Manual / candidate Version: 1.3; Actual result: —; Evidence: —
A17: FT-002-B | B17: Refresh and revoke session Boundary — Reuse recently rotated refresh token | C17: 1. Seed isolated FSCM fixture with required SKU, retailer, warehouse, roles and state; record starting stock/payment/ledger snapshots. 2. Sign in as All roles; perform scenario: Reuse recently rotated refresh token. 3. Submit both the valid operation and the specified invalid/boundary input. 4. Compare response, persisted state, actor audit, once-only effects and unchanged records against the expected result. | D17: Never issue second active session from a revoked predecessor | E17: Test environment seeded; authorized All roles; transaction isolated and resettable. | F17: Not Run | O17: Type: Boundary; Role: All roles; Level: System / Integration SRS v1.8 / BR: 3.2.1; NFR Security Test data: Reuse recently rotated refresh token Source: https://github.com/GFA26SE63/FSCM-Backend/blob/0f56f7099f07aa60d76673e6b6a57a2b606fb833/src/FSCM.Application/Features/Identity/IdentityService.cs Automation: Manual / candidate Version: 1.3; Actual result: —; Evidence: —
A18: FT-003-P | B18: Role and data-scope authorization Positive — Sales reads assigned retailer orders | C18: 1. Seed isolated FSCM fixture with required SKU, retailer, warehouse, roles and state; record starting stock/payment/ledger snapshots. 2. Sign in as All roles; perform scenario: Sales reads assigned retailer orders. 3. Submit both the valid operation and the specified invalid/boundary input. 4. Compare response, persisted state, actor audit, once-only effects and unchanged records against the expected result. | D18: Return authorized records only | E18: Test environment seeded; authorized All roles; transaction isolated and resettable. | F18: Not Run | O18: Type: Positive; Role: All roles; Level: System / Integration SRS v1.8 / BR: BR-01–04 Test data: Sales reads assigned retailer orders Source: https://github.com/GFA26SE63/FSCM-Backend/blob/0f56f7099f07aa60d76673e6b6a57a2b606fb833/src/FSCM.API/Security/ActiveAccountClaimsTransformation.cs Automation: Manual / candidate Version: 1.3; Actual result: —; Evidence: —
A19: FT-003-N | B19: Role and data-scope authorization Negative — Sales reads another territory's order | C19: 1. Seed isolated FSCM fixture with required SKU, retailer, warehouse, roles and state; record starting stock/payment/ledger snapshots. 2. Sign in as All roles; perform scenario: Sales reads another territory's order. 3. Submit both the valid operation and the specified invalid/boundary input. 4. Compare response, persisted state, actor audit, once-only effects and unchanged records against the expected result. | D19: Return forbidden/not-found without leaking data | E19: Test environment seeded; authorized All roles; transaction isolated and resettable. | F19: Not Run | O19: Type: Negative; Role: All roles; Level: System / Integration SRS v1.8 / BR: BR-01–04 Test data: Sales reads another territory's order Source: https://github.com/GFA26SE63/FSCM-Backend/blob/0f56f7099f07aa60d76673e6b6a57a2b606fb833/src/FSCM.API/Security/ActiveAccountClaimsTransformation.cs Automation: Manual / candidate Version: 1.3; Actual result: —; Evidence: —
A20: FT-003-B | B20: Role and data-scope authorization Boundary — Deactivated account uses existing JWT | C20: 1. Seed isolated FSCM fixture with required SKU, retailer, warehouse, roles and state; record starting stock/payment/ledger snapshots. 2. Sign in as All roles; perform scenario: Deactivated account uses existing JWT. 3. Submit both the valid operation and the specified invalid/boundary input. 4. Compare response, persisted state, actor audit, once-only effects and unchanged records against the expected result. | D20: Re-evaluate active status and scope per request | E20: Test environment seeded; authorized All roles; transaction isolated and resettable. | F20: Not Run | O20: Type: Boundary; Role: All roles; Level: System / Integration SRS v1.8 / BR: BR-01–04 Test data: Deactivated account uses existing JWT Source: https://github.com/GFA26SE63/FSCM-Backend/blob/0f56f7099f07aa60d76673e6b6a57a2b606fb833/src/FSCM.API/Security/ActiveAccountClaimsTransformation.cs Automation: Manual / candidate Version: 1.3; Actual result: —; Evidence: —
A21: R5-TC-AUTH-01 | B21: Valid account and scoped role | C21: 1. Login; 2. Query own orders; 3. Query another group. | D21: Token carries active scope; own read succeeds; cross-scope query forbidden. | E21: Active user in assigned area; seeded role. Test data: Sales account, valid password, other-group retailer. | F21: Not Run | O21: Requirement/Traceability: SRS v1.8 §3.2.1; BR-01/03; AC-3.2.1-01; M01/WF01/TS01 Priority: P1; Level: Integration / System / Acceptance Version: 1.3; Actual result: —; Evidence: —
A22: R5-TC-AUTH-02 | B22: Invalid credentials and session reuse | C22: 1. Attempt invalid login; 2. Reuse rotated token; 3. Retry protected read. | D22: Invalid login denied; reuse rejected/revoked per policy; no data leak. | E22: Account and refresh tokens exist. Test data: Wrong password; revoked/rotated refresh token. | F22: Not Run | O22: Requirement/Traceability: SRS v1.8 §3.2.1; AC-3.2.1-02; M01/WF01/TS02 Priority: P1; Level: Integration / System / Acceptance Version: 1.3; Actual result: —; Evidence: —

Sheet User Management
A2: Feature | B2: User Management | R2: Passed
A3: Test requirement | B3: Verify Administrator user management permits creation of authorized non-admin accounts with audit history, while blocking creation of additional Administrator accounts and unauthorized promotion of existing users to Administrator. | R3: Failed
A4: Number of TCs | B4: =COUNTA(A12:A14) -> 3 | R4: Pending
A5: Testing Round | B5: Passed | C5: Failed | D5: Pending | E5: N/A | R5: N/A
A6: Round 1 | B6: =COUNTIF(F12:F14,"Passed")+COUNTIF(F12:F14,"Pass") -> 0 | C6: =COUNTIF(F12:F14,"Failed")+COUNTIF(F12:F14,"Fail") -> 0 | D6: =COUNTIF(F12:F14,"Not Run")+COUNTIF(F12:F14,"Blocked")+COUNTIF(F12:F14,"Pending")+COUNTBLANK(F12:F14) -> 3 | E6: =COUNTIF(F12:F14,"N/A") -> 0
A7: Round 2 | B7: =COUNTIF(I12:I14,"Passed")+COUNTIF(I12:I14,"Pass") -> 0 | C7: =COUNTIF(I12:I14,"Failed")+COUNTIF(I12:I14,"Fail") -> 0 | D7: =COUNTIF(I12:I14,"Not Run")+COUNTIF(I12:I14,"Blocked")+COUNTIF(I12:I14,"Pending") -> 0 | E7: =COUNTIF(I12:I14,"N/A") -> 0
A8: Round 3 | B8: =COUNTIF(L12:L14,"Passed")+COUNTIF(L12:L14,"Pass") -> 0 | C8: =COUNTIF(L12:L14,"Failed")+COUNTIF(L12:L14,"Fail") -> 0 | D8: =COUNTIF(L12:L14,"Not Run")+COUNTIF(L12:L14,"Blocked")+COUNTIF(L12:L14,"Pending") -> 0 | E8: =COUNTIF(L12:L14,"N/A") -> 0
A10: Test Case ID | B10: Test Case Description | C10: Test Case Procedure | D10: Expected Results | E10: Pre-conditions | F10: Round 1 | G10: Test date | H10: Tester | I10: Round 2 | J10: Test date | K10: Tester | L10: Round 3 | M10: Test date | N10: Tester | O10: Note
A11: User Management — FSCM scenarios
A12: FT-004-P | B12: Administrator user management Positive — Create permitted Sales user | C12: 1. Seed isolated FSCM fixture with required SKU, retailer, warehouse, roles and state; record starting stock/payment/ledger snapshots. 2. Sign in as Administrator; perform scenario: Create permitted Sales user. 3. Submit both the valid operation and the specified invalid/boundary input. 4. Compare response, persisted state, actor audit, once-only effects and unchanged records against the expected result. | D12: Create a non-admin account with traceability | E12: Test environment seeded; authorized Administrator; transaction isolated and resettable. | F12: Not Run | O12: Type: Positive; Role: Administrator; Level: System / Integration SRS v1.8 / BR: 3.2.3; BR-02 Test data: Create permitted Sales user Source: https://github.com/GFA26SE63/FSCM-Backend/blob/0f56f7099f07aa60d76673e6b6a57a2b606fb833/src/FSCM.API/Controllers/UsersController.cs Automation: Manual / candidate Version: 1.3; Actual result: —; Evidence: —
A13: FT-004-N | B13: Administrator user management Negative — Create an Administrator through UI/API | C13: 1. Seed isolated FSCM fixture with required SKU, retailer, warehouse, roles and state; record starting stock/payment/ledger snapshots. 2. Sign in as Administrator; perform scenario: Create an Administrator through UI/API. 3. Submit both the valid operation and the specified invalid/boundary input. 4. Compare response, persisted state, actor audit, once-only effects and unchanged records against the expected result. | D13: Deny prohibited privileged account creation | E13: Test environment seeded; authorized Administrator; transaction isolated and resettable. | F13: Not Run | O13: Type: Negative; Role: Administrator; Level: System / Integration SRS v1.8 / BR: 3.2.3; BR-02 Test data: Create an Administrator through UI/API Source: https://github.com/GFA26SE63/FSCM-Backend/blob/0f56f7099f07aa60d76673e6b6a57a2b606fb833/src/FSCM.API/Controllers/UsersController.cs Automation: Manual / candidate Version: 1.3; Actual result: —; Evidence: —
A14: FT-004-B | B14: Administrator user management Boundary — Promote existing user to Administrator | C14: 1. Seed isolated FSCM fixture with required SKU, retailer, warehouse, roles and state; record starting stock/payment/ledger snapshots. 2. Sign in as Administrator; perform scenario: Promote existing user to Administrator. 3. Submit both the valid operation and the specified invalid/boundary input. 4. Compare response, persisted state, actor audit, once-only effects and unchanged records against the expected result. | D14: Deny administrator-role escalation even through update | E14: Test environment seeded; authorized Administrator; transaction isolated and resettable. | F14: Not Run | O14: Type: Boundary; Role: Administrator; Level: System / Integration SRS v1.8 / BR: 3.2.3; BR-02 Test data: Promote existing user to Administrator Source: https://github.com/GFA26SE63/FSCM-Backend/blob/0f56f7099f07aa60d76673e6b6a57a2b606fb833/src/FSCM.API/Controllers/UsersController.cs Automation: Manual / candidate Version: 1.3; Actual result: —; Evidence: —

Sheet Retailer Registration
A2: Feature | B2: Retailer Registration | R2: Passed
A3: Test requirement | B3: Verify retailer declarations capture mandatory assessment data and remain Pending until authorized review. Detect duplicate stores, require review reasons, issue an 8-digit code on approval, and permit deferred terms only when currently approved. | R3: Failed
A4: Number of TCs | B4: =COUNTA(A12:A19) -> 8 | R4: Pending
A5: Testing Round | B5: Passed | C5: Failed | D5: Pending | E5: N/A | R5: N/A
A6: Round 1 | B6: =COUNTIF(F12:F19,"Passed")+COUNTIF(F12:F19,"Pass") -> 0 | C6: =COUNTIF(F12:F19,"Failed")+COUNTIF(F12:F19,"Fail") -> 0 | D6: =COUNTIF(F12:F19,"Not Run")+COUNTIF(F12:F19,"Blocked")+COUNTIF(F12:F19,"Pending")+COUNTBLANK(F12:F19) -> 8 | E6: =COUNTIF(F12:F19,"N/A") -> 0
A7: Round 2 | B7: =COUNTIF(I12:I19,"Passed")+COUNTIF(I12:I19,"Pass") -> 0 | C7: =COUNTIF(I12:I19,"Failed")+COUNTIF(I12:I19,"Fail") -> 0 | D7: =COUNTIF(I12:I19,"Not Run")+COUNTIF(I12:I19,"Blocked")+COUNTIF(I12:I19,"Pending") -> 0 | E7: =COUNTIF(I12:I19,"N/A") -> 0
A8: Round 3 | B8: =COUNTIF(L12:L19,"Passed")+COUNTIF(L12:L19,"Pass") -> 0 | C8: =COUNTIF(L12:L19,"Failed")+COUNTIF(L12:L19,"Fail") -> 0 | D8: =COUNTIF(L12:L19,"Not Run")+COUNTIF(L12:L19,"Blocked")+COUNTIF(L12:L19,"Pending") -> 0 | E8: =COUNTIF(L12:L19,"N/A") -> 0
A10: Test Case ID | B10: Test Case Description | C10: Test Case Procedure | D10: Expected Results | E10: Pre-conditions | F10: Round 1 | G10: Test date | H10: Tester | I10: Round 2 | J10: Test date | K10: Tester | L10: Round 3 | M10: Test date | N10: Tester | O10: Note
A11: Retailer Registration — FSCM scenarios
A12: FT-005-P | B12: Declare retailer and assessment Positive — Complete prospect data and assessment | C12: 1. Seed isolated FSCM fixture with required SKU, retailer, warehouse, roles and state; record starting stock/payment/ledger snapshots. 2. Sign in as Sales; Operator; perform scenario: Complete prospect data and assessment. 3. Submit both the valid operation and the specified invalid/boundary input. 4. Compare response, persisted state, actor audit, once-only effects and unchanged records against the expected result. | D12: Create pending retailer declaration | E12: Test environment seeded; authorized Sales; Operator; transaction isolated and resettable. | F12: Not Run | O12: Type: Positive; Role: Sales; Operator; Level: System / Integration SRS v1.8 / BR: 3.3.1; BR-12 Test data: Complete prospect data and assessment Source: https://github.com/GFA26SE63/FSCM-Backend/blob/0f56f7099f07aa60d76673e6b6a57a2b606fb833/src/FSCM.API/Controllers/RetailersController.cs Automation: Manual / candidate Version: 1.3; Actual result: —; Evidence: —
A13: FT-005-N | B13: Declare retailer and assessment Negative — Duplicate store declaration | C13: 1. Seed isolated FSCM fixture with required SKU, retailer, warehouse, roles and state; record starting stock/payment/ledger snapshots. 2. Sign in as Sales; Operator; perform scenario: Duplicate store declaration. 3. Submit both the valid operation and the specified invalid/boundary input. 4. Compare response, persisted state, actor audit, once-only effects and unchanged records against the expected result. | D13: Detect duplicate and avoid new retailer | E13: Test environment seeded; authorized Sales; Operator; transaction isolated and resettable. | F13: Not Run | O13: Type: Negative; Role: Sales; Operator; Level: System / Integration SRS v1.8 / BR: 3.3.1; BR-12 Test data: Duplicate store declaration Source: https://github.com/GFA26SE63/FSCM-Backend/blob/0f56f7099f07aa60d76673e6b6a57a2b606fb833/src/FSCM.API/Controllers/RetailersController.cs Automation: Manual / candidate Version: 1.3; Actual result: —; Evidence: —
A14: FT-005-B | B14: Declare retailer and assessment Boundary — Missing mandatory assessment field | C14: 1. Seed isolated FSCM fixture with required SKU, retailer, warehouse, roles and state; record starting stock/payment/ledger snapshots. 2. Sign in as Sales; Operator; perform scenario: Missing mandatory assessment field. 3. Submit both the valid operation and the specified invalid/boundary input. 4. Compare response, persisted state, actor audit, once-only effects and unchanged records against the expected result. | D14: Validate required fields; do not silently activate | E14: Test environment seeded; authorized Sales; Operator; transaction isolated and resettable. | F14: Not Run | O14: Type: Boundary; Role: Sales; Operator; Level: System / Integration SRS v1.8 / BR: 3.3.1; BR-12 Test data: Missing mandatory assessment field Source: https://github.com/GFA26SE63/FSCM-Backend/blob/0f56f7099f07aa60d76673e6b6a57a2b606fb833/src/FSCM.API/Controllers/RetailersController.cs Automation: Manual / candidate Version: 1.3; Actual result: —; Evidence: —
A15: FT-006-P | B15: Review retailer activation Positive — Approve pending retailer with reason | C15: 1. Seed isolated FSCM fixture with required SKU, retailer, warehouse, roles and state; record starting stock/payment/ledger snapshots. 2. Sign in as Administrator; perform scenario: Approve pending retailer with reason. 3. Submit both the valid operation and the specified invalid/boundary input. 4. Compare response, persisted state, actor audit, once-only effects and unchanged records against the expected result. | D15: Assign active status and business code | E15: Test environment seeded; authorized Administrator; transaction isolated and resettable. | F15: Not Run | O15: Type: Positive; Role: Administrator; Level: System / Integration SRS v1.8 / BR: 3.3.2; BR-12 Test data: Approve pending retailer with reason Source: https://github.com/GFA26SE63/FSCM-Backend/blob/0f56f7099f07aa60d76673e6b6a57a2b606fb833/src/FSCM.Application/Features/Retailers/RetailerService.cs Automation: Manual / candidate Version: 1.3; Actual result: —; Evidence: —
A16: FT-006-N | B16: Review retailer activation Negative — Unauthorized reviewer attempts approval | C16: 1. Seed isolated FSCM fixture with required SKU, retailer, warehouse, roles and state; record starting stock/payment/ledger snapshots. 2. Sign in as Administrator; perform scenario: Unauthorized reviewer attempts approval. 3. Submit both the valid operation and the specified invalid/boundary input. 4. Compare response, persisted state, actor audit, once-only effects and unchanged records against the expected result. | D16: Reject unauthorized approval | E16: Test environment seeded; authorized Administrator; transaction isolated and resettable. | F16: Not Run | O16: Type: Negative; Role: Administrator; Level: System / Integration SRS v1.8 / BR: 3.3.2; BR-12 Test data: Unauthorized reviewer attempts approval Source: https://github.com/GFA26SE63/FSCM-Backend/blob/0f56f7099f07aa60d76673e6b6a57a2b606fb833/src/FSCM.Application/Features/Retailers/RetailerService.cs Automation: Manual / candidate Version: 1.3; Actual result: —; Evidence: —
A17: FT-006-B | B17: Review retailer activation Boundary — Rejection without reason | C17: 1. Seed isolated FSCM fixture with required SKU, retailer, warehouse, roles and state; record starting stock/payment/ledger snapshots. 2. Sign in as Administrator; perform scenario: Rejection without reason. 3. Submit both the valid operation and the specified invalid/boundary input. 4. Compare response, persisted state, actor audit, once-only effects and unchanged records against the expected result. | D17: Keep rejection reason mandatory and preserve review trail | E17: Test environment seeded; authorized Administrator; transaction isolated and resettable. | F17: Not Run | O17: Type: Boundary; Role: Administrator; Level: System / Integration SRS v1.8 / BR: 3.3.2; BR-12 Test data: Rejection without reason Source: https://github.com/GFA26SE63/FSCM-Backend/blob/0f56f7099f07aa60d76673e6b6a57a2b606fb833/src/FSCM.Application/Features/Retailers/RetailerService.cs Automation: Manual / candidate Version: 1.3; Actual result: —; Evidence: —
A18: R5-TC-RET-01 | B18: Retailer declared and approved | C18: 1. Submit declaration; 2. Admin approves; 3. Inspect code and scope. | D18: Pending→Active only under Admin approval; assigned 8-digit code and scoped account. | E18: Assigned Sales; pending Retailer. Test data: Store identity, MLOR and evidence, approval actor. | F18: Not Run | O18: Requirement/Traceability: SRS v1.8 §3.3.1–3.3.2; AC-3.3.2-01; M02/WF01/TS01 Priority: P1; Level: Integration / System / Acceptance Version: 1.3; Actual result: —; Evidence: —
A19: R5-TC-RET-02 | B19: Retailer term scope and validation | C19: 1. Request Deferred; 2. Change term version; 3. Attempt with invalid term. | D19: Only approved, currently valid term allows Deferred; otherwise rejected. | E19: Retailers with/without approved versioned credit terms. Test data: Term valid/expired/unapproved. | F19: Not Run | O19: Requirement/Traceability: SRS v1.8 §3.3.3, §3.10.1; BR-51/73; M02/WF02/TS01 Priority: P1; Level: Integration / System / Acceptance Version: 1.3; Actual result: —; Evidence: —

Sheet Retailer Profiles
A2: Feature | B2: Retailer Profiles | R2: Passed
A3: Test requirement | B3: Verify authorized retailer profile and versioned shelf-life requirement updates. Reject invalid MLOR ratios and resolve the effective requirement in order of SKU, Category, then product default without losing prior policy history. | R3: Failed
A4: Number of TCs | B4: =COUNTA(A12:A14) -> 3 | R4: Pending
A5: Testing Round | B5: Passed | C5: Failed | D5: Pending | E5: N/A | R5: N/A
A6: Round 1 | B6: =COUNTIF(F12:F14,"Passed")+COUNTIF(F12:F14,"Pass") -> 0 | C6: =COUNTIF(F12:F14,"Failed")+COUNTIF(F12:F14,"Fail") -> 0 | D6: =COUNTIF(F12:F14,"Not Run")+COUNTIF(F12:F14,"Blocked")+COUNTIF(F12:F14,"Pending")+COUNTBLANK(F12:F14) -> 3 | E6: =COUNTIF(F12:F14,"N/A") -> 0
A7: Round 2 | B7: =COUNTIF(I12:I14,"Passed")+COUNTIF(I12:I14,"Pass") -> 0 | C7: =COUNTIF(I12:I14,"Failed")+COUNTIF(I12:I14,"Fail") -> 0 | D7: =COUNTIF(I12:I14,"Not Run")+COUNTIF(I12:I14,"Blocked")+COUNTIF(I12:I14,"Pending") -> 0 | E7: =COUNTIF(I12:I14,"N/A") -> 0
A8: Round 3 | B8: =COUNTIF(L12:L14,"Passed")+COUNTIF(L12:L14,"Pass") -> 0 | C8: =COUNTIF(L12:L14,"Failed")+COUNTIF(L12:L14,"Fail") -> 0 | D8: =COUNTIF(L12:L14,"Not Run")+COUNTIF(L12:L14,"Blocked")+COUNTIF(L12:L14,"Pending") -> 0 | E8: =COUNTIF(L12:L14,"N/A") -> 0
A10: Test Case ID | B10: Test Case Description | C10: Test Case Procedure | D10: Expected Results | E10: Pre-conditions | F10: Round 1 | G10: Test date | H10: Tester | I10: Round 2 | J10: Test date | K10: Tester | L10: Round 3 | M10: Test date | N10: Tester | O10: Note
A11: Retailer Profiles — FSCM scenarios
A12: FT-007-P | B12: Manage retailer profile and MLOR Positive — Update permitted retailer/category/SKU MLOR | C12: 1. Seed isolated FSCM fixture with required SKU, retailer, warehouse, roles and state; record starting stock/payment/ledger snapshots. 2. Sign in as Administrator; perform scenario: Update permitted retailer/category/SKU MLOR. 3. Submit both the valid operation and the specified invalid/boundary input. 4. Compare response, persisted state, actor audit, once-only effects and unchanged records against the expected result. | D12: Save new version and retain history | E12: Test environment seeded; authorized Administrator; transaction isolated and resettable. | F12: Not Run | O12: Type: Positive; Role: Administrator; Level: System / Integration SRS v1.8 / BR: 3.3.3; 3.7.4 Test data: Update permitted retailer/category/SKU MLOR Source: https://github.com/GFA26SE63/FSCM-Backend/blob/0f56f7099f07aa60d76673e6b6a57a2b606fb833/src/FSCM.API/Controllers/MlorConfigurationsController.cs Automation: Manual / candidate Version: 1.3; Actual result: —; Evidence: —
A13: FT-007-N | B13: Manage retailer profile and MLOR Negative — Ratio less than or equal to zero | C13: 1. Seed isolated FSCM fixture with required SKU, retailer, warehouse, roles and state; record starting stock/payment/ledger snapshots. 2. Sign in as Administrator; perform scenario: Ratio less than or equal to zero. 3. Submit both the valid operation and the specified invalid/boundary input. 4. Compare response, persisted state, actor audit, once-only effects and unchanged records against the expected result. | D13: Reject invalid ratio | E13: Test environment seeded; authorized Administrator; transaction isolated and resettable. | F13: Not Run | O13: Type: Negative; Role: Administrator; Level: System / Integration SRS v1.8 / BR: 3.3.3; 3.7.4 Test data: Ratio less than or equal to zero Source: https://github.com/GFA26SE63/FSCM-Backend/blob/0f56f7099f07aa60d76673e6b6a57a2b606fb833/src/FSCM.API/Controllers/MlorConfigurationsController.cs Automation: Manual / candidate Version: 1.3; Actual result: —; Evidence: —
A14: FT-007-B | B14: Manage retailer profile and MLOR Boundary — SKU override and category fallback | C14: 1. Seed isolated FSCM fixture with required SKU, retailer, warehouse, roles and state; record starting stock/payment/ledger snapshots. 2. Sign in as Administrator; perform scenario: SKU override and category fallback. 3. Submit both the valid operation and the specified invalid/boundary input. 4. Compare response, persisted state, actor audit, once-only effects and unchanged records against the expected result. | D14: Use configured precedence and effective version for standard line | E14: Test environment seeded; authorized Administrator; transaction isolated and resettable. | F14: Not Run | O14: Type: Boundary; Role: Administrator; Level: System / Integration SRS v1.8 / BR: 3.3.3; 3.7.4 Test data: SKU override and category fallback Source: https://github.com/GFA26SE63/FSCM-Backend/blob/0f56f7099f07aa60d76673e6b6a57a2b606fb833/src/FSCM.API/Controllers/MlorConfigurationsController.cs Automation: Manual / candidate Version: 1.3; Actual result: —; Evidence: —

Sheet Product & Categories
A2: Feature | B2: Product & Categories | R2: Passed
A3: Test requirement | B3: Confirm Administrator AND Operator can create, price, edit Draft and publish SKU_A / SKU_B, using 100,000/50,000 VND list prices; reject unauthorized edits and modification of Published records. Replacements retain prior batch and sales history. | R3: Failed
A4: Number of TCs | B4: =COUNTA(A12:A21) -> 10 | R4: Pending
A5: Testing Round | B5: Passed | C5: Failed | D5: Pending | E5: N/A | R5: N/A
A6: Round 1 | B6: =COUNTIF(F12:F21,"Passed")+COUNTIF(F12:F21,"Pass") -> 0 | C6: =COUNTIF(F12:F21,"Failed")+COUNTIF(F12:F21,"Fail") -> 0 | D6: =COUNTIF(F12:F21,"Not Run")+COUNTIF(F12:F21,"Blocked")+COUNTIF(F12:F21,"Pending")+COUNTBLANK(F12:F21) -> 10 | E6: =COUNTIF(F12:F21,"N/A") -> 0
A7: Round 2 | B7: =COUNTIF(I12:I21,"Passed")+COUNTIF(I12:I21,"Pass") -> 0 | C7: =COUNTIF(I12:I21,"Failed")+COUNTIF(I12:I21,"Fail") -> 0 | D7: =COUNTIF(I12:I21,"Not Run")+COUNTIF(I12:I21,"Blocked")+COUNTIF(I12:I21,"Pending") -> 0 | E7: =COUNTIF(I12:I21,"N/A") -> 0
A8: Round 3 | B8: =COUNTIF(L12:L21,"Passed")+COUNTIF(L12:L21,"Pass") -> 0 | C8: =COUNTIF(L12:L21,"Failed")+COUNTIF(L12:L21,"Fail") -> 0 | D8: =COUNTIF(L12:L21,"Not Run")+COUNTIF(L12:L21,"Blocked")+COUNTIF(L12:L21,"Pending") -> 0 | E8: =COUNTIF(L12:L21,"N/A") -> 0
A10: Test Case ID | B10: Test Case Description | C10: Test Case Procedure | D10: Expected Results | E10: Pre-conditions | F10: Round 1 | G10: Test date | H10: Tester | I10: Round 2 | J10: Test date | K10: Tester | L10: Round 3 | M10: Test date | N10: Tester | O10: Note
A11: Product & Categories — FSCM scenarios
A12: FT-008-P | B12: Manage category hierarchy Positive — Create child category under parent | C12: 1. Seed isolated FSCM fixture with required SKU, retailer, warehouse, roles and state; record starting stock/payment/ledger snapshots. 2. Sign in as Administrator; perform scenario: Create child category under parent. 3. Submit both the valid operation and the specified invalid/boundary input. 4. Compare response, persisted state, actor audit, once-only effects and unchanged records against the expected result. | D12: Persist valid non-cyclic hierarchy | E12: Test environment seeded; authorized Administrator; transaction isolated and resettable. | F12: Not Run | O12: Type: Positive; Role: Administrator; Level: System / Integration SRS v1.8 / BR: 3.4.1 Test data: Create child category under parent Source: https://github.com/GFA26SE63/FSCM-Backend/blob/0f56f7099f07aa60d76673e6b6a57a2b606fb833/src/FSCM.API/Controllers/CategoriesController.cs Automation: Manual / candidate Version: 1.3; Actual result: —; Evidence: —
A13: FT-008-N | B13: Manage category hierarchy Negative — Select descendant as parent | C13: 1. Seed isolated FSCM fixture with required SKU, retailer, warehouse, roles and state; record starting stock/payment/ledger snapshots. 2. Sign in as Administrator; perform scenario: Select descendant as parent. 3. Submit both the valid operation and the specified invalid/boundary input. 4. Compare response, persisted state, actor audit, once-only effects and unchanged records against the expected result. | D13: Block parent-child cycles | E13: Test environment seeded; authorized Administrator; transaction isolated and resettable. | F13: Not Run | O13: Type: Negative; Role: Administrator; Level: System / Integration SRS v1.8 / BR: 3.4.1 Test data: Select descendant as parent Source: https://github.com/GFA26SE63/FSCM-Backend/blob/0f56f7099f07aa60d76673e6b6a57a2b606fb833/src/FSCM.API/Controllers/CategoriesController.cs Automation: Manual / candidate Version: 1.3; Actual result: —; Evidence: —
A14: FT-008-B | B14: Manage category hierarchy Boundary — Delete parent with active children/products | C14: 1. Seed isolated FSCM fixture with required SKU, retailer, warehouse, roles and state; record starting stock/payment/ledger snapshots. 2. Sign in as Administrator; perform scenario: Delete parent with active children/products. 3. Submit both the valid operation and the specified invalid/boundary input. 4. Compare response, persisted state, actor audit, once-only effects and unchanged records against the expected result. | D14: Preserve dependent children/products on prohibited delete | E14: Test environment seeded; authorized Administrator; transaction isolated and resettable. | F14: Not Run | O14: Type: Boundary; Role: Administrator; Level: System / Integration SRS v1.8 / BR: 3.4.1 Test data: Delete parent with active children/products Source: https://github.com/GFA26SE63/FSCM-Backend/blob/0f56f7099f07aa60d76673e6b6a57a2b606fb833/src/FSCM.API/Controllers/CategoriesController.cs Automation: Manual / candidate Version: 1.3; Actual result: —; Evidence: —
A15: FT-009-P | B15: Admin/Operator publishes SKU_A and SKU_B with approved effective prices | C15: 1. Sign in as Administrator; create SKU_A at 100,000 VND/carton and SKU_B at 50,000 VND/carton as Draft. 2. Publish both, verify Catalog. 3. Repeat on independent Draft with authorized Operator role. 4. Inspect effective price and audit. | D15: Both authorized roles can publish eligible Draft products; SKU_A/B visible and prices versioned; no duplicate SKU. | E15: F1 source fixture: Admin and Operator with product permissions; Draft SKU_A/SKU_B; price effective date. | F15: Not Run | O15: Type: Positive; Role: Administrator; Level: System / Integration SRS v1.8 / BR: 3.4.2; BR-07–08 Test data: Create Draft and publish valid SKU Source: https://github.com/GFA26SE63/FSCM-Backend/blob/0f56f7099f07aa60d76673e6b6a57a2b606fb833/src/FSCM.API/Controllers/ProductsController.cs Automation: Manual / candidate Version: 1.3; Actual result: —; Evidence: —
A16: FT-009-N | B16: Published SKU price locked; unauthorized non-product role cannot modify | C16: 1. Publish SKU_A. 2. Attempt edit price as Admin/Operator; must use new Draft/version. 3. Attempt any change as Sales. 4. Verify historical price and stock untouched. | D16: Published record immutable for both authorized roles; new Draft replacement allowed; Sales write forbidden; historical batch/transaction links unchanged. | E16: Test environment seeded; authorized Administrator; transaction isolated and resettable. | F16: Not Run | O16: Type: Negative; Role: Administrator; Level: System / Integration SRS v1.8 / BR: 3.4.2; BR-07–08 Test data: Edit published SKU price Source: https://github.com/GFA26SE63/FSCM-Backend/blob/0f56f7099f07aa60d76673e6b6a57a2b606fb833/src/FSCM.API/Controllers/ProductsController.cs Automation: Manual / candidate Version: 1.3; Actual result: —; Evidence: —
A17: FT-009-B | B17: Create and publish product Boundary — Clone already used SKU | C17: 1. Seed isolated FSCM fixture with required SKU, retailer, warehouse, roles and state; record starting stock/payment/ledger snapshots. 2. Sign in as Administrator; perform scenario: Clone already used SKU. 3. Submit both the valid operation and the specified invalid/boundary input. 4. Compare response, persisted state, actor audit, once-only effects and unchanged records against the expected result. | D17: Reject duplicate SKU without side effects | E17: Test environment seeded; authorized Administrator; transaction isolated and resettable. | F17: Not Run | O17: Type: Boundary; Role: Administrator; Level: System / Integration SRS v1.8 / BR: 3.4.2; BR-07–08 Test data: Clone already used SKU Source: https://github.com/GFA26SE63/FSCM-Backend/blob/0f56f7099f07aa60d76673e6b6a57a2b606fb833/src/FSCM.API/Controllers/ProductsController.cs Automation: Manual / candidate Version: 1.3; Actual result: —; Evidence: —
A18: FT-010-P | B18: Product search and catalog visibility Positive — Search published SKU in eligible catalog | C18: 1. Seed isolated FSCM fixture with required SKU, retailer, warehouse, roles and state; record starting stock/payment/ledger snapshots. 2. Sign in as Sales; Retailer; Administrator; perform scenario: Search published SKU in eligible catalog. 3. Submit both the valid operation and the specified invalid/boundary input. 4. Compare response, persisted state, actor audit, once-only effects and unchanged records against the expected result. | D18: Return only permitted published products | E18: Test environment seeded; authorized Sales; Retailer; Administrator; transaction isolated and resettable. | F18: Not Run | O18: Type: Positive; Role: Sales; Retailer; Administrator; Level: System / Integration SRS v1.8 / BR: 3.4.3 Test data: Search published SKU in eligible catalog Source: https://github.com/GFA26SE63/FSCM-Backend/blob/0f56f7099f07aa60d76673e6b6a57a2b606fb833/src/FSCM.Application/Features/Catalog/CatalogService.cs Automation: Manual / candidate Version: 1.3; Actual result: —; Evidence: —
A19: FT-010-N | B19: Product search and catalog visibility Negative — Access Draft product as purchasable | C19: 1. Seed isolated FSCM fixture with required SKU, retailer, warehouse, roles and state; record starting stock/payment/ledger snapshots. 2. Sign in as Sales; Retailer; Administrator; perform scenario: Access Draft product as purchasable. 3. Submit both the valid operation and the specified invalid/boundary input. 4. Compare response, persisted state, actor audit, once-only effects and unchanged records against the expected result. | D19: Never expose Draft/Inactive as orderable | E19: Test environment seeded; authorized Sales; Retailer; Administrator; transaction isolated and resettable. | F19: Not Run | O19: Type: Negative; Role: Sales; Retailer; Administrator; Level: System / Integration SRS v1.8 / BR: 3.4.3 Test data: Access Draft product as purchasable Source: https://github.com/GFA26SE63/FSCM-Backend/blob/0f56f7099f07aa60d76673e6b6a57a2b606fb833/src/FSCM.Application/Features/Catalog/CatalogService.cs Automation: Manual / candidate Version: 1.3; Actual result: —; Evidence: —
A20: FT-010-B | B20: Product search and catalog visibility Boundary — Empty search / paginated result | C20: 1. Seed isolated FSCM fixture with required SKU, retailer, warehouse, roles and state; record starting stock/payment/ledger snapshots. 2. Sign in as Sales; Retailer; Administrator; perform scenario: Empty search / paginated result. 3. Submit both the valid operation and the specified invalid/boundary input. 4. Compare response, persisted state, actor audit, once-only effects and unchanged records against the expected result. | D20: Return stable paged results or empty state | E20: Test environment seeded; authorized Sales; Retailer; Administrator; transaction isolated and resettable. | F20: Not Run | O20: Type: Boundary; Role: Sales; Retailer; Administrator; Level: System / Integration SRS v1.8 / BR: 3.4.3 Test data: Empty search / paginated result Source: https://github.com/GFA26SE63/FSCM-Backend/blob/0f56f7099f07aa60d76673e6b6a57a2b606fb833/src/FSCM.Application/Features/Catalog/CatalogService.cs Automation: Manual / candidate Version: 1.3; Actual result: —; Evidence: —
A21: R5-TC-CAT-01 | B21: F1 catalog, product authority and independent replacement Draft | C21: 1. Admin/Operator creates Category, SKU_A/B Draft and price effective versions. 2. Publish, query catalog as Sales. 3. Clone SKU_A for replacement, verify unique code and no migrated batches. 4. Test unauthorized writer. | D21: Admin and Operator permitted on catalog operations; Sales read-only; old SKU, inventory and historical orders unchanged; replacement has independent new Draft state. | E21: Draft/published SKU and parent category. Test data: Valid SKU, cycle-forming parent, inactive SKU. | F21: Not Run | O21: Requirement/Traceability: SRS v1.8 §3.4.1–3.4.2; AC-3.4.2-01; M03/WF01/TS01 Priority: P2; Level: Integration / System / Acceptance Version: 1.3; Actual result: —; Evidence: —

Sheet Promotion Management
A2: Feature | B2: Promotion Management | R2: Passed
A3: Test requirement | B3: Verify group promotion threshold sums eligible SKU quantities within one Sales Order: SKU_A6+SKU_B4 and SKU_A10 qualify; SKU_A6+SKU_B3 or external SKU4 do not. Apply 10% ordinary discount once, choose best valid campaign, then only percentage shelf-life tiers <100%. | R3: Failed
A4: Number of TCs | B4: =COUNTA(A12:A15) -> 4 | R4: Pending
A5: Testing Round | B5: Passed | C5: Failed | D5: Pending | E5: N/A | R5: N/A
A6: Round 1 | B6: =COUNTIF(F12:F15,"Passed")+COUNTIF(F12:F15,"Pass") -> 0 | C6: =COUNTIF(F12:F15,"Failed")+COUNTIF(F12:F15,"Fail") -> 0 | D6: =COUNTIF(F12:F15,"Not Run")+COUNTIF(F12:F15,"Blocked")+COUNTIF(F12:F15,"Pending")+COUNTBLANK(F12:F15) -> 4 | E6: =COUNTIF(F12:F15,"N/A") -> 0
A7: Round 2 | B7: =COUNTIF(I12:I15,"Passed")+COUNTIF(I12:I15,"Pass") -> 0 | C7: =COUNTIF(I12:I15,"Failed")+COUNTIF(I12:I15,"Fail") -> 0 | D7: =COUNTIF(I12:I15,"Not Run")+COUNTIF(I12:I15,"Blocked")+COUNTIF(I12:I15,"Pending") -> 0 | E7: =COUNTIF(I12:I15,"N/A") -> 0
A8: Round 3 | B8: =COUNTIF(L12:L15,"Passed")+COUNTIF(L12:L15,"Pass") -> 0 | C8: =COUNTIF(L12:L15,"Failed")+COUNTIF(L12:L15,"Fail") -> 0 | D8: =COUNTIF(L12:L15,"Not Run")+COUNTIF(L12:L15,"Blocked")+COUNTIF(L12:L15,"Pending") -> 0 | E8: =COUNTIF(L12:L15,"N/A") -> 0
A10: Test Case ID | B10: Test Case Description | C10: Test Case Procedure | D10: Expected Results | E10: Pre-conditions | F10: Round 1 | G10: Test date | H10: Tester | I10: Round 2 | J10: Test date | K10: Tester | L10: Round 3 | M10: Test date | N10: Tester | O10: Note
A11: Promotion Management — FSCM scenarios
A12: FT-011-P | B12: Group promotion applies to sum SKU_A6 + SKU_B4 | C12: 1. Admin creates eligible group {SKU_A,SKU_B}, threshold 10 cartons and 10% discount. 2. Sales creates R1 SO with A6 at 100,000 and B4 at 50,000. 3. Verify promotion eligibility and amounts before allocation. | D12: Eligible quantity=10; gross 800,000 VND; group discount=80,000; post-promotion base=720,000; applies once within this SO. | E12: F2 group SKU_A,SKU_B, active eligible retailer R1; list prices A100,000/B50,000; discount tier under applicable MLOR. | F12: Not Run | O12: Type: Positive; Role: Administrator; Level: System / Integration SRS v1.8 / BR: 3.5.1; BR-14–19 Test data: Create valid scoped promotion Source: https://github.com/GFA26SE63/FSCM-Backend/blob/0f56f7099f07aa60d76673e6b6a57a2b606fb833/src/FSCM.Application/Features/Promotions/PromotionService.cs Automation: Manual / candidate Version: 1.3; Actual result: —; Evidence: —
A13: FT-011-N | B13: Group promotion rejects under-threshold and foreign SKU quantities | C13: 1. Quote A6+B3 in one SO. 2. Quote A6+foreignSKU4 in a second SO. 3. Create two separate SOs whose combined quantity is 10. 4. Check eligible counted units. | D13: None qualifies for the 10-carton group; foreign SKU and quantities from other orders do not contribute. | E13: F2 group SKU_A,SKU_B, active eligible retailer R1; list prices A100,000/B50,000; discount tier under applicable MLOR. | F13: Not Run | O13: Type: Negative; Role: Administrator; Level: System / Integration SRS v1.8 / BR: 3.5.1; BR-14–19 Test data: Overlapping invalid period or unauthorized role Source: https://github.com/GFA26SE63/FSCM-Backend/blob/0f56f7099f07aa60d76673e6b6a57a2b606fb833/src/FSCM.Application/Features/Promotions/PromotionService.cs Automation: Manual / candidate Version: 1.3; Actual result: —; Evidence: —
A14: FT-011-B | B14: Group threshold boundary and active-campaign tie-break | C14: 1. Submit A10 and A6+B4 (valid), then A6+B3 (invalid). 2. Create two active group campaigns with equal VND discounts. 3. Set one campaign paused and repeat. | D14: Exactly 10 eligible cartons qualifies, 9 does not. Highest discount chosen per line; equal amount breaks by ascending campaign code; paused ignored. | E14: F2 group SKU_A,SKU_B, active eligible retailer R1; list prices A100,000/B50,000; discount tier under applicable MLOR. | F14: Not Run | O14: Type: Boundary; Role: Administrator; Level: System / Integration SRS v1.8 / BR: 3.5.1; BR-14–19 Test data: Paused/expired promotion evaluated for price Source: https://github.com/GFA26SE63/FSCM-Backend/blob/0f56f7099f07aa60d76673e6b6a57a2b606fb833/src/FSCM.Application/Features/Promotions/PromotionService.cs Automation: Manual / candidate Version: 1.3; Actual result: —; Evidence: —
A15: R5-TC-PROM-01 | B15: F2 promotion non-stacking, group threshold and percentage-only tiers | C15: 1. Seed SKU_A6+B4, 10-carton group promotion 10% and two overlapping valid ordinary campaigns. 2. Select largest VND benefit with deterministic code tie. 3. Apply valid percent-only batch tier after allocation. 4. Attempt fixed shelf-life tier and 100% tier. | D15: Only one ordinary discount per line; 80,000 VND off 800,000 total. Shelf-life percent tier applied to the remaining batch-specific net basis; fixed/100% rejected. | E15: F2 group SKU_A,SKU_B, active eligible retailer R1; list prices A100,000/B50,000; discount tier under applicable MLOR. | F15: Not Run | O15: Requirement/Traceability: SRS v1.8 §3.5.1; AC-3.5.1-01; M04/WF01/TS01 Priority: P2; Level: Integration / System / Acceptance Version: 1.3; Actual result: —; Evidence: —

Sheet Shelf-Life Pricing
A2: Feature | B2: Shelf-Life Pricing | R2: Passed
